Workbook
Name 属性类型: 游戏类型定义!$B$43:$B$67
Name 职业范围: 游戏类型定义!$B$31:$B$36
Name 装备部位: 游戏类型定义!$B$20:$B$29

Sheet 计算规则
A1: 序号 | B1: 类型 | C1: 内容 | D1: 规则或公式 | E1: 备注
A2: 1 | B2: 战斗伤害计算 | C2: 普通攻击伤害 | D2: 伤害 = randbtween(A最小伤害,A最大伤害)*(1-B护甲/(B护甲值+f(B等级)))*if(A攻击类型=物理攻击,1-B物抗/(B物抗+f(B等级)),1-B魔抗/(B魔抗+f(B等级)))
A3: 2 | C3: 单体技能攻击伤害 | D3: A武功伤害*意志/100+A攻击力-B防御力
A4: 3 | C4: 群体技能攻击伤害 | D4: 当前目标,基准攻击力：A武功伤害*内力/100+A攻击力 距离为0的目标伤害：基准攻击力*100%-敌防 距离为1的目标：基准攻击力*67%-敌防 距离为2的目标：基准攻击力*53%-敌防 距离为3的目标：基准攻击力*40%-敌防 距离为4的目标：基准攻击力*30%-敌防 距离为5的目标：基准攻击力*20%-敌防 距离为6的目标：基准攻击力*13%-敌防 距离为7待测试
A5: 4 | C5: 暴击伤害 | D5: 未暴击时的伤害值*(1.8+额外暴击伤害加成)
A6: 5 | B6: 用户基本信息 | C6: 用户每级的升级经验 | D6: 无公式，根据策划表格配置
A7: 6 | C7: 关卡不同对获取经验影响 | D7: 参见策划配置表，根据关卡怪物自身携带经验，战斗胜利后根据怪物数量以及怪物自身携带经验值结算 该关卡首次达到3星时，可得正常经验值的3倍经验值

Sheet 游戏类型定义
A1: 模块 | B1: 类型 | C1: 值 | I1: 装备个数
A2: 数据类型 | B2: 玩家属性 | C2: 1 | I2: 11
B3: 角色 | C3: 2 | I3: 11
B4: 道具 | C4: 3 | I4: 11
B5: 装备 | C5: 4 | I5: 11
A6: 玩家属性 | B6: 钻石 | C6: 1001 | I6: 11
B7: 金币 | C7: 1002 | I7: 11
B8: 等级 | C8: 1003 | H8: 胸甲 | I8: 18
B9: 经验 | C9: 1004 | H9: 护腿 | I9: 18
B10: vip等级 | C10: 1005 | H10: 战士主手 | I10: 25
A11: 物品 | B11: 普通类型 | C11: 0 | I11: 19
B12: 碎片 | C12: 1 | H12: 猎人主手 | I12: 23
B13: 宝石 | C13: 2 | I13: 19
B14: 锤子 | C14: 3 | H14: 法师主手 | I14: 27
B15: 宝箱 | C15: 4 | I15: 19
B16: 钥匙 | C16: 5
B17: 精华 | C17: 6
B18: 礼包 | C18: 7
B19: 宝石袋 | C19: 8
A20: 装备部位 | B20: 头盔 | C20: 1
B21: 戒指 | C21: 2
B22: 腰带 | C22: 3
B23: 胸甲 | C23: 4
B24: 主手武器 | C24: 5
B25: 副手武器 | C25: 6
B26: 护腿 | C26: 7
B27: 鞋子 | C27: 8
B28: 手套 | C28: 9
B29: 项链 | C29: 10
A30: 职业类型 | B30: 全职业 | C30: 0
B31: 战士 | C31: 1
B32: 猎人 | C32: 2
B33: 法师 | C33: 3
B34: 佣兵战士 | C34: 1001
B35: 佣兵猎人 | C35: 1002
B36: 佣兵法师 | C36: 1003
B37: 怪物战士 | C37: 2001
B38: 怪物猎人 | C38: 2002
B39: 怪物法师 | C39: 2003
A40: 神器开启条件 | B40: 全身装备+1 | C40: 1
...

Sheet 用户升级
A1: 英雄等级 | C1: 经验与用时 | N1: 金币与用时 | R1: 设计核心 | S1: 地图等级范围 | U1: 战斗时长（S） | V1: 越级级数
A2: 等级 | B2: 升下一级经验 | C2: 极限升级用时（h） | D2: 到本级总经验 | E2: 到本级总用时(h) | F2: 到本级总用时(day) | G2: 同等级怪物提供经验 | H2: 升至下一级战斗次数 | I2: 升至下一级用时(S) | J2: 总战斗次数 | K2: 总战斗用时(S) | L2: 神器经验加成 | M2: 越级战斗次数 | N2: 同等级怪物提供金币 | O2: 当前等级金币获取 | P2: 总金币获取 | S2: 1 | T2: 5 | U2: 20 | V2: 10
A3: 1 | B3: =20*A3^3-40*A3^2+30 -> 10 | C3: =ROUND(M3/180,0) -> 0 | D3: 0 | E3: =D3/G3 -> 0 | F3: =E3/24 -> 0 | G3: 10 | H3: =ROUND(B3/G3,1) -> 1 | I3: =H3*INDEX(U$2:U$15,INT((A3-1)/5)+1,) -> 20 | J3: =SUM(H$3:H3) -> 1 | K3: =SUM(I$3:I3) -> 20 | L3: 1 | M3: =ROUND(B3/INDEX(G$3:G$102,MIN(A3+$V$2,100)),0) -> 0 | N3: =G3 -> 10 | O3: =H3*N3 -> 10 | P3: =SUM(O$3:O3) -> 10 | S3: =S2+5 -> 6 | T3: =T2+5 -> 10 | U3: 20
A4: 2 | B4: =20*A4^3-40*A4^2+30 -> 30 | C4: =((M4/180)/24)/2.66/(100+L4)*100+C3 -> 8.5316778e-05 | D4: =SUM(B$3:B3) -> 10 | E4: =ROUND(SUM(I$3:I3)/3600,2) -> 0.01 | F4: =ROUND(SUM(I$3:I3)/(3600*24),2) -> 0 | G4: =G3+2 -> 12 | H4: =ROUND(B4/G4,1) -> 2.5 | I4: =H4*INDEX(U$2:U$15,INT((A4-1)/5)+1,) -> 50 | J4: =SUM(H$3:H4) -> 3.5 | K4: =SUM(I$3:I4) -> 70 | L4: 2 | M4: =ROUND(B4/INDEX(G$3:G$102,MIN(A4+$V$2,100)),0) -> 1 | N4: =G4 -> 12 | O4: =H4*N4 -> 30 | P4: =SUM(O$3:O4) -> 40 | S4: =S3+5 -> 11 | T4: =T3+5 -> 15 | U4: 20
A5: 3 | B5: =20*A5^3-40*A5^2+30 -> 210 | C5: =((M5/180)/24)/2.66/(100+L5)*100+C4 -> 0.00050775908 | D5: =SUM(B$3:B4) -> 40 | E5: =ROUND(SUM(I$3:I4)/3600,2) -> 0.02 | F5: =ROUND(SUM(I$3:I4)/(3600*24),2) -> 0 | G5: 14 | H5: =ROUND(B5/G5,1) -> 15 | I5: =H5*INDEX(U$2:U$15,INT((A5-1)/5)+1,) -> 300 | J5: =SUM(H$3:H5) -> 18.5 | K5: =SUM(I$3:I5) -> 370 | L5: 3 | M5: =ROUND(B5/INDEX(G$3:G$102,MIN(A5+$V$2,100)),0) -> 5 | N5: =G5 -> 14 | O5: =H5*N5 -> 210 | P5: =SUM(O$3:O5) -> 250 | S5: =S4+5 -> 16 | T5: =T4+5 -> 20 | U5: 20
A6: 4 | B6: =20*A6^3-40*A6^2+30 -> 670 | C6: =((M6/180)/24)/2.66/(100+L6)*100+C5 -> 0.0016792241 | D6: =SUM(B$3:B5) -> 250 | E6: =ROUND(SUM(I$3:I5)/3600,2) -> 0.1 | F6: =ROUND(SUM(I$3:I5)/(3600*24),2) -> 0 | G6: 16 | H6: =ROUND(B6/G6,1) -> 41.9 | I6: =H6*INDEX(U$2:U$15,INT((A6-1)/5)+1,) -> 838 | J6: =SUM(H$3:H6) -> 60.4 | K6: =SUM(I$3:I6) -> 1208 | L6: 4 | M6: =ROUND(B6/INDEX(G$3:G$102,MIN(A6+$V$2,100)),0) -> 14 | N6: =G6 -> 16 | O6: =H6*N6 -> 670.4 | P6: =SUM(O$3:O6) -> 920.4 | S6: =S5+5 -> 21 | T6: =T5+5 -> 25 | U6: 20
A7: 5 | B7: =20*A7^3-40*A7^2+30 -> 1530 | C7: =((M7/180)/24)/2.66/(100+L7)*100+C6 -> 0.0040827196 | D7: =SUM(B$3:B6) -> 920 | E7: =ROUND(SUM(I$3:I6)/3600,2) -> 0.34 | F7: =ROUND(SUM(I$3:I6)/(3600*24),2) -> 0.01 | G7: 18 | H7: =ROUND(B7/G7,1) -> 85 | I7: =H7*INDEX(U$2:U$15,INT((A7-1)/5)+1,) -> 1700 | J7: =SUM(H$3:H7) -> 145.4 | K7: =SUM(I$3:I7) -> 2908 | L7: 5 | M7: =ROUND(B7/INDEX(G$3:G$102,MIN(A7+$V$2,100)),0) -> 29 | N7: =G7 -> 18 | O7: =H7*N7 -> 1530 | P7: =SUM(O$3:O7) -> 2450.4 | S7: =S6+5 -> 26 | T7: =T6+5 -> 30 | U7: 20
A8: 6 | B8: =20*A8^3-40*A8^2+30 -> 2910 | C8: =((M8/180)/24)/2.66/(100+L8)*100+C7 -> 0.008351778 | D8: =SUM(B$3:B7) -> 2450 | E8: =ROUND(SUM(I$3:I7)/3600,2) -> 0.81 | F8: =ROUND(SUM(I$3:I7)/(3600*24),2) -> 0.03 | G8: 20 | H8: =ROUND(B8/G8,1) -> 145.5 | I8: =H8*INDEX(U$2:U$15,INT((A8-1)/5)+1,) -> 2910 | J8: =SUM(H$3:H8) -> 290.9 | K8: =SUM(I$3:I8) -> 5818 | L8: 6 | M8: =ROUND(B8/INDEX(G$3:G$102,MIN(A8+$V$2,100)),0) -> 52 | N8: =G8 -> 20 | O8: =H8*N8 -> 2910 | P8: =SUM(O$3:O8) -> 5360.4 | S8: =S7+5 -> 31 | T8: =T7+5 -> 35 | U8: 20
A9: 7 | B9: =20*A9^3-40*A9^2+30 -> 4930 | C9: =((M9/180)/24)/2.66/(100+L9)*100+C8 -> 0.015020839 | D9: =SUM(B$3:B8) -> 5360 | E9: =ROUND(SUM(I$3:I8)/3600,2) -> 1.62 | F9: =ROUND(SUM(I$3:I8)/(3600*24),2) -> 0.07 | G9: 22 | H9: =ROUND(B9/G9,1) -> 224.1 | I9: =H9*INDEX(U$2:U$15,INT((A9-1)/5)+1,) -> 4482 | J9: =SUM(H$3:H9) -> 515 | K9: =SUM(I$3:I9) -> 10300 | L9: 7 | M9: =ROUND(B9/INDEX(G$3:G$102,MIN(A9+$V$2,100)),0) -> 82 | N9: =G9 -> 22 | O9: =H9*N9 -> 4930.2 | P9: =SUM(O$3:O9) -> 10290.6 | S9: =S8+5 -> 36 | T9: =T8+5 -> 40 | U9: 20
A10: 8 | B10: =20*A10^3-40*A10^2+30 -> 7710 | C10: =((M10/180)/24)/2.66/(100+L10)*100+C9 -> 0.024690074 | D10: =SUM(B$3:B9) -> 10290 | E10: =ROUND(SUM(I$3:I9)/3600,2) -> 2.86 | F10: =ROUND(SUM(I$3:I9)/(3600*24),2) -> 0.12 | G10: 24 | H10: =ROUND(B10/G10,1) -> 321.3 | I10: =H10*INDEX(U$2:U$15,INT((A10-1)/5)+1,) -> 6426 | J10: =SUM(H$3:H10) -> 836.3 | K10: =SUM(I$3:I10) -> 16726 | L10: 8 | M10: =ROUND(B10/INDEX(G$3:G$102,MIN(A10+$V$2,100)),0) -> 120 | N10: =G10 -> 24 | O10: =H10*N10 -> 7711.2 | P10: =SUM(O$3:O10) -> 18001.8 | S10: =S9+5 -> 41 | T10: =T9+5 -> 45 | U10: 20
A11: 9 | B11: =20*A11^3-40*A11^2+30 -> 11370 | C11: =((M11/180)/24)/2.66/(100+L11)*100+C10 -> 0.038022973 | D11: =SUM(B$3:B10) -> 18000 | E11: =ROUND(SUM(I$3:I10)/3600,2) -> 4.65 | F11: =ROUND(SUM(I$3:I10)/(3600*24),2) -> 0.19 | G11: 28 | H11: =ROUND(B11/G11,1) -> 406.1 | I11: =H11*INDEX(U$2:U$15,INT((A11-1)/5)+1,) -> 8122 | J11: =SUM(H$3:H11) -> 1242.4 | K11: =SUM(I$3:I11) -> 24848 | L11: 9 | M11: =ROUND(B11/INDEX(G$3:G$102,MIN(A11+$V$2,100)),0) -> 167 | N11: =G11 -> 28 | O11: =H11*N11 -> 11370.8 | P11: =SUM(O$3:O11) -> 29372.6 | S11: =S10+5 -> 46 | T11: =T10+5 -> 50 | U11: 20
A12: 10 | B12: =20*A12^3-40*A12^2+30 -> 16030 | C12: =((M12/180)/24)/2.66/(100+L12)*100+C11 -> 0.055664931 | D12: =SUM(B$3:B11) -> 29370 | E12: =ROUND(SUM(I$3:I11)/3600,2) -> 6.9 | F12: =ROUND(SUM(I$3:I11)/(3600*24),2) -> 0.29 | G12: 32 | H12: =ROUND(B12/G12,1) -> 500.9 | I12: =H12*INDEX(U$2:U$15,INT((A12-1)/5)+1,) -> 10018 | J12: =SUM(H$3:H12) -> 1743.3 | K12: =SUM(I$3:I12) -> 34866 | L12: 10 | M12: =ROUND(B12/INDEX(G$3:G$102,MIN(A12+$V$2,100)),0) -> 223 | N12: =G12 -> 32 | O12: =H12*N12 -> 16028.8 | P12: =SUM(O$3:O12) -> 45401.4 | S12: =S11+5 -> 51 | T12: =T11+5 -> 55 | U12: 20
A13: 11 | B13: =20*A13^3-40*A13^2+30 -> 21810 | C13: =((M13/180)/24)/2.66/(100+L13)*100+C12 -> 0.077616708 | D13: =SUM(B$3:B12) -> 45400 | E13: =ROUND(SUM(I$3:I12)/3600,2) -> 9.69 | F13: =ROUND(SUM(I$3:I12)/(3600*24),2) -> 0.4 | G13: 36 | H13: =ROUND(B13/G13,1) -> 605.8 | I13: =H13*INDEX(U$2:U$15,INT((A13-1)/5)+1,) -> 12116 | J13: =SUM(H$3:H13) -> 2349.1 | K13: =SUM(I$3:I13) -> 46982 | L13: 11 | M13: =ROUND(B13/INDEX(G$3:G$102,MIN(A13+$V$2,100)),0) -> 280 | N13: =G13 -> 36 | O13: =H13*N13 -> 21808.8 | P13: =SUM(O$3:O13) -> 67210.2 | S13: =S12+5 -> 56 | T13: =T12+5 -> 60 | U13: 20
A14: 12 | B14: =20*A14^3-40*A14^2+30 -> 28830 | C14: =((M14/180)/24)/2.66/(100+L14)*100+C13 -> 0.10426754 | D14: =SUM(B$3:B13) -> 67210 | E14: =ROUND(SUM(I$3:I13)/3600,2) -> 13.05 | F14: =ROUND(SUM(I$3:I13)/(3600*24),2) -> 0.54 | G14: 40 | H14: =ROUND(B14/G14,1) -> 720.8 | I14: =H14*INDEX(U$2:U$15,INT((A14-1)/5)+1,) -> 14416 | J14: =SUM(H$3:H14) -> 3069.9 | K14: =SUM(I$3:I14) -> 61398 | L14: 12 | M14: =ROUND(B14/INDEX(G$3:G$102,MIN(A14+$V$2,100)),0) -> 343 | N14: =G14 -> 40 | O14: =H14*N14 -> 28832 | P14: =SUM(O$3:O14) -> 96042.2 | S14: =S13+5 -> 61 | T14: =T13+5 -> 65 | U14: 20
A15: 13 | B15: =20*A15^3-40*A15^2+30 -> 37210 | C15: =((M15/180)/24)/2.66/(100+L15)*100+C14 -> 0.13607333 | D15: =SUM(B$3:B14) -> 96040 | E15: =ROUND(SUM(I$3:I14)/3600,2) -> 17.06 | F15: =ROUND(SUM(I$3:I14)/(3600*24),2) -> 0.71 | G15: 44 | H15: =ROUND(B15/G15,1) -> 845.7 | I15: =H15*INDEX(U$2:U$15,INT((A15-1)/5)+1,) -> 16914 | J15: =SUM(H$3:H15) -> 3915.6 | K15: =SUM(I$3:I15) -> 78312 | L15: 13 | M15: =ROUND(B15/INDEX(G$3:G$102,MIN(A15+$V$2,100)),0) -> 413 | N15: =G15 -> 44 | O15: =H15*N15 -> 37210.8 | P15: =SUM(O$3:O15) -> 133253 | S15: =S14+5 -> 66 | T15: =T14+5 -> 70 | U15: 20
A16: 14 | B16: =20*A16^3-40*A16^2+30 -> 47070 | C16: =((M16/180)/24)/2.66/(100+L16)*100+C15 -> 0.173478 | D16: =SUM(B$3:B15) -> 133250 | E16: =ROUND(SUM(I$3:I15)/3600,2) -> 21.75 | F16: =ROUND(SUM(I$3:I15)/(3600*24),2) -> 0.91 | G16: 48 | H16: =ROUND(B16/G16,1) -> 980.6 | I16: =H16*INDEX(U$2:U$15,INT((A16-1)/5)+1,) -> 19612 | J16: =SUM(H$3:H16) -> 4896.2 | K16: =SUM(I$3:I16) -> 97924 | L16: 14 | M16: =ROUND(B16/INDEX(G$3:G$102,MIN(A16+$V$2,100)),0) -> 490 | N16: =G16 -> 48 | O16: =H16*N16 -> 47068.8 | P16: =SUM(O$3:O16) -> 180321.8 | S16: =S15+5 -> 71 | T16: =T15+5 -> 75 | U16: 20
... A21: 19 | B21: =20*A21^3-40*A21^2+30 -> 122770 | C21: =((M21/180)/24)/2.66/(100+L21)*100+C20 -> 0.45827527 | D21: =SUM(B$3:B20) -> 501000 | E21: =ROUND(SUM(I$3:I20)/3600,2) -> 57.6 | F21: =ROUND(SUM(I$3:I20)/(3600*24),2) -> 2.4 | G21: 68 | H21: =ROUND(B21/G21,1) -> 1805.4 | I21: =H21*INDEX(U$2:U$15,INT((A21-1)/5)+1,) -> 36108 | J21: =SUM(H$3:H21) -> 12173.7 | K21: =SUM(I$3:I21) -> 243474 | L21: 19 | M21: =ROUND(B21/INDEX(G$3:G$102,MIN(A21+$V$2,100)),0) -> 974 | N21: =G21 -> 68 | O21: =H21*N21 -> 122767.2 | P21: =SUM(O$3:O21) -> 623770.2 | S21: =S20+5 -> 96 | T21: =T20+5 -> 100 | U21: 20
A22: 20 | B22: =20*A22^3-40*A22^2+30 -> 144030 | C22: =((M22/180)/24)/2.66/(100+L22)*100+C21 -> 0.53739378 | D22: =SUM(B$3:B21) -> 623770 | E22: =ROUND(SUM(I$3:I21)/3600,2) -> 67.63 | F22: =ROUND(SUM(I$3:I21)/(3600*24),2) -> 2.82 | G22: 72 | H22: =ROUND(B22/G22,1) -> 2000.4 | I22: =H22*INDEX(U$2:U$15,INT((A22-1)/5)+1,) -> 40008 | J22: =SUM(H$3:H22) -> 14174.1 | K22: =SUM(I$3:I22) -> 283482 | L22: 20 | M22: =ROUND(B22/INDEX(G$3:G$102,MIN(A22+$V$2,100)),0) -> 1091 | N22: =G22 -> 72 | O22: =H22*N22 -> 144028.8 | P22: =SUM(O$3:O22) -> 767799
A23: 21 | B23: =20*A23^3-40*A23^2+30 -> 167610 | C23: =((M23/180)/24)/2.66/(100+L23)*100+C22 -> 0.62477649 | D23: =SUM(B$3:B22) -> 767800 | E23: =ROUND(SUM(I$3:I22)/3600,2) -> 78.75 | F23: =ROUND(SUM(I$3:I22)/(3600*24),2) -> 3.28 | G23: 78 | H23: =ROUND(B23/G23,1) -> 2148.8 | I23: =H23*INDEX(U$2:U$15,INT((A23-1)/5)+1,) -> 42976 | J23: =SUM(H$3:H23) -> 16322.9 | K23: =SUM(I$3:I23) -> 326458 | L23: 21 | M23: =ROUND(B23/INDEX(G$3:G$102,MIN(A23+$V$2,100)),0) -> 1215 | N23: =G23 -> 78 | O23: =H23*N23 -> 167606.4 | P23: =SUM(O$3:O23) -> 935405.4
A24: 22 | B24: =20*A24^3-40*A24^2+30 -> 193630 | C24: =((M24/180)/24)/2.66/(100+L24)*100+C23 -> 0.72071591 | D24: =SUM(B$3:B23) -> 935410 | E24: =ROUND(SUM(I$3:I23)/3600,2) -> 90.68 | F24: =ROUND(SUM(I$3:I23)/(3600*24),2) -> 3.78 | G24: 84 | H24: =ROUND(B24/G24,1) -> 2305.1 | I24: =H24*INDEX(U$2:U$15,INT((A24-1)/5)+1,) -> 46102 | J24: =SUM(H$3:H24) -> 18628 | K24: =SUM(I$3:I24) -> 372560 | L24: 22 | M24: =ROUND(B24/INDEX(G$3:G$102,MIN(A24+$V$2,100)),0) -> 1345 | N24: =G24 -> 84 | O24: =H24*N24 -> 193628.4 | P24: =SUM(O$3:O24) -> 1129033.8
A25: 23 | B25: =20*A25^3-40*A25^2+30 -> 222210 | C25: =((M25/180)/24)/2.66/(100+L25)*100+C24 -> 0.8254974 | D25: =SUM(B$3:B24) -> 1129040 | E25: =ROUND(SUM(I$3:I24)/3600,2) -> 103.49 | F25: =ROUND(SUM(I$3:I24)/(3600*24),2) -> 4.31 | G25: 90 | H25: =ROUND(B25/G25,1) -> 2469 | I25: =H25*INDEX(U$2:U$15,INT((A25-1)/5)+1,) -> 49380 | J25: =SUM(H$3:H25) -> 21097 | K25: =SUM(I$3:I25) -> 421940 | L25: 23 | M25: =ROUND(B25/INDEX(G$3:G$102,MIN(A25+$V$2,100)),0) -> 1481 | N25: =G25 -> 90 | O25: =H25*N25 -> 222210 | P25: =SUM(O$3:O25) -> 1351243.8
A26: 24 | B26: =20*A26^3-40*A26^2+30 -> 253470 | C26: =((M26/180)/24)/2.66/(100+L26)*100+C25 -> 0.93953979 | D26: =SUM(B$3:B25) -> 1351250 | E26: =ROUND(SUM(I$3:I25)/3600,2) -> 117.21 | F26: =ROUND(SUM(I$3:I25)/(3600*24),2) -> 4.88 | G26: 96 | H26: =ROUND(B26/G26,1) -> 2640.3 | I26: =H26*INDEX(U$2:U$15,INT((A26-1)/5)+1,) -> 52806 | J26: =SUM(H$3:H26) -> 23737.3 | K26: =SUM(I$3:I26) -> 474746 | L26: 24 | M26: =ROUND(B26/INDEX(G$3:G$102,MIN(A26+$V$2,100)),0) -> 1625 | N26: =G26 -> 96 | O26: =H26*N26 -> 253468.8 | P26: =SUM(O$3:O26) -> 1604712.6
A27: 25 | B27: =20*A27^3-40*A27^2+30 -> 287530 | C27: =((M27/180)/24)/2.66/(100+L27)*100+C26 -> 1.0631126 | D27: =SUM(B$3:B26) -> 1604720 | E27: =ROUND(SUM(I$3:I26)/3600,2) -> 131.87 | F27: =ROUND(SUM(I$3:I26)/(3600*24),2) -> 5.49 | G27: 102 | H27: =ROUND(B27/G27,1) -> 2818.9 | I27: =H27*INDEX(U$2:U$15,INT((A27-1)/5)+1,) -> 56378 | J27: =SUM(H$3:H27) -> 26556.2 | K27: =SUM(I$3:I27) -> 531124 | L27: 25 | M27: =ROUND(B27/INDEX(G$3:G$102,MIN(A27+$V$2,100)),0) -> 1775 | N27: =G27 -> 102 | O27: =H27*N27 -> 287527.8 | P27: =SUM(O$3:O27) -> 1892240.4
A28: 26 | B28: =20*A28^3-40*A28^2+30 -> 324510 | C28: =((M28/180)/24)/2.66/(100+L28)*100+C27 -> 1.196548 | D28: =SUM(B$3:B27) -> 1892250 | E28: =ROUND(SUM(I$3:I27)/3600,2) -> 147.53 | F28: =ROUND(SUM(I$3:I27)/(3600*24),2) -> 6.15 | G28: 108 | H28: =ROUND(B28/G28,1) -> 3004.7 | I28: =H28*INDEX(U$2:U$15,INT((A28-1)/5)+1,) -> 60094 | J28: =SUM(H$3:H28) -> 29560.9 | K28: =SUM(I$3:I28) -> 591218 | L28: 26 | M28: =ROUND(B28/INDEX(G$3:G$102,MIN(A28+$V$2,100)),0) -> 1932 | N28: =G28 -> 108 | O28: =H28*N28 -> 324507.6 | P28: =SUM(O$3:O28) -> 2216748
A29: 27 | B29: =20*A29^3-40*A29^2+30 -> 364530 | C29: =((M29/180)/24)/2.66/(100+L29)*100+C28 -> 1.3401019 | D29: =SUM(B$3:B28) -> 2216760 | E29: =ROUND(SUM(I$3:I28)/3600,2) -> 164.23 | F29: =ROUND(SUM(I$3:I28)/(3600*24),2) -> 6.84 | G29: 114 | H29: =ROUND(B29/G29,1) -> 3197.6 | I29: =H29*INDEX(U$2:U$15,INT((A29-1)/5)+1,) -> 63952 | J29: =SUM(H$3:H29) -> 32758.5 | K29: =SUM(I$3:I29) -> 655170 | L29: 27 | M29: =ROUND(B29/INDEX(G$3:G$102,MIN(A29+$V$2,100)),0) -> 2095 | N29: =G29 -> 114 | O29: =H29*N29 -> 364526.4 | P29: =SUM(O$3:O29) -> 2581274.4
A30: 28 | B30: =20*A30^3-40*A30^2+30 -> 407710 | C30: =((M30/180)/24)/2.66/(100+L30)*100+C29 -> 1.494092 | D30: =SUM(B$3:B29) -> 2581290 | E30: =ROUND(SUM(I$3:I29)/3600,2) -> 181.99 | F30: =ROUND(SUM(I$3:I29)/(3600*24),2) -> 7.58 | G30: 120 | H30: =ROUND(B30/G30,1) -> 3397.6 | I30: =H30*INDEX(U$2:U$15,INT((A30-1)/5)+1,) -> 67952 | J30: =SUM(H$3:H30) -> 36156.1 | K30: =SUM(I$3:I30) -> 723122 | L30: 28 | M30: =ROUND(B30/INDEX(G$3:G$102,MIN(A30+$V$2,100)),0) -> 2265 | N30: =G30 -> 120 | O30: =H30*N30 -> 407712 | P30: =SUM(O$3:O30) -> 2988986.4
A31: 29 | B31: =20*A31^3-40*A31^2+30 -> 454170 | C31: =((M31/180)/24)/2.66/(100+L31)*100+C30 -> 1.6588288 | D31: =SUM(B$3:B30) -> 2989000 | E31: =ROUND(SUM(I$3:I30)/3600,2) -> 200.87 | F31: =ROUND(SUM(I$3:I30)/(3600*24),2) -> 8.37 | G31: 126 | H31: =ROUND(B31/G31,1) -> 3604.5 | I31: =H31*INDEX(U$2:U$15,INT((A31-1)/5)+1,) -> 72090 | J31: =SUM(H$3:H31) -> 39760.6 | K31: =SUM(I$3:I31) -> 795212 | L31: 29 | M31: =ROUND(B31/INDEX(G$3:G$102,MIN(A31+$V$2,100)),0) -> 2442 | N31: =G31 -> 126 | O31: =H31*N31 -> 454167 | P31: =SUM(O$3:O31) -> 3443153.4
A32: 30 | B32: =20*A32^3-40*A32^2+30 -> 504030 | C32: =((M32/180)/24)/2.66/(100+L32)*100+C31 -> 1.8345486 | D32: =SUM(B$3:B31) -> 3443170 | E32: =ROUND(SUM(I$3:I31)/3600,2) -> 220.89 | F32: =ROUND(SUM(I$3:I31)/(3600*24),2) -> 9.2 | G32: 132 | H32: =ROUND(B32/G32,1) -> 3818.4 | I32: =H32*INDEX(U$2:U$15,INT((A32-1)/5)+1,) -> 76368 | J32: =SUM(H$3:H32) -> 43579 | K32: =SUM(I$3:I32) -> 871580 | L32: 30 | M32: =ROUND(B32/INDEX(G$3:G$102,MIN(A32+$V$2,100)),0) -> 2625 | N32: =G32 -> 132 | O32: =H32*N32 -> 504028.8 | P32: =SUM(O$3:O32) -> 3947182.2
A33: 31 | B33: =20*A33^3-40*A33^2+30 -> 557410 | C33: =((M33/180)/24)/2.66/(100+L33)*100+C32 -> 2.0196886 | D33: =SUM(B$3:B32) -> 3947200 | E33: =ROUND(SUM(I$3:I32)/3600,2) -> 242.11 | F33: =ROUND(SUM(I$3:I32)/(3600*24),2) -> 10.09 | G33: =G32+6 -> 138 | H33: =ROUND(B33/G33,1) -> 4039.2 | I33: =H33*INDEX(U$2:U$15,INT((A33-1)/5)+1,) -> 80784 | J33: =SUM(H$3:H33) -> 47618.2 | K33: =SUM(I$3:I33) -> 952364 | L33: 31 | M33: =ROUND(B33/INDEX(G$3:G$102,MIN(A33+$V$2,100)),0) -> 2787 | N33: =G33 -> 138 | O33: =H33*N33 -> 557409.6 | P33: =SUM(O$3:O33) -> 4504591.8
A34: 32 | B34: =20*A34^3-40*A34^2+30 -> 614430 | C34: =((M34/180)/24)/2.66/(100+L34)*100+C33 -> 2.2144358 | D34: =SUM(B$3:B33) -> 4504610 | E34: =ROUND(SUM(I$3:I33)/3600,2) -> 264.55 | F34: =ROUND(SUM(I$3:I33)/(3600*24),2) -> 11.02 | G34: =G33+6 -> 144 | H34: =ROUND(B34/G34,1) -> 4266.9 | I34: =H34*INDEX(U$2:U$15,INT((A34-1)/5)+1,) -> 85338 | J34: =SUM(H$3:H34) -> 51885.1 | K34: =SUM(I$3:I34) -> 1037702 | L34: 32 | M34: =ROUND(B34/INDEX(G$3:G$102,MIN(A34+$V$2,100)),0) -> 2954 | N34: =G34 -> 144 | O34: =H34*N34 -> 614433.6 | P34: =SUM(O$3:O34) -> 5119025.4
A35: 33 | B35: =20*A35^3-40*A35^2+30 -> 675210 | C35: =((M35/180)/24)/2.66/(100+L35)*100+C34 -> 2.4189728 | D35: =SUM(B$3:B34) -> 5119040 | E35: =ROUND(SUM(I$3:I34)/3600,2) -> 288.25 | F35: =ROUND(SUM(I$3:I34)/(3600*24),2) -> 12.01 | G35: =G34+6 -> 150 | H35: =ROUND(B35/G35,1) -> 4501.4 | I35: =H35*INDEX(U$2:U$15,INT((A35-1)/5)+1,) -> 90028 | J35: =SUM(H$3:H35) -> 56386.5 | K35: =SUM(I$3:I35) -> 1127730 | L35: 33 | M35: =ROUND(B35/INDEX(G$3:G$102,MIN(A35+$V$2,100)),0) -> 3126 | N35: =G35 -> 150 | O35: =H35*N35 -> 675210 | P35: =SUM(O$3:O35) -> 5794235.4
A36: 34 | B36: =20*A36^3-40*A36^2+30 -> 739870 | C36: =((M36/180)/24)/2.66/(100+L36)*100+C35 -> 2.6334783 | D36: =SUM(B$3:B35) -> 5794250 | E36: =ROUND(SUM(I$3:I35)/3600,2) -> 313.26 | F36: =ROUND(SUM(I$3:I35)/(3600*24),2) -> 13.05 | G36: =G35+6 -> 156 | H36: =ROUND(B36/G36,1) -> 4742.8 | I36: =H36*INDEX(U$2:U$15,INT((A36-1)/5)+1,) -> 94856 | J36: =SUM(H$3:H36) -> 61129.3 | K36: =SUM(I$3:I36) -> 1222586 | L36: 34 | M36: =ROUND(B36/INDEX(G$3:G$102,MIN(A36+$V$2,100)),0) -> 3303 | N36: =G36 -> 156 | O36: =H36*N36 -> 739876.8 | P36: =SUM(O$3:O36) -> 6534112.2
A37: 35 | B37: =20*A37^3-40*A37^2+30 -> 808530 | C37: =((M37/180)/24)/2.66/(100+L37)*100+C36 -> 2.8581268 | D37: =SUM(B$3:B36) -> 6534120 | E37: =ROUND(SUM(I$3:I36)/3600,2) -> 339.61 | F37: =ROUND(SUM(I$3:I36)/(3600*24),2) -> 14.15 | G37: =G36+6 -> 162 | H37: =ROUND(B37/G37,1) -> 4990.9 | I37: =H37*INDEX(U$2:U$15,INT((A37-1)/5)+1,) -> 99818 | J37: =SUM(H$3:H37) -> 66120.2 | K37: =SUM(I$3:I37) -> 1322404 | L37: 35 | M37: =ROUND(B37/INDEX(G$3:G$102,MIN(A37+$V$2,100)),0) -> 3485 | N37: =G37 -> 162 | O37: =H37*N37 -> 808525.8 | P37: =SUM(O$3:O37) -> 7342638
A38: 36 | B38: =20*A38^3-40*A38^2+30 -> 881310 | C38: =((M38/180)/24)/2.66/(100+L38)*100+C37 -> 3.0930892 | D38: =SUM(B$3:B37) -> 7342650 | E38: =ROUND(SUM(I$3:I37)/3600,2) -> 367.33 | F38: =ROUND(SUM(I$3:I37)/(3600*24),2) -> 15.31 | G38: =G37+6 -> 168 | H38: =ROUND(B38/G38,1) -> 5245.9 | I38: =H38*INDEX(U$2:U$15,INT((A38-1)/5)+1,) -> 104918 | J38: =SUM(H$3:H38) -> 71366.1 | K38: =SUM(I$3:I38) -> 1427322 | L38: 36 | M38: =ROUND(B38/INDEX(G$3:G$102,MIN(A38+$V$2,100)),0) -> 3672 | N38: =G38 -> 168 | O38: =H38*N38 -> 881311.2 | P38: =SUM(O$3:O38) -> 8223949.2
A39: 37 | B39: =20*A39^3-40*A39^2+30 -> 958330 | C39: =((M39/180)/24)/2.66/(100+L39)*100+C38 -> 3.3385325 | D39: =SUM(B$3:B38) -> 8223960 | E39: =ROUND(SUM(I$3:I38)/3600,2) -> 396.48 | F39: =ROUND(SUM(I$3:I38)/(3600*24),2) -> 16.52 | G39: =G38+6 -> 174 | H39: =ROUND(B39/G39,1) -> 5507.6 | I39: =H39*INDEX(U$2:U$15,INT((A39-1)/5)+1,) -> 110152 | J39: =SUM(H$3:H39) -> 76873.7 | K39: =SUM(I$3:I39) -> 1537474 | L39: 37 | M39: =ROUND(B39/INDEX(G$3:G$102,MIN(A39+$V$2,100)),0) -> 3864 | N39: =G39 -> 174 | O39: =H39*N39 -> 958322.4 | P39: =SUM(O$3:O39) -> 9182271.6
A40: 38 | B40: =20*A40^3-40*A40^2+30 -> 1039710 | C40: =((M40/180)/24)/2.66/(100+L40)*100+C39 -> 3.5946201 | D40: =SUM(B$3:B39) -> 9182290 | E40: =ROUND(SUM(I$3:I39)/3600,2) -> 427.08 | F40: =ROUND(SUM(I$3:I39)/(3600*24),2) -> 17.79 | G40: =G39+6 -> 180 | H40: =ROUND(B40/G40,1) -> 5776.2 | I40: =H40*INDEX(U$2:U$15,INT((A40-1)/5)+1,) -> 115524 | J40: =SUM(H$3:H40) -> 82649.9 | K40: =SUM(I$3:I40) -> 1652998 | L40: 38 | M40: =ROUND(B40/INDEX(G$3:G$102,MIN(A40+$V$2,100)),0) -> 4061 | N40: =G40 -> 180 | O40: =H40*N40 -> 1039716 | P40: =SUM(O$3:O40) -> 10221988
A41: 39 | B41: =20*A41^3-40*A41^2+30 -> 1125570 | C41: =((M41/180)/24)/2.66/(100+L41)*100+C40 -> 3.8615745 | D41: =SUM(B$3:B40) -> 10222000 | E41: =ROUND(SUM(I$3:I40)/3600,2) -> 459.17 | F41: =ROUND(SUM(I$3:I40)/(3600*24),2) -> 19.13 | G41: =G40+6 -> 186 | H41: =ROUND(B41/G41,1) -> 6051.5 | I41: =H41*INDEX(U$2:U$15,INT((A41-1)/5)+1,) -> 121030 | J41: =SUM(H$3:H41) -> 88701.4 | K41: =SUM(I$3:I41) -> 1774028 | L41: 39 | M41: =ROUND(B41/INDEX(G$3:G$102,MIN(A41+$V$2,100)),0) -> 4264 | N41: =G41 -> 186 | O41: =H41*N41 -> 1125579 | P41: =SUM(O$3:O41) -> 11347567
A42: 40 | B42: =20*A42^3-40*A42^2+30 -> 1216030 | C42: =((M42/180)/24)/2.66/(100+L42)*100+C41 -> 4.139489 | D42: =SUM(B$3:B41) -> 11347570 | E42: =ROUND(SUM(I$3:I41)/3600,2) -> 492.79 | F42: =ROUND(SUM(I$3:I41)/(3600*24),2) -> 20.53 | G42: =G41+6 -> 192 | H42: =ROUND(B42/G42,1) -> 6333.5 | I42: =H42*INDEX(U$2:U$15,INT((A42-1)/5)+1,) -> 126670 | J42: =SUM(H$3:H42) -> 95034.9 | K42: =SUM(I$3:I42) -> 1900698 | L42: 40 | M42: =ROUND(B42/INDEX(G$3:G$102,MIN(A42+$V$2,100)),0) -> 4471 | N42: =G42 -> 192 | O42: =H42*N42 -> 1216032 | P42: =SUM(O$3:O42) -> 12563599
A43: 41 | B43: =20*A43^3-40*A43^2+30 -> 1311210 | C43: =((M43/180)/24)/2.66/(100+L43)*100+C42 -> 4.4285168 | D43: =SUM(B$3:B42) -> 12563600 | E43: =ROUND(SUM(I$3:I42)/3600,2) -> 527.97 | F43: =ROUND(SUM(I$3:I42)/(3600*24),2) -> 22 | G43: =G42+8 -> 200 | H43: =ROUND(B43/G43,1) -> 6556.1 | I43: =H43*INDEX(U$2:U$15,INT((A43-1)/5)+1,) -> 131122 | J43: =SUM(H$3:H43) -> 101591 | K43: =SUM(I$3:I43) -> 2031820 | L43: 41 | M43: =ROUND(B43/INDEX(G$3:G$102,MIN(A43+$V$2,100)),0) -> 4683 | N43: =G43 -> 200 | O43: =H43*N43 -> 1311220 | P43: =SUM(O$3:O43) -> 13874819
A44: 42 | B44: =20*A44^3-40*A44^2+30 -> 1411230 | C44: =((M44/180)/24)/2.66/(100+L44)*100+C43 -> 4.7288078 | D44: =SUM(B$3:B43) -> 13874810 | E44: =ROUND(SUM(I$3:I43)/3600,2) -> 564.39 | F44: =ROUND(SUM(I$3:I43)/(3600*24),2) -> 23.52 | G44: =G43+8 -> 208 | H44: =ROUND(B44/G44,1) -> 6784.8 | I44: =H44*INDEX(U$2:U$15,INT((A44-1)/5)+1,) -> 135696 | J44: =SUM(H$3:H44) -> 108375.8 | K44: =SUM(I$3:I44) -> 2167516 | L44: 42 | M44: =ROUND(B44/INDEX(G$3:G$102,MIN(A44+$V$2,100)),0) -> 4900 | N44: =G44 -> 208 | O44: =H44*N44 -> 1411238.4 | P44: =SUM(O$3:O44) -> 15286057
...

Sheet 防御属性修正系数
A1: 等级 | B1: 护甲 | C1: 物抗 | D1: 魔抗 | E1: 暴击 | F1: 闪避 | G1: 命中 | H1: 韧性
A2: 1 | B2: =E2 -> 60 | C2: =(A2+1)*50 -> 100 | D2: =(A2+1)*50 -> 100 | E2: =3*A2^2+2*A2+55 -> 60
A3: 2 | B3: =E3 -> 71 | C3: =(A3+1)*50 -> 150 | D3: =(A3+1)*50 -> 150 | E3: =3*A3^2+2*A3+55 -> 71
A4: 3 | B4: =E4 -> 88 | C4: =(A4+1)*50 -> 200 | D4: =(A4+1)*50 -> 200 | E4: =3*A4^2+2*A4+55 -> 88
A5: 4 | B5: =E5 -> 111 | C5: =(A5+1)*50 -> 250 | D5: =(A5+1)*50 -> 250 | E5: =3*A5^2+2*A5+55 -> 111
A6: 5 | B6: =E6 -> 140 | C6: =(A6+1)*50 -> 300 | D6: =(A6+1)*50 -> 300 | E6: =3*A6^2+2*A6+55 -> 140
A7: 6 | B7: =E7 -> 175 | C7: =(A7+1)*50 -> 350 | D7: =(A7+1)*50 -> 350 | E7: =3*A7^2+2*A7+55 -> 175
A8: 7 | B8: =E8 -> 216 | C8: =(A8+1)*50 -> 400 | D8: =(A8+1)*50 -> 400 | E8: =3*A8^2+2*A8+55 -> 216
A9: 8 | B9: =E9 -> 263 | C9: =(A9+1)*50 -> 450 | D9: =(A9+1)*50 -> 450 | E9: =3*A9^2+2*A9+55 -> 263
A10: 9 | B10: =E10 -> 316 | C10: =(A10+1)*50 -> 500 | D10: =(A10+1)*50 -> 500 | E10: =3*A10^2+2*A10+55 -> 316
A11: 10 | B11: =E11 -> 375 | C11: =(A11+1)*50 -> 550 | D11: =(A11+1)*50 -> 550 | E11: =3*A11^2+2*A11+55 -> 375
A12: 11 | B12: =E12 -> 440 | C12: =(A12+1)*50 -> 600 | D12: =(A12+1)*50 -> 600 | E12: =3*A12^2+2*A12+55 -> 440
A13: 12 | B13: =E13 -> 511 | C13: =(A13+1)*50 -> 650 | D13: =(A13+1)*50 -> 650 | E13: =3*A13^2+2*A13+55 -> 511
... A71: 70 | B71: =E71 -> 14895 | C71: =(A71+1)*50 -> 3550 | D71: =(A71+1)*50 -> 3550 | E71: =3*A71^2+2*A71+55 -> 14895

Sheet 职业设计
A1: 职业区分 | J1: 初始力量 | K1: 10 | N1: 初始生命值 | O1: 0 | R1: 佣兵相对于主角属性比例 | S1: 1 | X1: 全职业
J2: 力量成长 | K2: 1 | N2: 生命值成长 | O2: 0 | X2: 战士
B3: 战士 | C3: 猎人 | D3: 法师 | E3: 佣兵战士 | F3: 佣兵猎人 | G3: 佣兵法师 | J3: 初始敏捷 | K3: 10 | N3: 初始魔法值 | O3: 20 | R3: 佣兵培养价格 | X3: 猎人
A4: 初始力量 | B4: 1.4 | C4: 1 | D4: 1 | E4: =B4*$S$1 -> 1.4 | F4: =C4*$S$1 -> 1 | G4: =D4*$S$1 -> 1 | J4: 敏捷成长 | K4: 1 | N4: 魔法值成长 | O4: 20 | R4: 普通培养 | S4: 500*等级 | X4: 法师
A5: 初始敏捷 | B5: 1 | C5: 1.5 | D5: 1 | E5: =B5*$S$1 -> 1 | F5: =C5*$S$1 -> 1.5 | G5: =D5*$S$1 -> 1 | J5: 初始智力 | K5: 10 | N5: 初始护甲 | O5: 0 | R5: 高级培养
A6: 初始智力 | B6: 1 | C6: 1 | D6: 1.5 | E6: =B6*$S$1 -> 1 | F6: =C6*$S$1 -> 1 | G6: =D6*$S$1 -> 1.5 | J6: 智力成长 | K6: 1 | N6: 护甲成长 | O6: 0 | R6: 白金培养
A7: 初始耐力 | B7: 1.3 | C7: 1.2 | D7: 1.2 | E7: =B7*$S$1 -> 1.3 | F7: =C7*$S$1 -> 1.2 | G7: =D7*$S$1 -> 1.2 | J7: 初始耐力 | K7: 10 | N7: 初始最小伤害 | O7: 5 | R7: 至尊培养
A8: 力量成长 | B8: 3 | C8: 1 | D8: 1 | E8: =B8*$S$1 -> 3 | F8: =C8*$S$1 -> 1 | G8: =D8*$S$1 -> 1 | J8: 耐力成长 | K8: 2 | N8: 初始最大伤害 | O8: 10
A9: 敏捷成长 | B9: 1 | C9: 3 | D9: 1 | E9: =B9*$S$1 -> 1 | F9: =C9*$S$1 -> 3 | G9: =D9*$S$1 -> 1
A10: 智力成长 | B10: 1 | C10: 1 | D10: 3 | E10: =B10*$S$1 -> 1 | F10: =C10*$S$1 -> 1 | G10: =D10*$S$1 -> 3 | J10: 1 | K10: 力量 | L10: = | M10: =J10*1 -> 1 | N10: 物抗 | O10: + | P10: =J10*1 -> 1 | Q10: 命中
A11: 耐力成长 | B11: 1 | C11: 1 | D11: 1 | E11: =B11*$S$1 -> 1 | F11: =C11*$S$1 -> 1 | G11: =D11*$S$1 -> 1 | J11: 1 | K11: 敏捷 | L11: = | M11: =J11*1 -> 1 | N11: 暴击 | O11: + | P11: =J11*0.2 -> 0.2 | Q11: 闪避
A12: 初始生命值 | B12: 1 | C12: 1 | D12: 1 | E12: =B12*$S$1 -> 1 | F12: =C12*$S$1 -> 1 | G12: =D12*$S$1 -> 1 | J12: 1 | K12: 智力 | L12: = | M12: =J12*1 -> 1 | N12: 魔抗 | O12: + | P12: =ROUNDDOWN(J12^(1/2),0) -> 1 | Q12: 每回合魔法回复
A13: 初始魔法值 | B13: 1 | C13: 1 | D13: 1 | E13: =B13*$S$1 -> 1 | F13: =C13*$S$1 -> 1 | G13: =D13*$S$1 -> 1 | J13: 1 | K13: 耐力 | L13: = | M13: =J13*10 -> 10 | N13: 血量 | O13: + | P13: =J13*1 -> 1 | Q13: 韧性
A14: 初始护甲 | B14: 1 | C14: 1 | D14: 1 | E14: =B14*$S$1 -> 1 | F14: =C14*$S$1 -> 1 | G14: =D14*$S$1 -> 1
A15: 生命值成长 | B15: 1 | C15: 1 | D15: 1 | E15: =B15*$S$1 -> 1 | F15: =C15*$S$1 -> 1 | G15: =D15*$S$1 -> 1 | J15: 1 | K15: 主属性 | L15: = | M15: =J15/2 -> 0.5 | N15: 最小伤害 | O15: + | P15: =J15 -> 1 | Q15: 最大伤害
A16: 魔法值成长 | B16: 1 | C16: 1 | D16: 1 | E16: =B16*$S$1 -> 1 | F16: =C16*$S$1 -> 1 | G16: =D16*$S$1 -> 1
A17: 护甲成长 | B17: 1 | C17: 1 | D17: 1 | E17: =B17*$S$1 -> 1 | F17: =C17*$S$1 -> 1 | G17: =D17*$S$1 -> 1
A18: 初始最小伤害 | B18: 1 | C18: 1 | D18: 1 | E18: =B18*$S$1 -> 1 | F18: =C18*$S$1 -> 1 | G18: =D18*$S$1 -> 1
A19: 初始最大伤害 | B19: 1 | C19: 1 | D19: 1 | E19: =B19*$S$1 -> 1 | F19: =C19*$S$1 -> 1 | G19: =D19*$S$1 -> 1
A21: 战士 | R21: 猎人 | AI21: 法师
A22: 等级 | B22: 力量 | C22: 敏捷 | D22: 智力 | E22: 耐力 | F22: 生命值 | G22: 魔法值 | H22: 最小伤害 | I22: 最大伤害 | J22: 护甲 | K22: 物抗 | L22: 魔抗 | M22: 暴击 | N22: 命中 | O22: 闪避 | P22: 韧性 | R22: 等级 | S22: 力量 | T22: 敏捷 | U22: 智力 | V22: 耐力 | W22: 生命值 | X22: 魔法值 | Y22: 最小伤害 | Z22: 最大伤害 | AA22: 护甲 | AB22: 物抗 | AC22: 魔抗 | AD22: 暴击 | AE22: 命中 | AF22: 闪避 | AG22: 韧性 | AI22: 等级 | AJ22: 力量 | AK22: 敏捷 | AL22: 智力 | AM22: 耐力 | AN22: 生命值 | AO22: 魔法值 | AP22: 最小伤害 | AQ22: 最大伤害 | AR22: 护甲 | AS22: 物抗 | AT22: 魔抗 | AU22: 暴击 | AV22: 命中 | AW22: 闪避 | AX22: 韧性
A23: 1 | B23: =$K$1*INDEX($A$3:$G$19,2,MATCH($A$21,$A$3:$G$3,0))+(A23-1)*$K$2*INDEX($A$3:$G$19,6,MATCH($A$21,$A$3:$G$3,0)) -> 14 | C23: =$K$3*INDEX($A$3:$G$19,3,MATCH($A$21,$A$3:$G$3,0))+(A23-1)*$K$4*INDEX($A$3:$G$19,7,MATCH($A$21,$A$3:$G$3,0)) -> 10 | D23: =$K$5*INDEX($A$3:$G$19,4,MATCH($A$21,$A$3:$G$3,0))+(A23-1)*$K$6*INDEX($A$3:$G$19,8,MATCH($A$21,$A$3:$G$3,0)) -> 10 | E23: =$K$7*INDEX($A$3:$G$19,5,MATCH($A$21,$A$3:$G$3,0))+(A23-1)*$K$8*INDEX($A$3:$G$19,9,MATCH($A$21,$A$3:$G$3,0)) -> 13 | F23: =$O$1*INDEX($A$3:$G$19,10,MATCH($A$21,$A$3:$G$3,0))+(A23-1)*$O$2*INDEX($A$3:$G$19,13,MATCH($A$21,$A$3:$G$3,0))+E23*$M$13 -> 130 | G23: =$O$3*INDEX($A$3:$G$19,11,MATCH($A$21,$A$3:$G$3,0))+(A23-1)*$O$4*INDEX($A$3:$G$19,14,MATCH($A$21,$A$3:$G$3,0)) -> 20 | H23: =$O$7*INDEX($A$3:$G$19,16,MATCH($A$21,$A$3:$G$3,0))+$M$15*IF(OR($A$21="战士",$A$21="佣兵战士"),B23,IF(OR($A$21="猎人",$A$21="佣兵猎人"),C23,D23)) -> 12 | I23: =$O$8*INDEX($A$3:$G$19,17,MATCH($A$21,$A$3:$G$3,0))+$P$15*IF(OR($A$21="战士",$A$21="佣兵战士"),B23,IF(OR($A$21="猎人",$A$21="佣兵猎人"),C23,D23)) -> 24 | J23: =$O$5*INDEX($A$3:$G$19,12,MATCH($A$21,$A$3:$G$3,0))+(A23-1)*$O$6*INDEX($A$3:$G$19,15,MATCH($A$21,$A$3:$G$3,0)) -> 0 | K23: =B23*$M$10 -> 14 | L23: =D23*$M$12 -> 10 | M23: =C23*$M$11 -> 10 | N23: =B23*$P$10 -> 14 | O23: =C23*$P$11 -> 2 | P23: =E23*$P$13 -> 13 | R23: 1 | S23: =$K$1*INDEX($A$3:$G$19,2,MATCH($R$21,$A$3:$G$3,0))+(R23-1)*$K$2*INDEX($A$3:$G$19,6,MATCH($R$21,$A$3:$G$3,0)) -> 10 | T23: =$K$3*INDEX($A$3:$G$19,3,MATCH($R$21,$A$3:$G$3,0))+(R23-1)*$K$4*INDEX($A$3:$G$19,7,MATCH($R$21,$A$3:$G$3,0)) -> 15 | U23: =$K$5*INDEX($A$3:$G$19,4,MATCH($R$21,$A$3:$G$3,0))+(R23-1)*$K$6*INDEX($A$3:$G$19,8,MATCH($R$21,$A$3:$G$3,0)) -> 10 | V23: =$K$7*INDEX($A$3:$G$19,5,MATCH($R$21,$A$3:$G$3,0))+(R23-1)*$K$8*INDEX($A$3:$G$19,9,MATCH($R$21,$A$3:$G$3,0)) -> 12 | W23: =$O$1*INDEX($A$3:$G$19,10,MATCH($R$21,$A$3:$G$3,0))+(R23-1)*$O$2*INDEX($A$3:$G$19,13,MATCH($R$21,$A$3:$G$3,0))+V23*$M$13 -> 120 | X23: =$O$3*INDEX($A$3:$G$19,11,MATCH($R$21,$A$3:$G$3,0))+(R23-1)*$O$4*INDEX($A$3:$G$19,14,MATCH($R$21,$A$3:$G$3,0)) -> 20 | Y23: =$O$7*INDEX($A$3:$G$19,16,MATCH($R$21,$A$3:$G$3,0))+$M$15*IF(OR($R$21="战士",$R$21="佣兵战士"),S23,IF(OR($R$21="猎人",$R$21="佣兵猎人"),T23,U23)) -> 12.5 | Z23: =$O$8*INDEX($A$3:$G$19,17,MATCH($R$21,$A$3:$G$3,0))+$P$15*IF(OR($R$21="战士",$R$21="佣兵战士"),S23,IF(OR($R$21="猎人",$R$21="佣兵猎人"),T23,U23)) -> 25 | AA23: =$O$5*INDEX($A$3:$G$19,12,MATCH($R$21,$A$3:$G$3,0))+(R23-1)*$O$6*INDEX($A$3:$G$19,15,MATCH($R$21,$A$3:$G$3,0)) -> 0 | AB23: =S23*$M$10 -> 10 | AC23: =U23*$M$12 -> 10 | AD23: =T23*$M$11 -> 15 | AE23: =S23*$P$10 -> 10 | AF23: =T23*$P$11 -> 3 | AG23: =V23*$P$13 -> 12 | AI23: 1 | AJ23: =$K$1*INDEX($A$3:$G$19,2,MATCH($AI$21,$A$3:$G$3,0))+(AI23-1)*$K$2*INDEX($A$3:$G$19,6,MATCH($AI$21,$A$3:$G$3,0)) -> 10 | AK23: =$K$3*INDEX($A$3:$G$19,3,MATCH($AI$21,$A$3:$G$3,0))+(AI23-1)*$K$4*INDEX($A$3:$G$19,7,MATCH($AI$21,$A$3:$G$3,0)) -> 10 | AL23: =$K$5*INDEX($A$3:$G$19,4,MATCH($AI$21,$A$3:$G$3,0))+(AI23-1)*$K$6*INDEX($A$3:$G$19,8,MATCH($AI$21,$A$3:$G$3,0)) -> 15 | AM23: =$K$7*INDEX($A$3:$G$19,5,MATCH($AI$21,$A$3:$G$3,0))+(AI23-1)*$K$8*INDEX($A$3:$G$19,9,MATCH($AI$21,$A$3:$G$3,0)) -> 12 | AN23: =$O$1*INDEX($A$3:$G$19,10,MATCH($AI$21,$A$3:$G$3,0))+(AI23-1)*$O$2*INDEX($A$3:$G$19,13,MATCH($AI$21,$A$3:$G$3,0))+AM23*$M$13 -> 120 | AO23: =$O$3*INDEX($A$3:$G$19,11,MATCH($AI$21,$A$3:$G$3,0))+(AI23-1)*$O$4*INDEX($A$3:$G$19,14,MATCH($AI$21,$A$3:$G$3,0)) -> 20 | AP23: =$O$7*INDEX($A$3:$G$19,16,MATCH($AI$21,$A$3:$G$3,0))+$M$15*IF(OR($AI$21="战士",$AI$21="佣兵战士"),AJ23,IF(OR($AI$21="猎人",$AI$21="佣兵猎人"),AK23,AL23)) -> 12.5 | AQ23: =$O$8*INDEX($A$3:$G$19,17,MATCH($AI$21,$A$3:$G$3,0))+$P$15*IF(OR($AI$21="战士",$AI$21="佣兵战士"),AJ23,IF(OR($AI$21="猎人",$AI$21="佣兵猎人"),AK23,AL23)) -> 25 | AR23: =$O$5*INDEX($A$3:$G$19,12,MATCH($AI$21,$A$3:$G$3,0))+(AI23-1)*$O$6*INDEX($A$3:$G$19,15,MATCH($AI$21,$A$3:$G$3,0)) -> 0 | AS23: =AJ23*$M$10 -> 10 | AT23: =AL23*$M$12 -> 15 | AU23: =AK23*$M$11 -> 10 | AV23: =AJ23*$P$10 -> 10 | AW23: =AK23*$P$11 -> 2 | AX23: =AM23*$P$13 -> 12
A24: 2 | B24: =$K$1*INDEX($A$3:$G$19,2,MATCH($A$21,$A$3:$G$3,0))+(A24-1)*$K$2*INDEX($A$3:$G$19,6,MATCH($A$21,$A$3:$G$3,0)) -> 17 | C24: =$K$3*INDEX($A$3:$G$19,3,MATCH($A$21,$A$3:$G$3,0))+(A24-1)*$K$4*INDEX($A$3:$G$19,7,MATCH($A$21,$A$3:$G$3,0)) -> 11 | D24: =$K$5*INDEX($A$3:$G$19,4,MATCH($A$21,$A$3:$G$3,0))+(A24-1)*$K$6*INDEX($A$3:$G$19,8,MATCH($A$21,$A$3:$G$3,0)) -> 11 | E24: =$K$7*INDEX($A$3:$G$19,5,MATCH($A$21,$A$3:$G$3,0))+(A24-1)*$K$8*INDEX($A$3:$G$19,9,MATCH($A$21,$A$3:$G$3,0)) -> 15 | F24: =$O$1*INDEX($A$3:$G$19,10,MATCH($A$21,$A$3:$G$3,0))+(A24-1)*$O$2*INDEX($A$3:$G$19,13,MATCH($A$21,$A$3:$G$3,0))+E24*$M$13 -> 150 | G24: =$O$3*INDEX($A$3:$G$19,11,MATCH($A$21,$A$3:$G$3,0))+(A24-1)*$O$4*INDEX($A$3:$G$19,14,MATCH($A$21,$A$3:$G$3,0)) -> 40 | H24: =$O$7*INDEX($A$3:$G$19,16,MATCH($A$21,$A$3:$G$3,0))+$M$15*IF(OR($A$21="战士",$A$21="佣兵战士"),B24,IF(OR($A$21="猎人",$A$21="佣兵猎人"),C24,D24)) -> 13.5 | I24: =$O$8*INDEX($A$3:$G$19,17,MATCH($A$21,$A$3:$G$3,0))+$P$15*IF(OR($A$21="战士",$A$21="佣兵战士"),B24,IF(OR($A$21="猎人",$A$21="佣兵猎人"),C24,D24)) -> 27 | J24: =$O$5*INDEX($A$3:$G$19,12,MATCH($A$21,$A$3:$G$3,0))+(A24-1)*$O$6*INDEX($A$3:$G$19,15,MATCH($A$21,$A$3:$G$3,0)) -> 0 | K24: =B24*$M$10 -> 17 | L24: =D24*$M$12 -> 11 | M24: =C24*$M$11 -> 11 | N24: =B24*$P$10 -> 17 | O24: =C24*$P$11 -> 2.2 | P24: =E24*$P$13 -> 15 | R24: 2 | S24: =$K$1*INDEX($A$3:$G$19,2,MATCH($R$21,$A$3:$G$3,0))+(R24-1)*$K$2*INDEX($A$3:$G$19,6,MATCH($R$21,$A$3:$G$3,0)) -> 11 | T24: =$K$3*INDEX($A$3:$G$19,3,MATCH($R$21,$A$3:$G$3,0))+(R24-1)*$K$4*INDEX($A$3:$G$19,7,MATCH($R$21,$A$3:$G$3,0)) -> 18 | U24: =$K$5*INDEX($A$3:$G$19,4,MATCH($R$21,$A$3:$G$3,0))+(R24-1)*$K$6*INDEX($A$3:$G$19,8,MATCH($R$21,$A$3:$G$3,0)) -> 11 | V24: =$K$7*INDEX($A$3:$G$19,5,MATCH($R$21,$A$3:$G$3,0))+(R24-1)*$K$8*INDEX($A$3:$G$19,9,MATCH($R$21,$A$3:$G$3,0)) -> 14 | W24: =$O$1*INDEX($A$3:$G$19,10,MATCH($R$21,$A$3:$G$3,0))+(R24-1)*$O$2*INDEX($A$3:$G$19,13,MATCH($R$21,$A$3:$G$3,0))+V24*$M$13 -> 140 | X24: =$O$3*INDEX($A$3:$G$19,11,MATCH($R$21,$A$3:$G$3,0))+(R24-1)*$O$4*INDEX($A$3:$G$19,14,MATCH($R$21,$A$3:$G$3,0)) -> 40 | Y24: =$O$7*INDEX($A$3:$G$19,16,MATCH($R$21,$A$3:$G$3,0))+$M$15*IF(OR($R$21="战士",$R$21="佣兵战士"),S24,IF(OR($R$21="猎人",$R$21="佣兵猎人"),T24,U24)) -> 14 | Z24: =$O$8*INDEX($A$3:$G$19,17,MATCH($R$21,$A$3:$G$3,0))+$P$15*IF(OR($R$21="战士",$R$21="佣兵战士"),S24,IF(OR($R$21="猎人",$R$21="佣兵猎人"),T24,U24)) -> 28 | AA24: =$O$5*INDEX($A$3:$G$19,12,MATCH($R$21,$A$3:$G$3,0))+(R24-1)*$O$6*INDEX($A$3:$G$19,15,MATCH($R$21,$A$3:$G$3,0)) -> 0 | AB24: =S24*$M$10 -> 11 | AC24: =U24*$M$12 -> 11 | AD24: =T24*$M$11 -> 18 | AE24: =S24*$P$10 -> 11 | AF24: =T24*$P$11 -> 3.6 | AG24: =V24*$P$13 -> 14 | AI24: 2 | AJ24: =$K$1*INDEX($A$3:$G$19,2,MATCH($AI$21,$A$3:$G$3,0))+(AI24-1)*$K$2*INDEX($A$3:$G$19,6,MATCH($AI$21,$A$3:$G$3,0)) -> 11 | AK24: =$K$3*INDEX($A$3:$G$19,3,MATCH($AI$21,$A$3:$G$3,0))+(AI24-1)*$K$4*INDEX($A$3:$G$19,7,MATCH($AI$21,$A$3:$G$3,0)) -> 11 | AL24: =$K$5*INDEX($A$3:$G$19,4,MATCH($AI$21,$A$3:$G$3,0))+(AI24-1)*$K$6*INDEX($A$3:$G$19,8,MATCH($AI$21,$A$3:$G$3,0)) -> 18 | AM24: =$K$7*INDEX($A$3:$G$19,5,MATCH($AI$21,$A$3:$G$3,0))+(AI24-1)*$K$8*INDEX($A$3:$G$19,9,MATCH($AI$21,$A$3:$G$3,0)) -> 14 | AN24: =$O$1*INDEX($A$3:$G$19,10,MATCH($AI$21,$A$3:$G$3,0))+(AI24-1)*$O$2*INDEX($A$3:$G$19,13,MATCH($AI$21,$A$3:$G$3,0))+AM24*$M$13 -> 140 | AO24: =$O$3*INDEX($A$3:$G$19,11,MATCH($AI$21,$A$3:$G$3,0))+(AI24-1)*$O$4*INDEX($A$3:$G$19,14,MATCH($AI$21,$A$3:$G$3,0)) -> 40 | AP24: =$O$7*INDEX($A$3:$G$19,16,MATCH($AI$21,$A$3:$G$3,0))+$M$15*IF(OR($AI$21="战士",$AI$21="佣兵战士"),AJ24,IF(OR($AI$21="猎人",$AI$21="佣兵猎人"),AK24,AL24)) -> 14 | AQ24: =$O$8*INDEX($A$3:$G$19,17,MATCH($AI$21,$A$3:$G$3,0))+$P$15*IF(OR($AI$21="战士",$AI$21="佣兵战士"),AJ24,IF(OR($AI$21="猎人",$AI$21="佣兵猎人"),AK24,AL24)) -> 28 | AR24: =$O$5*INDEX($A$3:$G$19,12,MATCH($AI$21,$A$3:$G$3,0))+(AI24-1)*$O$6*INDEX($A$3:$G$19,15,MATCH($AI$21,$A$3:$G$3,0)) -> 0 | AS24: =AJ24*$M$10 -> 11 | AT24: =AL24*$M$12 -> 18 | AU24: =AK24*$M$11 -> 11 | AV24: =AJ24*$P$10 -> 11 | AW24: =AK24*$P$11 -> 2.2 | AX24: =AM24*$P$13 -> 14
A25: 3 | B25: =$K$1*INDEX($A$3:$G$19,2,MATCH($A$21,$A$3:$G$3,0))+(A25-1)*$K$2*INDEX($A$3:$G$19,6,MATCH($A$21,$A$3:$G$3,0)) -> 20 | C25: =$K$3*INDEX($A$3:$G$19,3,MATCH($A$21,$A$3:$G$3,0))+(A25-1)*$K$4*INDEX($A$3:$G$19,7,MATCH($A$21,$A$3:$G$3,0)) -> 12 | D25: =$K$5*INDEX($A$3:$G$19,4,MATCH($A$21,$A$3:$G$3,0))+(A25-1)*$K$6*INDEX($A$3:$G$19,8,MATCH($A$21,$A$3:$G$3,0)) -> 12 | E25: =$K$7*INDEX($A$3:$G$19,5,MATCH($A$21,$A$3:$G$3,0))+(A25-1)*$K$8*INDEX($A$3:$G$19,9,MATCH($A$21,$A$3:$G$3,0)) -> 17 | F25: =$O$1*INDEX($A$3:$G$19,10,MATCH($A$21,$A$3:$G$3,0))+(A25-1)*$O$2*INDEX($A$3:$G$19,13,MATCH($A$21,$A$3:$G$3,0))+E25*$M$13 -> 170 | G25: =$O$3*INDEX($A$3:$G$19,11,MATCH($A$21,$A$3:$G$3,0))+(A25-1)*$O$4*INDEX($A$3:$G$19,14,MATCH($A$21,$A$3:$G$3,0)) -> 60 | H25: =$O$7*INDEX($A$3:$G$19,16,MATCH($A$21,$A$3:$G$3,0))+$M$15*IF(OR($A$21="战士",$A$21="佣兵战士"),B25,IF(OR($A$21="猎人",$A$21="佣兵猎人"),C25,D25)) -> 15 | I25: =$O$8*INDEX($A$3:$G$19,17,MATCH($A$21,$A$3:$G$3,0))+$P$15*IF(OR($A$21="战士",$A$21="佣兵战士"),B25,IF(OR($A$21="猎人",$A$21="佣兵猎人"),C25,D25)) -> 30 | J25: =$O$5*INDEX($A$3:$G$19,12,MATCH($A$21,$A$3:$G$3,0))+(A25-1)*$O$6*INDEX($A$3:$G$19,15,MATCH($A$21,$A$3:$G$3,0)) -> 0 | K25: =B25*$M$10 -> 20 | L25: =D25*$M$12 -> 12 | M25: =C25*$M$11 -> 12 | N25: =B25*$P$10 -> 20 | O25: =C25*$P$11 -> 2.4 | P25: =E25*$P$13 -> 17 | R25: 3 | S25: =$K$1*INDEX($A$3:$G$19,2,MATCH($R$21,$A$3:$G$3,0))+(R25-1)*$K$2*INDEX($A$3:$G$19,6,MATCH($R$21,$A$3:$G$3,0)) -> 12 | T25: =$K$3*INDEX($A$3:$G$19,3,MATCH($R$21,$A$3:$G$3,0))+(R25-1)*$K$4*INDEX($A$3:$G$19,7,MATCH($R$21,$A$3:$G$3,0)) -> 21 | U25: =$K$5*INDEX($A$3:$G$19,4,MATCH($R$21,$A$3:$G$3,0))+(R25-1)*$K$6*INDEX($A$3:$G$19,8,MATCH($R$21,$A$3:$G$3,0)) -> 12 | V25: =$K$7*INDEX($A$3:$G$19,5,MATCH($R$21,$A$3:$G$3,0))+(R25-1)*$K$8*INDEX($A$3:$G$19,9,MATCH($R$21,$A$3:$G$3,0)) -> 16 | W25: =$O$1*INDEX($A$3:$G$19,10,MATCH($R$21,$A$3:$G$3,0))+(R25-1)*$O$2*INDEX($A$3:$G$19,13,MATCH($R$21,$A$3:$G$3,0))+V25*$M$13 -> 160 | X25: =$O$3*INDEX($A$3:$G$19,11,MATCH($R$21,$A$3:$G$3,0))+(R25-1)*$O$4*INDEX($A$3:$G$19,14,MATCH($R$21,$A$3:$G$3,0)) -> 60 | Y25: =$O$7*INDEX($A$3:$G$19,16,MATCH($R$21,$A$3:$G$3,0))+$M$15*IF(OR($R$21="战士",$R$21="佣兵战士"),S25,IF(OR($R$21="猎人",$R$21="佣兵猎人"),T25,U25)) -> 15.5 | Z25: =$O$8*INDEX($A$3:$G$19,17,MATCH($R$21,$A$3:$G$3,0))+$P$15*IF(OR($R$21="战士",$R$21="佣兵战士"),S25,IF(OR($R$21="猎人",$R$21="佣兵猎人"),T25,U25)) -> 31 | AA25: =$O$5*INDEX($A$3:$G$19,12,MATCH($R$21,$A$3:$G$3,0))+(R25-1)*$O$6*INDEX($A$3:$G$19,15,MATCH($R$21,$A$3:$G$3,0)) -> 0 | AB25: =S25*$M$10 -> 12 | AC25: =U25*$M$12 -> 12 | AD25: =T25*$M$11 -> 21 | AE25: =S25*$P$10 -> 12 | AF25: =T25*$P$11 -> 4.2 | AG25: =V25*$P$13 -> 16 | AI25: 3 | AJ25: =$K$1*INDEX($A$3:$G$19,2,MATCH($AI$21,$A$3:$G$3,0))+(AI25-1)*$K$2*INDEX($A$3:$G$19,6,MATCH($AI$21,$A$3:$G$3,0)) -> 12 | AK25: =$K$3*INDEX($A$3:$G$19,3,MATCH($AI$21,$A$3:$G$3,0))+(AI25-1)*$K$4*INDEX($A$3:$G$19,7,MATCH($AI$21,$A$3:$G$3,0)) -> 12 | AL25: =$K$5*INDEX($A$3:$G$19,4,MATCH($AI$21,$A$3:$G$3,0))+(AI25-1)*$K$6*INDEX($A$3:$G$19,8,MATCH($AI$21,$A$3:$G$3,0)) -> 21 | AM25: =$K$7*INDEX($A$3:$G$19,5,MATCH($AI$21,$A$3:$G$3,0))+(AI25-1)*$K$8*INDEX($A$3:$G$19,9,MATCH($AI$21,$A$3:$G$3,0)) -> 16 | AN25: =$O$1*INDEX($A$3:$G$19,10,MATCH($AI$21,$A$3:$G$3,0))+(AI25-1)*$O$2*INDEX($A$3:$G$19,13,MATCH($AI$21,$A$3:$G$3,0))+AM25*$M$13 -> 160 | AO25: =$O$3*INDEX($A$3:$G$19,11,MATCH($AI$21,$A$3:$G$3,0))+(AI25-1)*$O$4*INDEX($A$3:$G$19,14,MATCH($AI$21,$A$3:$G$3,0)) -> 60 | AP25: =$O$7*INDEX($A$3:$G$19,16,MATCH($AI$21,$A$3:$G$3,0))+$M$15*IF(OR($AI$21="战士",$AI$21="佣兵战士"),AJ25,IF(OR($AI$21="猎人",$AI$21="佣兵猎人"),AK25,AL25)) -> 15.5 | AQ25: =$O$8*INDEX($A$3:$G$19,17,MATCH($AI$21,$A$3:$G$3,0))+$P$15*IF(OR($AI$21="战士",$AI$21="佣兵战士"),AJ25,IF(OR($AI$21="猎人",$AI$21="佣兵猎人"),AK25,AL25)) -> 31 | AR25: =$O$5*INDEX($A$3:$G$19,12,MATCH($AI$21,$A$3:$G$3,0))+(AI25-1)*$O$6*INDEX($A$3:$G$19,15,MATCH($AI$21,$A$3:$G$3,0)) -> 0 | AS25: =AJ25*$M$10 -> 12 | AT25: =AL25*$M$12 -> 21 | AU25: =AK25*$M$11 -> 12 | AV25: =AJ25*$P$10 -> 12 | AW25: =AK25*$P$11 -> 2.4 | AX25: =AM25*$P$13 -> 16
A26: 4 | B26: =$K$1*INDEX($A$3:$G$19,2,MATCH($A$21,$A$3:$G$3,0))+(A26-1)*$K$2*INDEX($A$3:$G$19,6,MATCH($A$21,$A$3:$G$3,0)) -> 23 | C26: =$K$3*INDEX($A$3:$G$19,3,MATCH($A$21,$A$3:$G$3,0))+(A26-1)*$K$4*INDEX($A$3:$G$19,7,MATCH($A$21,$A$3:$G$3,0)) -> 13 | D26: =$K$5*INDEX($A$3:$G$19,4,MATCH($A$21,$A$3:$G$3,0))+(A26-1)*$K$6*INDEX($A$3:$G$19,8,MATCH($A$21,$A$3:$G$3,0)) -> 13 | E26: =$K$7*INDEX($A$3:$G$19,5,MATCH($A$21,$A$3:$G$3,0))+(A26-1)*$K$8*INDEX($A$3:$G$19,9,MATCH($A$21,$A$3:$G$3,0)) -> 19 | F26: =$O$1*INDEX($A$3:$G$19,10,MATCH($A$21,$A$3:$G$3,0))+(A26-1)*$O$2*INDEX($A$3:$G$19,13,MATCH($A$21,$A$3:$G$3,0))+E26*$M$13 -> 190 | G26: =$O$3*INDEX($A$3:$G$19,11,MATCH($A$21,$A$3:$G$3,0))+(A26-1)*$O$4*INDEX($A$3:$G$19,14,MATCH($A$21,$A$3:$G$3,0)) -> 80 | H26: =$O$7*INDEX($A$3:$G$19,16,MATCH($A$21,$A$3:$G$3,0))+$M$15*IF(OR($A$21="战士",$A$21="佣兵战士"),B26,IF(OR($A$21="猎人",$A$21="佣兵猎人"),C26,D26)) -> 16.5 | I26: =$O$8*INDEX($A$3:$G$19,17,MATCH($A$21,$A$3:$G$3,0))+$P$15*IF(OR($A$21="战士",$A$21="佣兵战士"),B26,IF(OR($A$21="猎人",$A$21="佣兵猎人"),C26,D26)) -> 33 | J26: =$O$5*INDEX($A$3:$G$19,12,MATCH($A$21,$A$3:$G$3,0))+(A26-1)*$O$6*INDEX($A$3:$G$19,15,MATCH($A$21,$A$3:$G$3,0)) -> 0 | K26: =B26*$M$10 -> 23 | L26: =D26*$M$12 -> 13 | M26: =C26*$M$11 -> 13 | N26: =B26*$P$10 -> 23 | O26: =C26*$P$11 -> 2.6 | P26: =E26*$P$13 -> 19 | R26: 4 | S26: =$K$1*INDEX($A$3:$G$19,2,MATCH($R$21,$A$3:$G$3,0))+(R26-1)*$K$2*INDEX($A$3:$G$19,6,MATCH($R$21,$A$3:$G$3,0)) -> 13 | T26: =$K$3*INDEX($A$3:$G$19,3,MATCH($R$21,$A$3:$G$3,0))+(R26-1)*$K$4*INDEX($A$3:$G$19,7,MATCH($R$21,$A$3:$G$3,0)) -> 24 | U26: =$K$5*INDEX($A$3:$G$19,4,MATCH($R$21,$A$3:$G$3,0))+(R26-1)*$K$6*INDEX($A$3:$G$19,8,MATCH($R$21,$A$3:$G$3,0)) -> 13 | V26: =$K$7*INDEX($A$3:$G$19,5,MATCH($R$21,$A$3:$G$3,0))+(R26-1)*$K$8*INDEX($A$3:$G$19,9,MATCH($R$21,$A$3:$G$3,0)) -> 18 | W26: =$O$1*INDEX($A$3:$G$19,10,MATCH($R$21,$A$3:$G$3,0))+(R26-1)*$O$2*INDEX($A$3:$G$19,13,MATCH($R$21,$A$3:$G$3,0))+V26*$M$13 -> 180 | X26: =$O$3*INDEX($A$3:$G$19,11,MATCH($R$21,$A$3:$G$3,0))+(R26-1)*$O$4*INDEX($A$3:$G$19,14,MATCH($R$21,$A$3:$G$3,0)) -> 80 | Y26: =$O$7*INDEX($A$3:$G$19,16,MATCH($R$21,$A$3:$G$3,0))+$M$15*IF(OR($R$21="战士",$R$21="佣兵战士"),S26,IF(OR($R$21="猎人",$R$21="佣兵猎人"),T26,U26)) -> 17 | Z26: =$O$8*INDEX($A$3:$G$19,17,MATCH($R$21,$A$3:$G$3,0))+$P$15*IF(OR($R$21="战士",$R$21="佣兵战士"),S26,IF(OR($R$21="猎人",$R$21="佣兵猎人"),T26,U26)) -> 34 | AA26: =$O$5*INDEX($A$3:$G$19,12,MATCH($R$21,$A$3:$G$3,0))+(R26-1)*$O$6*INDEX($A$3:$G$19,15,MATCH($R$21,$A$3:$G$3,0)) -> 0 | AB26: =S26*$M$10 -> 13 | AC26: =U26*$M$12 -> 13 | AD26: =T26*$M$11 -> 24 | AE26: =S26*$P$10 -> 13 | AF26: =T26*$P$11 -> 4.8 | AG26: =V26*$P$13 -> 18 | AI26: 4 | AJ26: =$K$1*INDEX($A$3:$G$19,2,MATCH($AI$21,$A$3:$G$3,0))+(AI26-1)*$K$2*INDEX($A$3:$G$19,6,MATCH($AI$21,$A$3:$G$3,0)) -> 13 | AK26: =$K$3*INDEX($A$3:$G$19,3,MATCH($AI$21,$A$3:$G$3,0))+(AI26-1)*$K$4*INDEX($A$3:$G$19,7,MATCH($AI$21,$A$3:$G$3,0)) -> 13 | AL26: =$K$5*INDEX($A$3:$G$19,4,MATCH($AI$21,$A$3:$G$3,0))+(AI26-1)*$K$6*INDEX($A$3:$G$19,8,MATCH($AI$21,$A$3:$G$3,0)) -> 24 | AM26: =$K$7*INDEX($A$3:$G$19,5,MATCH($AI$21,$A$3:$G$3,0))+(AI26-1)*$K$8*INDEX($A$3:$G$19,9,MATCH($AI$21,$A$3:$G$3,0)) -> 18 | AN26: =$O$1*INDEX($A$3:$G$19,10,MATCH($AI$21,$A$3:$G$3,0))+(AI26-1)*$O$2*INDEX($A$3:$G$19,13,MATCH($AI$21,$A$3:$G$3,0))+AM26*$M$13 -> 180 | AO26: =$O$3*INDEX($A$3:$G$19,11,MATCH($AI$21,$A$3:$G$3,0))+(AI26-1)*$O$4*INDEX($A$3:$G$19,14,MATCH($AI$21,$A$3:$G$3,0)) -> 80 | AP26: =$O$7*INDEX($A$3:$G$19,16,MATCH($AI$21,$A$3:$G$3,0))+$M$15*IF(OR($AI$21="战士",$AI$21="佣兵战士"),AJ26,IF(OR($AI$21="猎人",$AI$21="佣兵猎人"),AK26,AL26)) -> 17 | AQ26: =$O$8*INDEX($A$3:$G$19,17,MATCH($AI$21,$A$3:$G$3,0))+$P$15*IF(OR($AI$21="战士",$AI$21="佣兵战士"),AJ26,IF(OR($AI$21="猎人",$AI$21="佣兵猎人"),AK26,AL26)) -> 34 | AR26: =$O$5*INDEX($A$3:$G$19,12,MATCH($AI$21,$A$3:$G$3,0))+(AI26-1)*$O$6*INDEX($A$3:$G$19,15,MATCH($AI$21,$A$3:$G$3,0)) -> 0 | AS26: =AJ26*$M$10 -> 13 | AT26: =AL26*$M$12 -> 24 | AU26: =AK26*$M$11 -> 13 | AV26: =AJ26*$P$10 -> 13 | AW26: =AK26*$P$11 -> 2.6 | AX26: =AM26*$P$13 -> 18
A27: 5 | B27: =$K$1*INDEX($A$3:$G$19,2,MATCH($A$21,$A$3:$G$3,0))+(A27-1)*$K$2*INDEX($A$3:$G$19,6,MATCH($A$21,$A$3:$G$3,0)) -> 26 | C27: =$K$3*INDEX($A$3:$G$19,3,MATCH($A$21,$A$3:$G$3,0))+(A27-1)*$K$4*INDEX($A$3:$G$19,7,MATCH($A$21,$A$3:$G$3,0)) -> 14 | D27: =$K$5*INDEX($A$3:$G$19,4,MATCH($A$21,$A$3:$G$3,0))+(A27-1)*$K$6*INDEX($A$3:$G$19,8,MATCH($A$21,$A$3:$G$3,0)) -> 14 | E27: =$K$7*INDEX($A$3:$G$19,5,MATCH($A$21,$A$3:$G$3,0))+(A27-1)*$K$8*INDEX($A$3:$G$19,9,MATCH($A$21,$A$3:$G$3,0)) -> 21 | F27: =$O$1*INDEX($A$3:$G$19,10,MATCH($A$21,$A$3:$G$3,0))+(A27-1)*$O$2*INDEX($A$3:$G$19,13,MATCH($A$21,$A$3:$G$3,0))+E27*$M$13 -> 210 | G27: =$O$3*INDEX($A$3:$G$19,11,MATCH($A$21,$A$3:$G$3,0))+(A27-1)*$O$4*INDEX($A$3:$G$19,14,MATCH($A$21,$A$3:$G$3,0)) -> 100 | H27: =$O$7*INDEX($A$3:$G$19,16,MATCH($A$21,$A$3:$G$3,0))+$M$15*IF(OR($A$21="战士",$A$21="佣兵战士"),B27,IF(OR($A$21="猎人",$A$21="佣兵猎人"),C27,D27)) -> 18 | I27: =$O$8*INDEX($A$3:$G$19,17,MATCH($A$21,$A$3:$G$3,0))+$P$15*IF(OR($A$21="战士",$A$21="佣兵战士"),B27,IF(OR($A$21="猎人",$A$21="佣兵猎人"),C27,D27)) -> 36 | J27: =$O$5*INDEX($A$3:$G$19,12,MATCH($A$21,$A$3:$G$3,0))+(A27-1)*$O$6*INDEX($A$3:$G$19,15,MATCH($A$21,$A$3:$G$3,0)) -> 0 | K27: =B27*$M$10 -> 26 | L27: =D27*$M$12 -> 14 | M27: =C27*$M$11 -> 14 | N27: =B27*$P$10 -> 26 | O27: =C27*$P$11 -> 2.8 | P27: =E27*$P$13 -> 21 | R27: 5 | S27: =$K$1*INDEX($A$3:$G$19,2,MATCH($R$21,$A$3:$G$3,0))+(R27-1)*$K$2*INDEX($A$3:$G$19,6,MATCH($R$21,$A$3:$G$3,0)) -> 14 | T27: =$K$3*INDEX($A$3:$G$19,3,MATCH($R$21,$A$3:$G$3,0))+(R27-1)*$K$4*INDEX($A$3:$G$19,7,MATCH($R$21,$A$3:$G$3,0)) -> 27 | U27: =$K$5*INDEX($A$3:$G$19,4,MATCH($R$21,$A$3:$G$3,0))+(R27-1)*$K$6*INDEX($A$3:$G$19,8,MATCH($R$21,$A$3:$G$3,0)) -> 14 | V27: =$K$7*INDEX($A$3:$G$19,5,MATCH($R$21,$A$3:$G$3,0))+(R27-1)*$K$8*INDEX($A$3:$G$19,9,MATCH($R$21,$A$3:$G$3,0)) -> 20 | W27: =$O$1*INDEX($A$3:$G$19,10,MATCH($R$21,$A$3:$G$3,0))+(R27-1)*$O$2*INDEX($A$3:$G$19,13,MATCH($R$21,$A$3:$G$3,0))+V27*$M$13 -> 200 | X27: =$O$3*INDEX($A$3:$G$19,11,MATCH($R$21,$A$3:$G$3,0))+(R27-1)*$O$4*INDEX($A$3:$G$19,14,MATCH($R$21,$A$3:$G$3,0)) -> 100 | Y27: =$O$7*INDEX($A$3:$G$19,16,MATCH($R$21,$A$3:$G$3,0))+$M$15*IF(OR($R$21="战士",$R$21="佣兵战士"),S27,IF(OR($R$21="猎人",$R$21="佣兵猎人"),T27,U27)) -> 18.5 | Z27: =$O$8*INDEX($A$3:$G$19,17,MATCH($R$21,$A$3:$G$3,0))+$P$15*IF(OR($R$21="战士",$R$21="佣兵战士"),S27,IF(OR($R$21="猎人",$R$21="佣兵猎人"),T27,U27)) -> 37 | AA27: =$O$5*INDEX($A$3:$G$19,12,MATCH($R$21,$A$3:$G$3,0))+(R27-1)*$O$6*INDEX($A$3:$G$19,15,MATCH($R$21,$A$3:$G$3,0)) -> 0 | AB27: =S27*$M$10 -> 14 | AC27: =U27*$M$12 -> 14 | AD27: =T27*$M$11 -> 27 | AE27: =S27*$P$10 -> 14 | AF27: =T27*$P$11 -> 5.4 | AG27: =V27*$P$13 -> 20 | AI27: 5 | AJ27: =$K$1*INDEX($A$3:$G$19,2,MATCH($AI$21,$A$3:$G$3,0))+(AI27-1)*$K$2*INDEX($A$3:$G$19,6,MATCH($AI$21,$A$3:$G$3,0)) -> 14 | AK27: =$K$3*INDEX($A$3:$G$19,3,MATCH($AI$21,$A$3:$G$3,0))+(AI27-1)*$K$4*INDEX($A$3:$G$19,7,MATCH($AI$21,$A$3:$G$3,0)) -> 14 | AL27: =$K$5*INDEX($A$3:$G$19,4,MATCH($AI$21,$A$3:$G$3,0))+(AI27-1)*$K$6*INDEX($A$3:$G$19,8,MATCH($AI$21,$A$3:$G$3,0)) -> 27 | AM27: =$K$7*INDEX($A$3:$G$19,5,MATCH($AI$21,$A$3:$G$3,0))+(AI27-1)*$K$8*INDEX($A$3:$G$19,9,MATCH($AI$21,$A$3:$G$3,0)) -> 20 | AN27: =$O$1*INDEX($A$3:$G$19,10,MATCH($AI$21,$A$3:$G$3,0))+(AI27-1)*$O$2*INDEX($A$3:$G$19,13,MATCH($AI$21,$A$3:$G$3,0))+AM27*$M$13 -> 200 | AO27: =$O$3*INDEX($A$3:$G$19,11,MATCH($AI$21,$A$3:$G$3,0))+(AI27-1)*$O$4*INDEX($A$3:$G$19,14,MATCH($AI$21,$A$3:$G$3,0)) -> 100 | AP27: =$O$7*INDEX($A$3:$G$19,16,MATCH($AI$21,$A$3:$G$3,0))+$M$15*IF(OR($AI$21="战士",$AI$21="佣兵战士"),AJ27,IF(OR($AI$21="猎人",$AI$21="佣兵猎人"),AK27,AL27)) -> 18.5 | AQ27: =$O$8*INDEX($A$3:$G$19,17,MATCH($AI$21,$A$3:$G$3,0))+$P$15*IF(OR($AI$21="战士",$AI$21="佣兵战士"),AJ27,IF(OR($AI$21="猎人",$AI$21="佣兵猎人"),AK27,AL27)) -> 37 | AR27: =$O$5*INDEX($A$3:$G$19,12,MATCH($AI$21,$A$3:$G$3,0))+(AI27-1)*$O$6*INDEX($A$3:$G$19,15,MATCH($AI$21,$A$3:$G$3,0)) -> 0 | AS27: =AJ27*$M$10 -> 14 | AT27: =AL27*$M$12 -> 27 | AU27: =AK27*$M$11 -> 14 | AV27: =AJ27*$P$10 -> 14 | AW27: =AK27*$P$11 -> 2.8 | AX27: =AM27*$P$13 -> 20
A28: 6 | B28: =$K$1*INDEX($A$3:$G$19,2,MATCH($A$21,$A$3:$G$3,0))+(A28-1)*$K$2*INDEX($A$3:$G$19,6,MATCH($A$21,$A$3:$G$3,0)) -> 29 | C28: =$K$3*INDEX($A$3:$G$19,3,MATCH($A$21,$A$3:$G$3,0))+(A28-1)*$K$4*INDEX($A$3:$G$19,7,MATCH($A$21,$A$3:$G$3,0)) -> 15 | D28: =$K$5*INDEX($A$3:$G$19,4,MATCH($A$21,$A$3:$G$3,0))+(A28-1)*$K$6*INDEX($A$3:$G$19,8,MATCH($A$21,$A$3:$G$3,0)) -> 15 | E28: =$K$7*INDEX($A$3:$G$19,5,MATCH($A$21,$A$3:$G$3,0))+(A28-1)*$K$8*INDEX($A$3:$G$19,9,MATCH($A$21,$A$3:$G$3,0)) -> 23 | F28: =$O$1*INDEX($A$3:$G$19,10,MATCH($A$21,$A$3:$G$3,0))+(A28-1)*$O$2*INDEX($A$3:$G$19,13,MATCH($A$21,$A$3:$G$3,0))+E28*$M$13 -> 230 | G28: =$O$3*INDEX($A$3:$G$19,11,MATCH($A$21,$A$3:$G$3,0))+(A28-1)*$O$4*INDEX($A$3:$G$19,14,MATCH($A$21,$A$3:$G$3,0)) -> 120 | H28: =$O$7*INDEX($A$3:$G$19,16,MATCH($A$21,$A$3:$G$3,0))+$M$15*IF(OR($A$21="战士",$A$21="佣兵战士"),B28,IF(OR($A$21="猎人",$A$21="佣兵猎人"),C28,D28)) -> 19.5 | I28: =$O$8*INDEX($A$3:$G$19,17,MATCH($A$21,$A$3:$G$3,0))+$P$15*IF(OR($A$21="战士",$A$21="佣兵战士"),B28,IF(OR($A$21="猎人",$A$21="佣兵猎人"),C28,D28)) -> 39 | J28: =$O$5*INDEX($A$3:$G$19,12,MATCH($A$21,$A$3:$G$3,0))+(A28-1)*$O$6*INDEX($A$3:$G$19,15,MATCH($A$21,$A$3:$G$3,0)) -> 0 | K28: =B28*$M$10 -> 29 | L28: =D28*$M$12 -> 15 | M28: =C28*$M$11 -> 15 | N28: =B28*$P$10 -> 29 | O28: =C28*$P$11 -> 3 | P28: =E28*$P$13 -> 23 | R28: 6 | S28: =$K$1*INDEX($A$3:$G$19,2,MATCH($R$21,$A$3:$G$3,0))+(R28-1)*$K$2*INDEX($A$3:$G$19,6,MATCH($R$21,$A$3:$G$3,0)) -> 15 | T28: =$K$3*INDEX($A$3:$G$19,3,MATCH($R$21,$A$3:$G$3,0))+(R28-1)*$K$4*INDEX($A$3:$G$19,7,MATCH($R$21,$A$3:$G$3,0)) -> 30 | U28: =$K$5*INDEX($A$3:$G$19,4,MATCH($R$21,$A$3:$G$3,0))+(R28-1)*$K$6*INDEX($A$3:$G$19,8,MATCH($R$21,$A$3:$G$3,0)) -> 15 | V28: =$K$7*INDEX($A$3:$G$19,5,MATCH($R$21,$A$3:$G$3,0))+(R28-1)*$K$8*INDEX($A$3:$G$19,9,MATCH($R$21,$A$3:$G$3,0)) -> 22 | W28: =$O$1*INDEX($A$3:$G$19,10,MATCH($R$21,$A$3:$G$3,0))+(R28-1)*$O$2*INDEX($A$3:$G$19,13,MATCH($R$21,$A$3:$G$3,0))+V28*$M$13 -> 220 | X28: =$O$3*INDEX($A$3:$G$19,11,MATCH($R$21,$A$3:$G$3,0))+(R28-1)*$O$4*INDEX($A$3:$G$19,14,MATCH($R$21,$A$3:$G$3,0)) -> 120 | Y28: =$O$7*INDEX($A$3:$G$19,16,MATCH($R$21,$A$3:$G$3,0))+$M$15*IF(OR($R$21="战士",$R$21="佣兵战士"),S28,IF(OR($R$21="猎人",$R$21="佣兵猎人"),T28,U28)) -> 20 | Z28: =$O$8*INDEX($A$3:$G$19,17,MATCH($R$21,$A$3:$G$3,0))+$P$15*IF(OR($R$21="战士",$R$21="佣兵战士"),S28,IF(OR($R$21="猎人",$R$21="佣兵猎人"),T28,U28)) -> 40 | AA28: =$O$5*INDEX($A$3:$G$19,12,MATCH($R$21,$A$3:$G$3,0))+(R28-1)*$O$6*INDEX($A$3:$G$19,15,MATCH($R$21,$A$3:$G$3,0)) -> 0 | AB28: =S28*$M$10 -> 15 | AC28: =U28*$M$12 -> 15 | AD28: =T28*$M$11 -> 30 | AE28: =S28*$P$10 -> 15 | AF28: =T28*$P$11 -> 6 | AG28: =V28*$P$13 -> 22 | AI28: 6 | AJ28: =$K$1*INDEX($A$3:$G$19,2,MATCH($AI$21,$A$3:$G$3,0))+(AI28-1)*$K$2*INDEX($A$3:$G$19,6,MATCH($AI$21,$A$3:$G$3,0)) -> 15 | AK28: =$K$3*INDEX($A$3:$G$19,3,MATCH($AI$21,$A$3:$G$3,0))+(AI28-1)*$K$4*INDEX($A$3:$G$19,7,MATCH($AI$21,$A$3:$G$3,0)) -> 15 | AL28: =$K$5*INDEX($A$3:$G$19,4,MATCH($AI$21,$A$3:$G$3,0))+(AI28-1)*$K$6*INDEX($A$3:$G$19,8,MATCH($AI$21,$A$3:$G$3,0)) -> 30 | AM28: =$K$7*INDEX($A$3:$G$19,5,MATCH($AI$21,$A$3:$G$3,0))+(AI28-1)*$K$8*INDEX($A$3:$G$19,9,MATCH($AI$21,$A$3:$G$3,0)) -> 22 | AN28: =$O$1*INDEX($A$3:$G$19,10,MATCH($AI$21,$A$3:$G$3,0))+(AI28-1)*$O$2*INDEX($A$3:$G$19,13,MATCH($AI$21,$A$3:$G$3,0))+AM28*$M$13 -> 220 | AO28: =$O$3*INDEX($A$3:$G$19,11,MATCH($AI$21,$A$3:$G$3,0))+(AI28-1)*$O$4*INDEX($A$3:$G$19,14,MATCH($AI$21,$A$3:$G$3,0)) -> 120 | AP28: =$O$7*INDEX($A$3:$G$19,16,MATCH($AI$21,$A$3:$G$3,0))+$M$15*IF(OR($AI$21="战士",$AI$21="佣兵战士"),AJ28,IF(OR($AI$21="猎人",$AI$21="佣兵猎人"),AK28,AL28)) -> 20 | AQ28: =$O$8*INDEX($A$3:$G$19,17,MATCH($AI$21,$A$3:$G$3,0))+$P$15*IF(OR($AI$21="战士",$AI$21="佣兵战士"),AJ28,IF(OR($AI$21="猎人",$AI$21="佣兵猎人"),AK28,AL28)) -> 40 | AR28: =$O$5*INDEX($A$3:$G$19,12,MATCH($AI$21,$A$3:$G$3,0))+(AI28-1)*$O$6*INDEX($A$3:$G$19,15,MATCH($AI$21,$A$3:$G$3,0)) -> 0 | AS28: =AJ28*$M$10 -> 15 | AT28: =AL28*$M$12 -> 30 | AU28: =AK28*$M$11 -> 15 | AV28: =AJ28*$P$10 -> 15 | AW28: =AK28*$P$11 -> 3 | AX28: =AM28*$P$13 -> 22
A29: 7 | B29: =$K$1*INDEX($A$3:$G$19,2,MATCH($A$21,$A$3:$G$3,0))+(A29-1)*$K$2*INDEX($A$3:$G$19,6,MATCH($A$21,$A$3:$G$3,0)) -> 32 | C29: =$K$3*INDEX($A$3:$G$19,3,MATCH($A$21,$A$3:$G$3,0))+(A29-1)*$K$4*INDEX($A$3:$G$19,7,MATCH($A$21,$A$3:$G$3,0)) -> 16 | D29: =$K$5*INDEX($A$3:$G$19,4,MATCH($A$21,$A$3:$G$3,0))+(A29-1)*$K$6*INDEX($A$3:$G$19,8,MATCH($A$21,$A$3:$G$3,0)) -> 16 | E29: =$K$7*INDEX($A$3:$G$19,5,MATCH($A$21,$A$3:$G$3,0))+(A29-1)*$K$8*INDEX($A$3:$G$19,9,MATCH($A$21,$A$3:$G$3,0)) -> 25 | F29: =$O$1*INDEX($A$3:$G$19,10,MATCH($A$21,$A$3:$G$3,0))+(A29-1)*$O$2*INDEX($A$3:$G$19,13,MATCH($A$21,$A$3:$G$3,0))+E29*$M$13 -> 250 | G29: =$O$3*INDEX($A$3:$G$19,11,MATCH($A$21,$A$3:$G$3,0))+(A29-1)*$O$4*INDEX($A$3:$G$19,14,MATCH($A$21,$A$3:$G$3,0)) -> 140 | H29: =$O$7*INDEX($A$3:$G$19,16,MATCH($A$21,$A$3:$G$3,0))+$M$15*IF(OR($A$21="战士",$A$21="佣兵战士"),B29,IF(OR($A$21="猎人",$A$21="佣兵猎人"),C29,D29)) -> 21 | I29: =$O$8*INDEX($A$3:$G$19,17,MATCH($A$21,$A$3:$G$3,0))+$P$15*IF(OR($A$21="战士",$A$21="佣兵战士"),B29,IF(OR($A$21="猎人",$A$21="佣兵猎人"),C29,D29)) -> 42 | J29: =$O$5*INDEX($A$3:$G$19,12,MATCH($A$21,$A$3:$G$3,0))+(A29-1)*$O$6*INDEX($A$3:$G$19,15,MATCH($A$21,$A$3:$G$3,0)) -> 0 | K29: =B29*$M$10 -> 32 | L29: =D29*$M$12 -> 16 | M29: =C29*$M$11 -> 16 | N29: =B29*$P$10 -> 32 | O29: =C29*$P$11 -> 3.2 | P29: =E29*$P$13 -> 25 | R29: 7 | S29: =$K$1*INDEX($A$3:$G$19,2,MATCH($R$21,$A$3:$G$3,0))+(R29-1)*$K$2*INDEX($A$3:$G$19,6,MATCH($R$21,$A$3:$G$3,0)) -> 16 | T29: =$K$3*INDEX($A$3:$G$19,3,MATCH($R$21,$A$3:$G$3,0))+(R29-1)*$K$4*INDEX($A$3:$G$19,7,MATCH($R$21,$A$3:$G$3,0)) -> 33 | U29: =$K$5*INDEX($A$3:$G$19,4,MATCH($R$21,$A$3:$G$3,0))+(R29-1)*$K$6*INDEX($A$3:$G$19,8,MATCH($R$21,$A$3:$G$3,0)) -> 16 | V29: =$K$7*INDEX($A$3:$G$19,5,MATCH($R$21,$A$3:$G$3,0))+(R29-1)*$K$8*INDEX($A$3:$G$19,9,MATCH($R$21,$A$3:$G$3,0)) -> 24 | W29: =$O$1*INDEX($A$3:$G$19,10,MATCH($R$21,$A$3:$G$3,0))+(R29-1)*$O$2*INDEX($A$3:$G$19,13,MATCH($R$21,$A$3:$G$3,0))+V29*$M$13 -> 240 | X29: =$O$3*INDEX($A$3:$G$19,11,MATCH($R$21,$A$3:$G$3,0))+(R29-1)*$O$4*INDEX($A$3:$G$19,14,MATCH($R$21,$A$3:$G$3,0)) -> 140 | Y29: =$O$7*INDEX($A$3:$G$19,16,MATCH($R$21,$A$3:$G$3,0))+$M$15*IF(OR($R$21="战士",$R$21="佣兵战士"),S29,IF(OR($R$21="猎人",$R$21="佣兵猎人"),T29,U29)) -> 21.5 | Z29: =$O$8*INDEX($A$3:$G$19,17,MATCH($R$21,$A$3:$G$3,0))+$P$15*IF(OR($R$21="战士",$R$21="佣兵战士"),S29,IF(OR($R$21="猎人",$R$21="佣兵猎人"),T29,U29)) -> 43 | AA29: =$O$5*INDEX($A$3:$G$19,12,MATCH($R$21,$A$3:$G$3,0))+(R29-1)*$O$6*INDEX($A$3:$G$19,15,MATCH($R$21,$A$3:$G$3,0)) -> 0 | AB29: =S29*$M$10 -> 16 | AC29: =U29*$M$12 -> 16 | AD29: =T29*$M$11 -> 33 | AE29: =S29*$P$10 -> 16 | AF29: =T29*$P$11 -> 6.6 | AG29: =V29*$P$13 -> 24 | AI29: 7 | AJ29: =$K$1*INDEX($A$3:$G$19,2,MATCH($AI$21,$A$3:$G$3,0))+(AI29-1)*$K$2*INDEX($A$3:$G$19,6,MATCH($AI$21,$A$3:$G$3,0)) -> 16 | AK29: =$K$3*INDEX($A$3:$G$19,3,MATCH($AI$21,$A$3:$G$3,0))+(AI29-1)*$K$4*INDEX($A$3:$G$19,7,MATCH($AI$21,$A$3:$G$3,0)) -> 16 | AL29: =$K$5*INDEX($A$3:$G$19,4,MATCH($AI$21,$A$3:$G$3,0))+(AI29-1)*$K$6*INDEX($A$3:$G$19,8,MATCH($AI$21,$A$3:$G$3,0)) -> 33 | AM29: =$K$7*INDEX($A$3:$G$19,5,MATCH($AI$21,$A$3:$G$3,0))+(AI29-1)*$K$8*INDEX($A$3:$G$19,9,MATCH($AI$21,$A$3:$G$3,0)) -> 24 | AN29: =$O$1*INDEX($A$3:$G$19,10,MATCH($AI$21,$A$3:$G$3,0))+(AI29-1)*$O$2*INDEX($A$3:$G$19,13,MATCH($AI$21,$A$3:$G$3,0))+AM29*$M$13 -> 240 | AO29: =$O$3*INDEX($A$3:$G$19,11,MATCH($AI$21,$A$3:$G$3,0))+(AI29-1)*$O$4*INDEX($A$3:$G$19,14,MATCH($AI$21,$A$3:$G$3,0)) -> 140 | AP29: =$O$7*INDEX($A$3:$G$19,16,MATCH($AI$21,$A$3:$G$3,0))+$M$15*IF(OR($AI$21="战士",$AI$21="佣兵战士"),AJ29,IF(OR($AI$21="猎人",$AI$21="佣兵猎人"),AK29,AL29)) -> 21.5 | AQ29: =$O$8*INDEX($A$3:$G$19,17,MATCH($AI$21,$A$3:$G$3,0))+$P$15*IF(OR($AI$21="战士",$AI$21="佣兵战士"),AJ29,IF(OR($AI$21="猎人",$AI$21="佣兵猎人"),AK29,AL29)) -> 43 | AR29: =$O$5*INDEX($A$3:$G$19,12,MATCH($AI$21,$A$3:$G$3,0))+(AI29-1)*$O$6*INDEX($A$3:$G$19,15,MATCH($AI$21,$A$3:$G$3,0)) -> 0 | AS29: =AJ29*$M$10 -> 16 | AT29: =AL29*$M$12 -> 33 | AU29: =AK29*$M$11 -> 16 | AV29: =AJ29*$P$10 -> 16 | AW29: =AK29*$P$11 -> 3.2 | AX29: =AM29*$P$13 -> 24
