Workbook

Sheet 天天挂机经验
A1: 1 | B1: =ROUND(POWER(A1,4)*5-70/3*POWER(A1,3)+25*POWER(A1,2)+23*A1-25,0) -> 5
A2: 2 | B2: =ROUND(POWER(A2,4)*5-70/3*POWER(A2,3)+25*POWER(A2,2)+23*A2-25,0) -> 14
A3: 3 | B3: =ROUND(POWER(A3,4)*5-70/3*POWER(A3,3)+25*POWER(A3,2)+23*A3-25,0) -> 44
A4: 4 | B4: =ROUND(POWER(A4,4)*5-70/3*POWER(A4,3)+25*POWER(A4,2)+23*A4-25,0) -> 254
A5: 5 | B5: =ROUND(POWER(A5,4)*5-70/3*POWER(A5,3)+25*POWER(A5,2)+23*A5-25,0) -> 923
A6: 6 | B6: =ROUND(POWER(A6,4)*5-70/3*POWER(A6,3)+25*POWER(A6,2)+23*A6-25,0) -> 2453
A7: 7 | B7: =ROUND(POWER(A7,4)*5-70/3*POWER(A7,3)+25*POWER(A7,2)+23*A7-25,0) -> 5363
A8: 8 | B8: =ROUND(POWER(A8,4)*5-70/3*POWER(A8,3)+25*POWER(A8,2)+23*A8-25,0) -> 10292
A9: 9 | B9: =ROUND(POWER(A9,4)*5-70/3*POWER(A9,3)+25*POWER(A9,2)+23*A9-25,0) -> 18002
A10: 10 | B10: =ROUND(POWER(A10,4)*5-70/3*POWER(A10,3)+25*POWER(A10,2)+23*A10-25,0) -> 29372
A11: 11 | B11: =ROUND(POWER(A11,4)*5-70/3*POWER(A11,3)+25*POWER(A11,2)+23*A11-25,0) -> 45401
A12: 12 | B12: =ROUND(POWER(A12,4)*5-70/3*POWER(A12,3)+25*POWER(A12,2)+23*A12-25,0) -> 67211
... A70: 70 | B70: =ROUND(POWER(A70,4)*5-70/3*POWER(A70,3)+25*POWER(A70,2)+23*A70-25,0) -> 112170752
A71: 71 | B71: 118834800
A72: 72 | B72: 125791410
A73: 73 | B73: 133049040
A74: 74 | B74: 140616250
A75: 75 | B75: 148501720
A76: 76 | B76: 156714250
A77: 77 | B77: 165262760
A78: 78 | B78: 174156290
A79: 79 | B79: =ROUND(POWER(A79,4)*5-70/3*POWER(A79,3)+25*POWER(A79,2)+23*A79-25,0) -> 183403979
A80: 80 | B80: =ROUND(POWER(A80,4)*5-70/3*POWER(A80,3)+25*POWER(A80,2)+23*A80-25,0) -> 193015148
A81: 81 | B81: =ROUND(POWER(A81,4)*5-70/3*POWER(A81,3)+25*POWER(A81,2)+23*A81-25,0) -> 202999178
A82: 82 | B82: =ROUND(POWER(A82,4)*5-70/3*POWER(A82,3)+25*POWER(A82,2)+23*A82-25,0) -> 213365588
A83: 83 | B83: =ROUND(POWER(A83,4)*5-70/3*POWER(A83,3)+25*POWER(A83,2)+23*A83-25,0) -> 224124017
A84: 84 | B84: =ROUND(POWER(A84,4)*5-70/3*POWER(A84,3)+25*POWER(A84,2)+23*A84-25,0) -> 235284227
A85: 85 | B85: =ROUND(POWER(A85,4)*5-70/3*POWER(A85,3)+25*POWER(A85,2)+23*A85-25,0) -> 246856097
A86: 86 | B86: =ROUND(POWER(A86,4)*5-70/3*POWER(A86,3)+25*POWER(A86,2)+23*A86-25,0) -> 258849626
A87: 87 | B87: =ROUND(POWER(A87,4)*5-70/3*POWER(A87,3)+25*POWER(A87,2)+23*A87-25,0) -> 271274936
A88: 88 | B88: =ROUND(POWER(A88,4)*5-70/3*POWER(A88,3)+25*POWER(A88,2)+23*A88-25,0) -> 284142266
A89: 89 | B89: =ROUND(POWER(A89,4)*5-70/3*POWER(A89,3)+25*POWER(A89,2)+23*A89-25,0) -> 297461975
A90: 90 | B90: =ROUND(POWER(A90,4)*5-70/3*POWER(A90,3)+25*POWER(A90,2)+23*A90-25,0) -> 311244545
... A100: 100 | B100: =ROUND(POWER(A100,4)*5-70/3*POWER(A100,3)+25*POWER(A100,2)+23*A100-25,0) -> 476918942

Sheet 数值拟合
A1: 鞋子 | D1: 手套 | G1: 戒指 | J1: 武器 | M1: 抗性 | P1: 腰带 | S1: 护甲 | V1: 副手
A2: 6 | B2: 4 | D2: 6 | E2: 12 | G2: 8 | H2: 80 | J2: 1 | K2: 8 | M2: 8 | N2: 20 | P2: 5 | Q2: 100 | S2: 3 | T2: 3 | V2: 2 | W2: 4
A3: 12 | B3: 12 | D3: 12 | E3: 43 | G3: 14 | H3: 150 | J3: 4 | K3: 17 | M3: 14 | N3: 64 | P3: 11 | Q3: 480 | S3: 7 | T3: 9 | V3: 6 | W3: 12
A4: 18 | B4: 24 | D4: 18 | E4: 106 | G4: 17 | H4: 190 | J4: 7 | K4: 30 | M4: 17 | N4: 96 | P4: 17 | Q4: 1160 | S4: 11 | T4: 20 | V4: 10 | W4: 30
A5: 24 | B5: 40 | D5: 24 | E5: 211 | G5: 20 | H5: 240 | J5: 10 | K5: 56 | M5: 20 | N5: 136 | P5: 23 | Q5: 2120 | S5: 15 | T5: 39 | V5: 14 | W5: 60
A6: 27 | B6: 49 | D6: 27 | E6: 282 | G6: 26 | H6: 340 | J6: 13 | K6: 98 | M6: 26 | N6: 237 | P6: 29 | Q6: 3360 | S6: 19 | T6: 66 | V6: 18 | W6: 106
A7: 30 | B7: 59 | D7: 30 | E7: 368 | G7: 32 | H7: 460 | J7: 16 | K7: 156 | M7: 32 | N7: 372 | P7: 32 | Q7: 4100 | S7: 23 | T7: 104 | V7: 22 | W7: 171
A8: 36 | B8: 82 | D8: 36 | E8: 588 | G8: 38 | H8: 590 | J8: 19 | K8: 234 | M8: 38 | N8: 542 | P8: 35 | Q8: 4900 | S8: 27 | T8: 153 | V8: 26 | W8: 257
A9: 42 | B9: 108 | D9: 42 | E9: 880 | G9: 44 | H9: 740 | J9: 22 | K9: 339 | M9: 44 | N9: 751 | P9: 41 | Q9: 6720 | S9: 31 | T9: 216 | V9: 30 | W9: 368
A10: 48 | B10: 138 | D10: 48 | E10: 1256 | G10: 47 | H10: 820 | J10: 25 | K10: 471 | M10: 47 | N10: 870 | P10: 47 | Q10: 8840 | S10: 35 | T10: 293 | V10: 34 | W10: 507
A11: 54 | B11: 172 | D11: 54 | E11: 1726 | G11: 50 | H11: 900 | J11: 28 | K11: 630 | M11: 50 | N11: 1000 | P11: 53 | Q11: 11240 | S11: 39 | T11: 387 | V11: 38 | W11: 676
A12: 57 | B12: 190 | D12: 57 | E12: 1999 | G12: 56 | H12: 1080 | J12: 31 | K12: 825 | M12: 56 | N12: 1292 | P12: 59 | Q12: 13920 | S12: 43 | T12: 498 | V12: 42 | W12: 880
A13: 60 | B13: 209 | D13: 60 | E13: 2300 | G13: 62 | H13: 1260 | J13: 34 | K13: 1059 | M13: 62 | N13: 1629 | P13: 62 | Q13: 15380 | S13: 47 | T13: 629 | V13: 46 | W13: 1121
... A20: 96 | B20: 508 | D20: 96 | E20: 8510 | G20: 98 | H20: 2700 | J20: 55 | K20: 3993 | M20: 98 | N20: 4763 | P20: 95 | Q20: 36000 | S20: 75 | T20: 2217 | V20: 74 | W20: 4102
J21: 58 | K21: 4641 | S21: 79 | T21: 2558 | V21: 78 | W21: 4750
J22: 61 | K22: 5352 | S22: 83 | T22: 2933 | V22: 82 | W22: 5462
J23: 64 | K23: 6132 | S23: 87 | T23: 3342 | V23: 86 | W23: 6243
J24: 67 | K24: 6987 | S24: 91 | T24: 3788 | V24: 90 | W24: 7094
J25: 70 | K25: 7917 | S25: 95 | T25: 4271 | V25: 94 | W25: 8019
J26: 73 | K26: 8925 | V26: 98 | W26: 9021
J27: 76 | K27: 10017
J28: 79 | K28: 11193
J29: 82 | K29: 12459
J30: 85 | K30: 13821
J31: 88 | K31: 15273
J32: 91 | K32: 16827
J33: 94 | K33: 18480
J34: 97 | K34: 20238
J35: 100 | K35: 22107

Sheet 特效
A1: 戒指 | B1: 金币掉落
A2: 腰带 | B2: 最大生命值
A3: 胸甲 | B3: 免控
A4: 护腿 | B4: 反伤
A5: 副手 | B5: 破甲
A6: 武器 | B6: 吸血
A7: 项链 | B7: 装备掉落
A8: 头盔 | B8: 回血
A9: 鞋子 | B9: 获得经验
A10: 手套 | B10: 暴击伤害

Sheet 经验值
A1: 人物等级 | B1: 升级经验 | C1: 怪物等级 | D1: 怪物经验 | E1: 升级杀怪数 | F1: 所需时间 | G1: 所需时间(小时) | H1: 累计时间（小时） | I1: 累计时间（天） | K1: 标准战斗时间
A2: 1 | B2: 10 | C2: 1 | D2: 10 | E2: =B2/D2 -> 1 | F2: =E2*$K$2 -> 20 | G2: =F2/3600 -> 0.0055555556 | H2: =G2 -> 0.0055555556 | I2: =H2/24 -> 0.00023148148 | K2: 20
A3: 2 | B3: 30 | C3: 2 | D3: 12 | E3: =B3/D3 -> 2.5 | F3: =E3*$K$2 -> 50 | G3: =F3/3600 -> 0.013888889 | H3: =H2+G3 -> 0.019444444 | I3: =H3/24 -> 0.00081018519
A4: 3 | B4: 210 | C4: 3 | D4: 14 | E4: =B4/D4 -> 15 | F4: =E4*$K$2 -> 300 | G4: =F4/3600 -> 0.083333333 | H4: =H3+G4 -> 0.10277778 | I4: =H4/24 -> 0.0042824074
A5: 4 | B5: 670 | C5: 4 | D5: 16 | E5: =B5/D5 -> 41.875 | F5: =E5*$K$2 -> 837.5 | G5: =F5/3600 -> 0.23263889 | H5: =H4+G5 -> 0.33541667 | I5: =H5/24 -> 0.013975694
A6: 5 | B6: 1530 | C6: 5 | D6: 18 | E6: =B6/D6 -> 85 | F6: =E6*$K$2 -> 1700 | G6: =F6/3600 -> 0.47222222 | H6: =H5+G6 -> 0.80763889 | I6: =H6/24 -> 0.03365162
A7: 6 | B7: 2910 | C7: 6 | D7: 20 | E7: =B7/D7 -> 145.5 | F7: =E7*$K$2 -> 2910 | G7: =F7/3600 -> 0.80833333 | H7: =H6+G7 -> 1.6159722 | I7: =H7/24 -> 0.067332176
A8: 7 | B8: 4930 | C8: 7 | D8: 22 | E8: =B8/D8 -> 224.09091 | F8: =E8*$K$2 -> 4481.8182 | G8: =F8/3600 -> 1.2449495 | H8: =H7+G8 -> 2.8609217 | I8: =H8/24 -> 0.11920507
A9: 8 | B9: 7710 | C9: 8 | D9: 24 | E9: =B9/D9 -> 321.25 | F9: =E9*$K$2 -> 6425 | G9: =F9/3600 -> 1.7847222 | H9: =H8+G9 -> 4.6456439 | I9: =H9/24 -> 0.1935685
A10: 9 | B10: 11370 | C10: 9 | D10: 28 | E10: =B10/D10 -> 406.07143 | F10: =E10*$K$2 -> 8121.4286 | G10: =F10/3600 -> 2.2559524 | H10: =H9+G10 -> 6.9015963 | I10: =H10/24 -> 0.28756651
A11: 10 | B11: 16030 | C11: 10 | D11: 32 | E11: =B11/D11 -> 500.9375 | F11: =E11*$K$2 -> 10018.75 | G11: =F11/3600 -> 2.7829861 | H11: =H10+G11 -> 9.6845824 | I11: =H11/24 -> 0.40352427
A12: 11 | B12: 21810 | C12: 11 | D12: 36 | E12: =B12/D12 -> 605.83333 | F12: =E12*$K$2 -> 12116.667 | G12: =F12/3600 -> 3.3657407 | H12: =H11+G12 -> 13.050323 | I12: =H12/24 -> 0.54376347
A13: 12 | B13: 28830 | C13: 12 | D13: 40 | E13: =B13/D13 -> 720.75 | F13: =E13*$K$2 -> 14415 | G13: =F13/3600 -> 4.0041667 | H13: =H12+G13 -> 17.05449 | I13: =H13/24 -> 0.71060374
A14: 13 | B14: 37210 | C14: 13 | D14: 44 | E14: =B14/D14 -> 845.68182 | F14: =E14*$K$2 -> 16913.636 | G14: =F14/3600 -> 4.6982323 | H14: =H13+G14 -> 21.752722 | I14: =H14/24 -> 0.90636342
... A71: 70 | B71: 6664030 | C71: 70 | D71: 502 | E71: =B71/D71 -> 13274.96 | F71: =E71*$K$2 -> 265499.2 | G71: =F71/3600 -> 73.749779 | H71: =H70+G71 -> 2152.0301 | I71: =H71/24 -> 89.667921
A74: 高5级打怪
A75: 人物等级 | B75: 升级经验 | C75: 怪物等级 | D75: 怪物经验
A76: 1 | B76: 10 | C76: 1 | D76: 10 | E76: =B76/D76 -> 1 | F76: =E76*$K$2 -> 20 | G76: =F76/3600 -> 0.0055555556 | H76: =H75+G76 -> 0.0055555556 | I76: =H76/24 -> 0.00023148148
A77: 2 | B77: 30 | C77: 2 | D77: 12 | E77: =B77/D77 -> 2.5 | F77: =E77*$K$2 -> 50 | G77: =F77/3600 -> 0.013888889 | H77: =H76+G77 -> 0.019444444 | I77: =H77/24 -> 0.00081018519
A78: 3 | B78: 210 | C78: 3 | D78: 14 | E78: =B78/D78 -> 15 | F78: =E78*$K$2 -> 300 | G78: =F78/3600 -> 0.083333333 | H78: =H77+G78 -> 0.10277778 | I78: =H78/24 -> 0.0042824074
A79: 4 | B79: 670 | C79: 4 | D79: 16 | E79: =B79/D79 -> 41.875 | F79: =E79*$K$2 -> 837.5 | G79: =F79/3600 -> 0.23263889 | H79: =H78+G79 -> 0.33541667 | I79: =H79/24 -> 0.013975694
A80: 5 | B80: 1530 | C80: 5 | D80: 18 | E80: =B80/D80 -> 85 | F80: =E80*$K$2 -> 1700 | G80: =F80/3600 -> 0.47222222 | H80: =H79+G80 -> 0.80763889 | I80: =H80/24 -> 0.03365162
A81: 6 | B81: 2910 | C81: 6 | D81: 20 | E81: =B81/D81 -> 145.5 | F81: =E81*$K$2 -> 2910 | G81: =F81/3600 -> 0.80833333 | H81: =H80+G81 -> 1.6159722 | I81: =H81/24 -> 0.067332176
A82: 7 | B82: 4930 | C82: 7 | D82: 22 | E82: =B82/D82 -> 224.09091 | F82: =E82*$K$2 -> 4481.8182 | G82: =F82/3600 -> 1.2449495 | H82: =H81+G82 -> 2.8609217 | I82: =H82/24 -> 0.11920507
A83: 8 | B83: 7710 | C83: 8 | D83: 24 | E83: =B83/D83 -> 321.25 | F83: =E83*$K$2 -> 6425 | G83: =F83/3600 -> 1.7847222 | H83: =H82+G83 -> 4.6456439 | I83: =H83/24 -> 0.1935685
A84: 9 | B84: 11370 | C84: 9 | D84: 28 | E84: =B84/D84 -> 406.07143 | F84: =E84*$K$2 -> 8121.4286 | G84: =F84/3600 -> 2.2559524 | H84: =H83+G84 -> 6.9015963 | I84: =H84/24 -> 0.28756651
A85: 10 | B85: 16030 | C85: 10 | D85: 32 | E85: =B85/D85 -> 500.9375 | F85: =E85*$K$2 -> 10018.75 | G85: =F85/3600 -> 2.7829861 | H85: =H84+G85 -> 9.6845824 | I85: =H85/24 -> 0.40352427
A86: 11 | B86: 21810 | C86: 11 | D86: 36 | E86: =B86/D85 -> 681.5625 | F86: =E86*$K$2 -> 13631.25 | G86: =F86/3600 -> 3.7864583 | H86: =H85+G86 -> 13.471041 | I86: =H86/24 -> 0.56129337
A87: 12 | B87: 28830 | C87: 12 | D87: 40 | E87: =B87/D85 -> 900.9375 | F87: =E87*$K$2 -> 18018.75 | G87: =F87/3600 -> 5.0052083 | H87: =H86+G87 -> 18.476249 | I87: =H87/24 -> 0.76984371
A88: 13 | B88: 37210 | C88: 13 | D88: 44 | E88: =B88/D85 -> 1162.8125 | F88: =E88*$K$2 -> 23256.25 | G88: =F88/3600 -> 6.4600694 | H88: =H87+G88 -> 24.936319 | I88: =H88/24 -> 1.0390133
A89: 14 | B89: 47070 | C89: 14 | D89: 48 | E89: =B89/D85 -> 1470.9375 | F89: =E89*$K$2 -> 29418.75 | G89: =F89/3600 -> 8.171875 | H89: =H88+G89 -> 33.108194 | I89: =H89/24 -> 1.3795081
A90: 15 | B90: 58530 | C90: 15 | D90: 52 | E90: =B90/D85 -> 1829.0625 | F90: =E90*$K$2 -> 36581.25 | G90: =F90/3600 -> 10.161458 | H90: =H89+G90 -> 43.269652 | I90: =H90/24 -> 1.8029022
A91: 16 | B91: 71710 | C91: 16 | D91: 56 | E91: =B91/D86 -> 1991.9444 | F91: =E91*$K$2 -> 39838.889 | G91: =F91/3600 -> 11.066358 | H91: =H90+G91 -> 54.33601 | I91: =H91/24 -> 2.2640004
A92: 17 | B92: 86730 | C92: 17 | D92: 60 | E92: =B92/D87 -> 2168.25 | F92: =E92*$K$2 -> 43365 | G92: =F92/3600 -> 12.045833 | H92: =H91+G92 -> 66.381843 | I92: =H92/24 -> 2.7659101
A93: 18 | B93: 103710 | C93: 18 | D93: 64 | E93: =B93/D88 -> 2357.0455 | F93: =E93*$K$2 -> 47140.909 | G93: =F93/3600 -> 13.094697 | H93: =H92+G93 -> 79.47654 | I93: =H93/24 -> 3.3115225
A94: 19 | B94: 122770 | C94: 19 | D94: 68 | E94: =B94/D89 -> 2557.7083 | F94: =E94*$K$2 -> 51154.167 | G94: =F94/3600 -> 14.209491 | H94: =H93+G94 -> 93.686031 | I94: =H94/24 -> 3.9035846
A95: 20 | B95: 144030 | C95: 20 | D95: 72 | E95: =B95/D90 -> 2769.8077 | F95: =E95*$K$2 -> 55396.154 | G95: =F95/3600 -> 15.387821 | H95: =H94+G95 -> 109.07385 | I95: =H95/24 -> 4.5447438
A96: 21 | B96: 167610 | C96: 21 | D96: 78 | E96: =B96/D91 -> 2993.0357 | F96: =E96*$K$2 -> 59860.714 | G96: =F96/3600 -> 16.627976 | H96: =H95+G96 -> 125.70183 | I96: =H96/24 -> 5.2375762
A97: 22 | B97: 193630 | C97: 22 | D97: 84 | E97: =B97/D92 -> 3227.1667 | F97: =E97*$K$2 -> 64543.333 | G97: =F97/3600 -> 17.928704 | H97: =H96+G97 -> 143.63053 | I97: =H97/24 -> 5.9846055
A98: 23 | B98: 222210 | C98: 23 | D98: 90 | E98: =B98/D93 -> 3472.0312 | F98: =E98*$K$2 -> 69440.625 | G98: =F98/3600 -> 19.289062 | H98: =H97+G98 -> 162.91959 | I98: =H98/24 -> 6.7883164
...

Sheet 等级属性
A2: 力 | B2: 168 | D2: 35 | E2: 35
A3: 敏 | B3: 89 | D3: 90 | E3: 35
A4: 智 | B4: 73 | D4: 35 | E4: 90 | G4: 人物属性成长
A5: 耐 | B5: 112 | D5: 62 | E5: 62 | G5: 耐力 | H5: 主属性 | I5: 其他
G6: 2 | H6: 3 | I6: 1

Sheet 强化规则
A1: 强化等级系数 | D1: 品质系数 | G1: 装备等级系数 | J1: 金币消耗系数 | K1: 2000 | P1: 部位系数
A2: 1 | B2: 1 | D2: 白 | E2: 1 | G2: LV1 | H2: 1 | P2: 武器 | Q2: 2
A3: 2 | B3: 1.5 | D3: 绿 | E3: 2 | G3: LV5 | H3: 1.5 | P3: 副手 | Q3: 1.25
A4: 3 | B4: 2.25 | D4: 蓝 | E4: 3 | G4: LV10 | H4: 2.25 | P4: 头 | Q4: 1
A5: 4 | B5: 2.75 | D5: 紫 | E5: 4 | G5: LV15 | H5: 2.75 | P5: 胸 | Q5: 1
A6: 5 | B6: 3.5 | D6: 橙 | E6: 5 | G6: LV20 | H6: 3.25 | P6: 腿 | Q6: 1
A7: 6 | B7: 6.25 | G7: LV25 | H7: 3.75 | P7: 腰带 | Q7: 1.25
A8: 7 | B8: 7.25 | G8: LV30 | H8: 4.25 | P8: 项链 | Q8: 1
A9: 8 | B9: 8.25 | G9: LV35 | H9: 4.75 | P9: 戒指 | Q9: 1.25
A10: 9 | B10: 9.25 | G10: LV40 | H10: 5.25 | P10: 鞋 | Q10: 1
A11: 10 | B11: 10.25 | G11: LV45 | H11: 5.75 | P11: 手 | Q11: 1
A12: 11 | B12: 18 | G12: LV50 | H12: 6.25
A13: 12 | B13: 20 | G13: LV55 | H13: 6.75
A14: 13 | B14: 22 | G14: LV60 | H14: 7.25
A15: 14 | B15: 24 | G15: LV65 | H15: 7.75
A16: 15 | B16: 26 | G16: LV70 | H16: 8.25
A17: 16 | B17: 50 | G17: 极品加成 | H17: 1.5
A18: 17 | B18: 54
A19: 18 | B19: 58
A20: 19 | B20: 62
A21: 20 | B21: 66
A23: 基础消耗
A24: 等级 | B24: 白 | C24: 绿 | D24: 蓝 | E24: 紫 | F24: 橙
A25: LV1 | B25: =ROUNDDOWN(VLOOKUP(B$24,$D$2:$E$6,2,FALSE)*VLOOKUP($A25,$G$2:$H$16,2,FALSE),0) -> 1 | C25: =ROUNDDOWN(VLOOKUP(C$24,$D$2:$E$6,2,FALSE)*VLOOKUP($A25,$G$2:$H$16,2,FALSE),0) -> 2 | D25: =ROUNDDOWN(VLOOKUP(D$24,$D$2:$E$6,2,FALSE)*VLOOKUP($A25,$G$2:$H$16,2,FALSE),0) -> 3 | E25: =ROUNDDOWN(VLOOKUP(E$24,$D$2:$E$6,2,FALSE)*VLOOKUP($A25,$G$2:$H$16,2,FALSE),0) -> 4 | F25: =ROUNDDOWN(VLOOKUP(F$24,$D$2:$E$6,2,FALSE)*VLOOKUP($A25,$G$2:$H$16,2,FALSE),0) -> 5 | J25: 8 | K25: =B2*$J$25 -> 8 | L25: 27
A26: LV5 | B26: =ROUNDDOWN(VLOOKUP(B$24,$D$2:$E$6,2,FALSE)*VLOOKUP($A26,$G$2:$H$16,2,FALSE),0) -> 1 | C26: =ROUNDDOWN(VLOOKUP(C$24,$D$2:$E$6,2,FALSE)*VLOOKUP($A26,$G$2:$H$16,2,FALSE),0) -> 3 | D26: =ROUNDDOWN(VLOOKUP(D$24,$D$2:$E$6,2,FALSE)*VLOOKUP($A26,$G$2:$H$16,2,FALSE),0) -> 4 | E26: =ROUNDDOWN(VLOOKUP(E$24,$D$2:$E$6,2,FALSE)*VLOOKUP($A26,$G$2:$H$16,2,FALSE),0) -> 6 | F26: =ROUNDDOWN(VLOOKUP(F$24,$D$2:$E$6,2,FALSE)*VLOOKUP($A26,$G$2:$H$16,2,FALSE),0) -> 7 | K26: =B3*$J$25 -> 12 | L26: 41
A27: LV10 | B27: =ROUNDDOWN(VLOOKUP(B$24,$D$2:$E$6,2,FALSE)*VLOOKUP($A27,$G$2:$H$16,2,FALSE),0) -> 2 | C27: =ROUNDDOWN(VLOOKUP(C$24,$D$2:$E$6,2,FALSE)*VLOOKUP($A27,$G$2:$H$16,2,FALSE),0) -> 4 | D27: =ROUNDDOWN(VLOOKUP(D$24,$D$2:$E$6,2,FALSE)*VLOOKUP($A27,$G$2:$H$16,2,FALSE),0) -> 6 | E27: =ROUNDDOWN(VLOOKUP(E$24,$D$2:$E$6,2,FALSE)*VLOOKUP($A27,$G$2:$H$16,2,FALSE),0) -> 9 | F27: =ROUNDDOWN(VLOOKUP(F$24,$D$2:$E$6,2,FALSE)*VLOOKUP($A27,$G$2:$H$16,2,FALSE),0) -> 11 | K27: =B4*$J$25 -> 18 | L27: 56
A28: LV15 | B28: =ROUNDDOWN(VLOOKUP(B$24,$D$2:$E$6,2,FALSE)*VLOOKUP($A28,$G$2:$H$16,2,FALSE),0) -> 2 | C28: =ROUNDDOWN(VLOOKUP(C$24,$D$2:$E$6,2,FALSE)*VLOOKUP($A28,$G$2:$H$16,2,FALSE),0) -> 5 | D28: =ROUNDDOWN(VLOOKUP(D$24,$D$2:$E$6,2,FALSE)*VLOOKUP($A28,$G$2:$H$16,2,FALSE),0) -> 8 | E28: =ROUNDDOWN(VLOOKUP(E$24,$D$2:$E$6,2,FALSE)*VLOOKUP($A28,$G$2:$H$16,2,FALSE),0) -> 11 | F28: =ROUNDDOWN(VLOOKUP(F$24,$D$2:$E$6,2,FALSE)*VLOOKUP($A28,$G$2:$H$16,2,FALSE),0) -> 13 | K28: =B5*$J$25 -> 22 | L28: 72
A29: LV20 | B29: =ROUNDDOWN(VLOOKUP(B$24,$D$2:$E$6,2,FALSE)*VLOOKUP($A29,$G$2:$H$16,2,FALSE),0) -> 3 | C29: =ROUNDDOWN(VLOOKUP(C$24,$D$2:$E$6,2,FALSE)*VLOOKUP($A29,$G$2:$H$16,2,FALSE),0) -> 6 | D29: =ROUNDDOWN(VLOOKUP(D$24,$D$2:$E$6,2,FALSE)*VLOOKUP($A29,$G$2:$H$16,2,FALSE),0) -> 9 | E29: =ROUNDDOWN(VLOOKUP(E$24,$D$2:$E$6,2,FALSE)*VLOOKUP($A29,$G$2:$H$16,2,FALSE),0) -> 13 | F29: =ROUNDDOWN(VLOOKUP(F$24,$D$2:$E$6,2,FALSE)*VLOOKUP($A29,$G$2:$H$16,2,FALSE),0) -> 16 | K29: =B6*$J$25 -> 28 | L29: 88
A30: LV25 | B30: =ROUNDDOWN(VLOOKUP(B$24,$D$2:$E$6,2,FALSE)*VLOOKUP($A30,$G$2:$H$16,2,FALSE),0) -> 3 | C30: =ROUNDDOWN(VLOOKUP(C$24,$D$2:$E$6,2,FALSE)*VLOOKUP($A30,$G$2:$H$16,2,FALSE),0) -> 7 | D30: =ROUNDDOWN(VLOOKUP(D$24,$D$2:$E$6,2,FALSE)*VLOOKUP($A30,$G$2:$H$16,2,FALSE),0) -> 11 | E30: =ROUNDDOWN(VLOOKUP(E$24,$D$2:$E$6,2,FALSE)*VLOOKUP($A30,$G$2:$H$16,2,FALSE),0) -> 15 | F30: =ROUNDDOWN(VLOOKUP(F$24,$D$2:$E$6,2,FALSE)*VLOOKUP($A30,$G$2:$H$16,2,FALSE),0) -> 18 | K30: =B7*$J$25 -> 50
A31: LV30 | B31: =ROUNDDOWN(VLOOKUP(B$24,$D$2:$E$6,2,FALSE)*VLOOKUP($A31,$G$2:$H$16,2,FALSE),0) -> 4 | C31: =ROUNDDOWN(VLOOKUP(C$24,$D$2:$E$6,2,FALSE)*VLOOKUP($A31,$G$2:$H$16,2,FALSE),0) -> 8 | D31: =ROUNDDOWN(VLOOKUP(D$24,$D$2:$E$6,2,FALSE)*VLOOKUP($A31,$G$2:$H$16,2,FALSE),0) -> 12 | E31: =ROUNDDOWN(VLOOKUP(E$24,$D$2:$E$6,2,FALSE)*VLOOKUP($A31,$G$2:$H$16,2,FALSE),0) -> 17 | F31: =ROUNDDOWN(VLOOKUP(F$24,$D$2:$E$6,2,FALSE)*VLOOKUP($A31,$G$2:$H$16,2,FALSE),0) -> 21 | K31: =B8*$J$25 -> 58
A32: LV35 | B32: =ROUNDDOWN(VLOOKUP(B$24,$D$2:$E$6,2,FALSE)*VLOOKUP($A32,$G$2:$H$16,2,FALSE),0) -> 4 | C32: =ROUNDDOWN(VLOOKUP(C$24,$D$2:$E$6,2,FALSE)*VLOOKUP($A32,$G$2:$H$16,2,FALSE),0) -> 9 | D32: =ROUNDDOWN(VLOOKUP(D$24,$D$2:$E$6,2,FALSE)*VLOOKUP($A32,$G$2:$H$16,2,FALSE),0) -> 14 | E32: =ROUNDDOWN(VLOOKUP(E$24,$D$2:$E$6,2,FALSE)*VLOOKUP($A32,$G$2:$H$16,2,FALSE),0) -> 19 | F32: =ROUNDDOWN(VLOOKUP(F$24,$D$2:$E$6,2,FALSE)*VLOOKUP($A32,$G$2:$H$16,2,FALSE),0) -> 23 | K32: =B9*$J$25 -> 66
A33: LV40 | B33: =ROUNDDOWN(VLOOKUP(B$24,$D$2:$E$6,2,FALSE)*VLOOKUP($A33,$G$2:$H$16,2,FALSE),0) -> 5 | C33: =ROUNDDOWN(VLOOKUP(C$24,$D$2:$E$6,2,FALSE)*VLOOKUP($A33,$G$2:$H$16,2,FALSE),0) -> 10 | D33: =ROUNDDOWN(VLOOKUP(D$24,$D$2:$E$6,2,FALSE)*VLOOKUP($A33,$G$2:$H$16,2,FALSE),0) -> 15 | E33: =ROUNDDOWN(VLOOKUP(E$24,$D$2:$E$6,2,FALSE)*VLOOKUP($A33,$G$2:$H$16,2,FALSE),0) -> 21 | F33: =ROUNDDOWN(VLOOKUP(F$24,$D$2:$E$6,2,FALSE)*VLOOKUP($A33,$G$2:$H$16,2,FALSE),0) -> 26 | K33: =B10*$J$25 -> 74
A34: LV45 | B34: =ROUNDDOWN(VLOOKUP(B$24,$D$2:$E$6,2,FALSE)*VLOOKUP($A34,$G$2:$H$16,2,FALSE),0) -> 5 | C34: =ROUNDDOWN(VLOOKUP(C$24,$D$2:$E$6,2,FALSE)*VLOOKUP($A34,$G$2:$H$16,2,FALSE),0) -> 11 | D34: =ROUNDDOWN(VLOOKUP(D$24,$D$2:$E$6,2,FALSE)*VLOOKUP($A34,$G$2:$H$16,2,FALSE),0) -> 17 | E34: =ROUNDDOWN(VLOOKUP(E$24,$D$2:$E$6,2,FALSE)*VLOOKUP($A34,$G$2:$H$16,2,FALSE),0) -> 23 | F34: =ROUNDDOWN(VLOOKUP(F$24,$D$2:$E$6,2,FALSE)*VLOOKUP($A34,$G$2:$H$16,2,FALSE),0) -> 28 | K34: =B11*$J$25 -> 82
A35: LV50 | B35: =ROUNDDOWN(VLOOKUP(B$24,$D$2:$E$6,2,FALSE)*VLOOKUP($A35,$G$2:$H$16,2,FALSE),0) -> 6 | C35: =ROUNDDOWN(VLOOKUP(C$24,$D$2:$E$6,2,FALSE)*VLOOKUP($A35,$G$2:$H$16,2,FALSE),0) -> 12 | D35: =ROUNDDOWN(VLOOKUP(D$24,$D$2:$E$6,2,FALSE)*VLOOKUP($A35,$G$2:$H$16,2,FALSE),0) -> 18 | E35: =ROUNDDOWN(VLOOKUP(E$24,$D$2:$E$6,2,FALSE)*VLOOKUP($A35,$G$2:$H$16,2,FALSE),0) -> 25 | F35: =ROUNDDOWN(VLOOKUP(F$24,$D$2:$E$6,2,FALSE)*VLOOKUP($A35,$G$2:$H$16,2,FALSE),0) -> 31 | K35: =B12*$J$25 -> 144
A36: LV55 | B36: =ROUNDDOWN(VLOOKUP(B$24,$D$2:$E$6,2,FALSE)*VLOOKUP($A36,$G$2:$H$16,2,FALSE),0) -> 6 | C36: =ROUNDDOWN(VLOOKUP(C$24,$D$2:$E$6,2,FALSE)*VLOOKUP($A36,$G$2:$H$16,2,FALSE),0) -> 13 | D36: =ROUNDDOWN(VLOOKUP(D$24,$D$2:$E$6,2,FALSE)*VLOOKUP($A36,$G$2:$H$16,2,FALSE),0) -> 20 | E36: =ROUNDDOWN(VLOOKUP(E$24,$D$2:$E$6,2,FALSE)*VLOOKUP($A36,$G$2:$H$16,2,FALSE),0) -> 27 | F36: =ROUNDDOWN(VLOOKUP(F$24,$D$2:$E$6,2,FALSE)*VLOOKUP($A36,$G$2:$H$16,2,FALSE),0) -> 33 | K36: =B13*$J$25 -> 160
A37: LV60 | B37: =ROUNDDOWN(VLOOKUP(B$24,$D$2:$E$6,2,FALSE)*VLOOKUP($A37,$G$2:$H$16,2,FALSE),0) -> 7 | C37: =ROUNDDOWN(VLOOKUP(C$24,$D$2:$E$6,2,FALSE)*VLOOKUP($A37,$G$2:$H$16,2,FALSE),0) -> 14 | D37: =ROUNDDOWN(VLOOKUP(D$24,$D$2:$E$6,2,FALSE)*VLOOKUP($A37,$G$2:$H$16,2,FALSE),0) -> 21 | E37: =ROUNDDOWN(VLOOKUP(E$24,$D$2:$E$6,2,FALSE)*VLOOKUP($A37,$G$2:$H$16,2,FALSE),0) -> 29 | F37: =ROUNDDOWN(VLOOKUP(F$24,$D$2:$E$6,2,FALSE)*VLOOKUP($A37,$G$2:$H$16,2,FALSE),0) -> 36 | K37: =B14*$J$25 -> 176
A38: LV65 | B38: =ROUNDDOWN(VLOOKUP(B$24,$D$2:$E$6,2,FALSE)*VLOOKUP($A38,$G$2:$H$16,2,FALSE),0) -> 7 | C38: =ROUNDDOWN(VLOOKUP(C$24,$D$2:$E$6,2,FALSE)*VLOOKUP($A38,$G$2:$H$16,2,FALSE),0) -> 15 | D38: =ROUNDDOWN(VLOOKUP(D$24,$D$2:$E$6,2,FALSE)*VLOOKUP($A38,$G$2:$H$16,2,FALSE),0) -> 23 | E38: =ROUNDDOWN(VLOOKUP(E$24,$D$2:$E$6,2,FALSE)*VLOOKUP($A38,$G$2:$H$16,2,FALSE),0) -> 31 | F38: =ROUNDDOWN(VLOOKUP(F$24,$D$2:$E$6,2,FALSE)*VLOOKUP($A38,$G$2:$H$16,2,FALSE),0) -> 38 | K38: =B15*$J$25 -> 192
A39: LV70 | B39: =ROUNDDOWN(VLOOKUP(B$24,$D$2:$E$6,2,FALSE)*VLOOKUP($A39,$G$2:$H$16,2,FALSE),0) -> 8 | C39: =ROUNDDOWN(VLOOKUP(C$24,$D$2:$E$6,2,FALSE)*VLOOKUP($A39,$G$2:$H$16,2,FALSE),0) -> 16 | D39: =ROUNDDOWN(VLOOKUP(D$24,$D$2:$E$6,2,FALSE)*VLOOKUP($A39,$G$2:$H$16,2,FALSE),0) -> 24 | E39: =ROUNDDOWN(VLOOKUP(E$24,$D$2:$E$6,2,FALSE)*VLOOKUP($A39,$G$2:$H$16,2,FALSE),0) -> 33 | F39: =ROUNDDOWN(VLOOKUP(F$24,$D$2:$E$6,2,FALSE)*VLOOKUP($A39,$G$2:$H$16,2,FALSE),0) -> 41

Sheet 战斗力成长
A1: 战士
A2: 等级 | B2: 装备属性 | C2: 人物属性 | D2: 总属性 | E2: 属性暴击 | F2: 总暴击 | G2: 暴击率 | H2: 武器伤害 | I2: 属性攻击力 | J2: 技能倍数 | K2: 总输出 | L2: 耐力值 | M2: 腰带加血 | N2: 生命总值 | O2: 腰带占生命比 | P2: 护甲增值 | Q2: 总护甲 | R2: 护甲减伤 | S2: 物抗 | T2: 魔抗 | U2: 物抗减伤 | V2: 魔抗减伤 | W2: 闪避 | X2: 闪避减伤 | Y2: 有效生命 | Z2: 战斗回合数 | AA2: 强化系数 | AB2: 护甲强化系数 | AC2: 韧性 | AD2: 韧性减免 | AE2: 神器星级 | AF2: 神器生命 | AG2: 神器吸血 | AH2: 神器护甲 | AI2: 神器物抗 | AJ2: 神器闪避 | AK2: 神器伤害 | AL2: 神器暴击 | AM2: 神器暴伤 | AN2: 护甲穿透 | AO2: 抗性穿透 | AP2: BOSS护甲 | AQ2: BOSS抗性 | AR2: 吸血EHP/回合 | AS2: 回血EHP/回合 | AT2: 佣兵EHP | AU2: 佣兵DPS | AV2: 佣兵辅助加成 | AW2: 佣兵光环DPS | AX2: 佣兵光环EHP | AY2: 合计DPS | AZ2: 合计EHP | BB2: 参考回合数
A3: 1 | B3: 56 | C3: 47 | D3: =C3+B3 -> 103 | E3: =装备属性设计!AB3*AA3 -> 9 | F3: =(E3+$C$27*D3+D26)*(1+AL3/100) -> 19.3 | G3: =F3/(A3*A3*3+3*A3+50+F3) -> 0.2563081 | H3: =装备属性设计!Q3*AA3 -> 8 | I3: =D3*1.5*MAX($C$26:$C$29) -> 92.7 | J3: 1 | K3: =(I3+H3)/2*(1+AK3/100)*J3 -> 50.35 | L3: =$C$29*D3 -> 20.6 | M3: =装备属性设计!D3*AA3 -> 100 | N3: =ROUND((L3*10+M3)*(100+AF3)/100,0) -> 306 | O3: =M3/N3 -> 0.32679739 | P3: =(装备属性设计!I3+装备属性设计!F3) -> 6 | Q3: =(P3+E26)*AB3*(1+AH3/100) -> 10 | R3: =Q3/(A3*A3*3+A3*3+50+Q3) -> 0.15151515 | S3: =装备属性设计!X3*AB3*(1+AI3/100) -> 0 | T3: =装备属性设计!V3*AB3 -> 0 | U3: =(S3+D3*$C$26*(1+AI3/100))/($A3*50+S3+D3*$C$26*(1+AI3/100)+50) -> 0.38195303 | V3: =(T3+B3*$C$28)/($A3*50+T3+B3*$C$28+50) -> 0.053030303 | W3: =(装备属性设计!Z3*战斗力成长!AB3+D3*C$27*0.2)*(1+AJ3/100) -> 5.06 | X3: =W3/((3*$A3*$A3+3*$A3+50)/4+W3) -> 0.26547744 | Y3: =(N3/(1-R3))/(1-U3)/(1-X3) -> 794.42099 | Z3: =Y3/K3 -> 15.777974 | AA3: 1 | AB3: =(AA3-1)/1.5+1 -> 1 | AC3: =B3*C$29 -> 11.2 | AD3: =AC3/((A3*A3*3+A3*3+50)*2+AC3) -> 0.090909091 | AE3: 0 | AF3: =AE3*5 -> 0 | AG3: =AE3*2 -> 0 | AH3: =AE3*8/2 -> 0 | AI3: =AE3*7/2 -> 0 | AJ3: =AE3*8/3 -> 0 | AK3: =AE3*4 -> 0 | AL3: =AE3*8 -> 0 | AM3: =AE3*7 -> 0 | AN3: =AE3*8/(AE3*8+100) -> 0 | AO3: =AE4*8/(AE4*8+100) -> 0 | AP3: 0 | AQ3: 0 | AR3: =AG3*K3/100/(1-X3)/(1-U3)/(1-R3) -> 0 | AS3: =Y3*AE3/1000*2 -> 0 | AT3: 1 | AU3: 0 | AV3: 1 | AW3: 1 | AX3: 1 | AY3: =(MIN(AT3/(Y3+(AR3+AS3)/2*BB3),1)*AU3+K3)*AW3 -> 50.35 | AZ3: =(Y3+AT3)*AX3*AV3 -> 795.42099 | BA3: =AY3*AZ3^(1/3) -> 466.51451 | BB3: 10
A4: 5 | B4: 140 | C4: 75 | D4: =C4+B4 -> 215 | E4: =装备属性设计!AB4*AA4 -> 24.15 | F4: =(E4+$C$27*D4+D27)*(1+AL4/100) -> 45.65 | G4: =F4/(A4*A4*3+3*A4+50+F4) -> 0.24589281 | H4: =装备属性设计!Q4*AA4 -> 31.5 | I4: =D4*1.5*MAX($C$26:$C$29) -> 193.5 | J4: 1.25 | K4: =(I4+H4)/2*(1+AK4/100)*J4 -> 140.625 | L4: =$C$29*D4 -> 43 | M4: =装备属性设计!D4*AA4 -> 252 | N4: =ROUND((L4*10+M4)*(100+AF4)/100,0) -> 682 | O4: =M4/N4 -> 0.36950147 | P4: =(装备属性设计!I4+装备属性设计!F4) -> 18 | Q4: =(P4+E27)*AB4*(1+AH4/100) -> 31 | R4: =Q4/(A4*A4*3+A4*3+50+Q4) -> 0.18128655 | S4: =装备属性设计!X4*AB4*(1+AI4/100) -> 20.666667 | T4: =装备属性设计!V4*AB4 -> 20.666667 | U4: =(S4+D4*$C$26*(1+AI4/100))/($A4*50+S4+D4*$C$26*(1+AI4/100)+50) -> 0.33283914 | V4: =(T4+B4*$C$28)/($A4*50+T4+B4*$C$28+50) -> 0.10358566 | W4: =(装备属性设计!Z4*战斗力成长!AB4+D4*C$27*0.2)*(1+AJ4/100) -> 7.4 | X4: =W4/((3*$A4*$A4+3*$A4+50)/4+W4) -> 0.1745283 | Y4: =(N4/(1-R4))/(1-U4)/(1-X4) -> 1512.5847 | Z4: =Y4/K4 -> 10.756158 | AA4: 1.05 | AB4: =(AA4-1)/1.5+1 -> 1.0333333 | AC4: =B4*C$29 -> 28 | AD4: =AC4/((A4*A4*3+A4*3+50)*2+AC4) -> 0.090909091 | AE4: 0 | AF4: =AE4*5 -> 0 | AG4: =AE4*2 -> 0 | AH4: =AE4*8/2 -> 0 | AI4: =AE4*7/2 -> 0 | AJ4: =AE4*8/3 -> 0 | AK4: =AE4*4 -> 0 | AL4: =AE4*8 -> 0 | AM4: =AE4*7 -> 0 | AN4: =AE4*8/(AE4*8+100) -> 0 | AO4: =AE4*8/(AE4*8+100) -> 0 | AP4: 0 | AQ4: 0 | AR4: =AG4*K4/100/(1-X4)/(1-U4)/(1-R4) -> 0 | AS4: =Y4*AE4/1000*2 -> 0 | AT4: 1 | AU4: 0 | AV4: 1 | AW4: 1 | AX4: 1 | AY4: =(MIN(AT4/(Y4+(AR4+AS4)/2*BB4),1)*AU4+K4)*AW4 -> 140.625 | AZ4: =(Y4+AT4)*AX4*AV4 -> 1513.5847 | BA4: =AY4*AZ4^(1/3) -> 1614.5994 | BB4: 12
A5: 10 | B5: 380 | C5: 110 | D5: =C5+B5 -> 490 | E5: =装备属性设计!AB5*AA5 -> 47.3 | F5: =(E5+$C$27*D5+D28)*(1+AL5/100) -> 104.004 | G5: =F5/(A5*A5*3+3*A5+50+F5) -> 0.21488252 | H5: =装备属性设计!Q5*AA5 -> 105.6 | I5: =D5*1.5*MAX($C$26:$C$29) -> 441 | J5: 1.3 | K5: =(I5+H5)/2*(1+AK5/100)*J5 -> 369.5016 | L5: =$C$29*D5 -> 98 | M5: =装备属性设计!D5*AA5 -> 528 | N5: =ROUND((L5*10+M5)*(100+AF5)/100,0) -> 1583 | O5: =M5/N5 -> 0.3335439 | P5: =(装备属性设计!I5+装备属性设计!F5) -> 40 | Q5: =(P5+E28)*AB5*(1+AH5/100) -> 77.653333 | R5: =Q5/(A5*A5*3+A5*3+50+Q5) -> 0.16967719 | S5: =装备属性设计!X5*AB5*(1+AI5/100) -> 70.656 | T5: =装备属性设计!V5*AB5 -> 21.333333 | U5: =(S5+D5*$C$26*(1+AI5/100))/($A5*50+S5+D5*$C$26*(1+AI5/100)+50) -> 0.40537069 | V5: =(T5+B5*$C$28)/($A5*50+T5+B5*$C$28+50) -> 0.097374179 | W5: =(装备属性设计!Z5*战斗力成长!AB5+D5*C$27*0.2)*(1+AJ5/100) -> 23.202667 | X5: =W5/((3*$A5*$A5+3*$A5+50)/4+W5) -> 0.19629563 | Y5: =(N5/(1-R5))/(1-U5)/(1-X5) -> 3989.2505 | Z5: =Y5/K5 -> 10.796301 | AA5: 1.1 | AB5: =(AA5-1)/1.5+1 -> 1.0666667 | AC5: =B5*C$29 -> 76 | AD5: =AC5/((A5*A5*3+A5*3+50)*2+AC5) -> 0.090909091 | AE5: 1 | AF5: =AE5*5 -> 5 | AG5: =AE5*2 -> 2 | AH5: =AE5*8/2 -> 4 | AI5: =AE5*7/2 -> 3.5 | AJ5: =AE5*8/3 -> 2.6666667 | AK5: =AE5*4 -> 4 | AL5: =AE5*8 -> 8 | AM5: =AE5*7 -> 7 | AN5: =AE5*8/(AE5*8+100) -> 0.074074074 | AO5: =AE5*8/(AE5*8+100) -> 0.074074074 | AP5: 0 | AQ5: 0 | AR5: =AG5*K5/100/(1-X5)/(1-U5)/(1-R5) -> 18.623303 | AS5: =Y5*AE5/1000*2 -> 7.978501 | AT5: 1 | AU5: 0 | AV5: 1 | AW5: 1 | AX5: 1 | AY5: =(MIN(AT5/(Y5+(AR5+AS5)/2*BB5),1)*AU5+K5)*AW5 -> 369.5016 | AZ5: =(Y5+AT5)*AX5*AV5 -> 3990.2505 | BA5: =AY5*AZ5^(1/3) -> 5860.7029 | BB5: 14
A6: 15 | B6: 770 | C6: 145 | D6: =C6+B6 -> 915 | E6: =装备属性设计!AB6*AA6 -> 127.2 | F6: =(E6+$C$27*D6+D29)*(1+AL6/100) -> 236.196 | G6: =F6/(A6*A6*3+3*A6+50+F6) -> 0.23474154 | H6: =装备属性设计!Q6*AA6 -> 187.2 | I6: =D6*1.5*MAX($C$26:$C$29) -> 823.5 | J6: 1.35 | K6: =(I6+H6)/2*(1+AK6/100)*J6 -> 709.5114 | L6: =$C$29*D6 -> 183 | M6: =装备属性设计!D6*AA6 -> 1392 | N6: =ROUND((L6*10+M6)*(100+AF6)/100,0) -> 3383 | O6: =M6/N6 -> 0.41146911 | P6: =(装备属性设计!I6+装备属性设计!F6) -> 78 | Q6: =(P6+E29)*AB6*(1+AH6/100) -> 213.33867 | R6: =Q6/(A6*A6*3+A6*3+50+Q6) -> 0.2169534 | S6: =装备属性设计!X6*AB6*(1+AI6/100) -> 75.072 | T6: =装备属性设计!V6*AB6 -> 72.533333 | U6: =(S6+D6*$C$26*(1+AI6/100))/($A6*50+S6+D6*$C$26*(1+AI6/100)+50) -> 0.44570969 | V6: =(T6+B6*$C$28)/($A6*50+T6+B6*$C$28+50) -> 0.15748087 | W6: =(装备属性设计!Z6*战斗力成长!AB6+D6*C$27*0.2)*(1+AJ6/100) -> 46.713333 | X6: =W6/((3*$A6*$A6+3*$A6+50)/4+W6) -> 0.19527897 | Y6: =(N6/(1-R6))/(1-U6)/(1-X6) -> 9685.7165 | Z6: =Y6/K6 -> 13.651249 | AA6: 1.2 | AB6: =(AA6-1)/1.5+1 -> 1.1333333 | AC6: =B6*C$29 -> 154 | AD6: =AC6/((A6*A6*3+A6*3+50)*2+AC6) -> 0.090909091 | AE6: 1 | AF6: =AE6*5 -> 5 | AG6: =AE6*2 -> 2 | AH6: =AE6*8/2 -> 4 | AI6: =AE6*7/2 -> 3.5 | AJ6: =AE6*8/3 -> 2.6666667 | AK6: =AE6*4 -> 4 | AL6: =AE6*8 -> 8 | AM6: =AE6*7 -> 7 | AN6: =AE6*8/(AE6*8+100) -> 0.074074074 | AO6: =AE6*8/(AE6*8+100) -> 0.074074074 | AP6: 0 | AQ6: 0 | AR6: =AG6*K6/100/(1-X6)/(1-U6)/(1-R6) -> 40.627409 | AS6: =Y6*AE6/1000*2 -> 19.371433 | AT6: =佣兵培养!AB2 -> 3644.0643 | AU6: =佣兵培养!AE2 -> 329.05 | AV6: 1.1 | AW6: 1 | AX6: 1 | AY6: =(MIN(AT6/(Y6+(AR6+AS6)/2*BB6),1)*AU6+K6)*AW6 -> 827.46476 | AZ6: =(Y6+AT6)*AX6*AV6 -> 14662.759 | BA6: =AY6*AZ6^(1/3) -> 20252.94 | BB6: 16
A7: 20 | B7: 1310 | C7: 180 | D7: =C7+B7 -> 1490 | E7: =装备属性设计!AB7*AA7 -> 253.2 | F7: =(E7+$C$27*D7+D30)*(1+AL7/100) -> 466.552 | G7: =F7/(A7*A7*3+3*A7+50+F7) -> 0.26261657 | H7: =装备属性设计!Q7*AA7 -> 405.6 | I7: =D7*1.5*MAX($C$26:$C$29) -> 1341 | J7: 1.4 | K7: =(I7+H7)/2*(1+AK7/100)*J7 -> 1320.4296 | L7: =$C$29*D7 -> 298 | M7: =装备属性设计!D7*AA7 -> 2544 | N7: =ROUND((L7*10+M7)*(100+AF7)/100,0) -> 6076 | O7: =M7/N7 -> 0.41869651 | P7: =(装备属性设计!I7+装备属性设计!F7) -> 204 | Q7: =(P7+E30)*AB7*(1+AH7/100) -> 459 | R7: =Q7/(A7*A7*3+A7*3+50+Q7) -> 0.25946863 | S7: =装备属性设计!X7*AB7*(1+AI7/100) -> 164.92267 | T7: =装备属性设计!V7*AB7 -> 154.13333 | U7: =(S7+D7*$C$26*(1+AI7/100))/($A7*50+S7+D7*$C$26*(1+AI7/100)+50) -> 0.51646387 | V7: =(T7+B7*$C$28)/($A7*50+T7+B7*$C$28+50) -> 0.21356169 | W7: =(装备属性设计!Z7*战斗力成长!AB7+D7*C$27*0.2)*(1+AJ7/100) -> 79.140444 | X7: =W7/((3*$A7*$A7+3*$A7+50)/4+W7) -> 0.1946202 | Y7: =(N7/(1-R7))/(1-U7)/(1-X7) -> 21069.035 | Z7: =Y7/K7 -> 15.956197 | AA7: 1.2 | AB7: =(AA7-1)/1.5+1 -> 1.1333333 | AC7: =B7*C$29 -> 262 | AD7: =AC7/((A7*A7*3+A7*3+50)*2+AC7) -> 0.090909091 | AE7: 2 | AF7: =AE7*5 -> 10 | AG7: =AE7*2 -> 4 | AH7: =AE7*8/2 -> 8 | AI7: =AE7*7/2 -> 7 | AJ7: =AE7*8/3 -> 5.3333333 | AK7: =AE7*4 -> 8 | AL7: =AE7*8 -> 16 | AM7: =AE7*7 -> 14 | AN7: =AE7*8/(AE7*8+100) -> 0.13793103 | AO7: =AE7*8/(AE7*8+100) -> 0.13793103 | AP7: 0 | AQ7: 0 | AR7: =AG7*K7/100/(1-X7)/(1-U7)/(1-R7) -> 183.14797 | AS7: =Y7*AE7/1000*2 -> 84.276139 | AT7: =佣兵培养!AB3 -> 10236.558 | AU7: =佣兵培养!AE3 -> 745.4934 | AV7: 1.1 | AW7: 1.03 | AX7: 1.05 | AY7: =(MIN(AT7/(Y7+(AR7+AS7)/2*BB7),1)*AU7+K7)*AW7 -> 1694.8642 | AZ7: =(Y7+AT7)*AX7*AV7 -> 36157.959 | BA7: =AY7*AZ7^(1/3) -> 56044.914 | BB7: 18
A8: 25 | B8: 2000 | C8: 215 | D8: =C8+B8 -> 2215 | E8: =装备属性设计!AB8*AA8 -> 371.8 | F8: =(E8+$C$27*D8+D31)*(1+AL8/100) -> 688.228 | G8: =F8/(A8*A8*3+3*A8+50+F8) -> 0.25601549 | H8: =装备属性设计!Q8*AA8 -> 690.3 | I8: =D8*1.5*MAX($C$26:$C$29) -> 1993.5 | J8: 1.45 | K8: =(I8+H8)/2*(1+AK8/100)*J8 -> 2101.4154 | L8: =$C$29*D8 -> 443 | M8: =装备属性设计!D8*AA8 -> 4368 | N8: =ROUND((L8*10+M8)*(100+AF8)/100,0) -> 9678 | O8: =M8/N8 -> 0.45133292 | P8: =(装备属性设计!I8+装备属性设计!F8) -> 306 | Q8: =(P8+E31)*AB8*(1+AH8/100) -> 728.352 | R8: =Q8/(A8*A8*3+A8*3+50+Q8) -> 0.26695676 | S8: =装备属性设计!X8*AB8*(1+AI8/100) -> 304.308 | T8: =装备属性设计!V8*AB8 -> 284.4 | U8: =(S8+D8*$C$26*(1+AI8/100))/($A8*50+S8+D8*$C$26*(1+AI8/100)+50) -> 0.57043794 | V8: =(T8+B8*$C$28)/($A8*50+T8+B8*$C$28+50) -> 0.2714638 | W8: =(装备属性设计!Z8*战斗力成长!AB8+D8*C$27*0.2)*(1+AJ8/100) -> 125.03067 | X8: =W8/((3*$A8*$A8+3*$A8+50)/4+W8) -> 0.20003925 | Y8: =(N8/(1-R8))/(1-U8)/(1-X8) -> 38420.359 | Z8: =Y8/K8 -> 18.283086 | AA8: 1.3 | AB8: =(AA8-1)/1.5+1 -> 1.2 | AC8: =B8*C$29 -> 400 | AD8: =AC8/((A8*A8*3+A8*3+50)*2+AC8) -> 0.090909091 | AE8: 2 | AF8: =AE8*5 -> 10 | AG8: =AE8*2 -> 4 | AH8: =AE8*8/2 -> 8 | AI8: =AE8*7/2 -> 7 | AJ8: =AE8*8/3 -> 5.3333333 | AK8: =AE8*4 -> 8 | AL8: =AE8*8 -> 16 | AM8: =AE8*7 -> 14 | AN8: =AE8*8/(AE8*8+100) -> 0.13793103 | AO8: =AE8*8/(AE8*8+100) -> 0.13793103 | AP8: 0 | AQ8: 0 | AR8: =AG8*K8/100/(1-X8)/(1-U8)/(1-R8) -> 333.69347 | AS8: =Y8*AE8/1000*2 -> 153.68144 | AT8: =佣兵培养!AB4 -> 22668.779 | AU8: =佣兵培养!AE4 -> 1252.0391 | AV8: 1.1 | AW8: 1.03 | AX8: 1.05 | AY8: =(MIN(AT8/(Y8+(AR8+AS8)/2*BB8),1)*AU8+K8)*AW8 -> 2839.6921 | AZ8: =(Y8+AT8)*AX8*AV8 -> 70557.955 | BA8: =AY8*AZ8^(1/3) -> 117341.94 | BB8: 20
A9: 30 | B9: 2840 | C9: 250 | D9: =C9+B9 -> 3090 | E9: =装备属性设计!AB9*AA9 -> 477.1 | F9: =(E9+$C$27*D9+D32)*(1+AL9/100) -> 974.764 | G9: =F9/(A9*A9*3+3*A9+50+F9) -> 0.25552406 | H9: =装备属性设计!Q9*AA9 -> 1072.5 | I9: =D9*1.5*MAX($C$26:$C$29) -> 2781 | J9: 1.5 | K9: =(I9+H9)/2*(1+AK9/100)*J9 -> 3236.94 | L9: =$C$29*D9 -> 618 | M9: =装备属性设计!D9*AA9 -> 4368 | N9: =ROUND((L9*10+M9)*(100+AF9)/100,0) -> 12130 | O9: =M9/N9 -> 0.36009893 | P9: =(装备属性设计!I9+装备属性设计!F9) -> 432 | Q9: =(P9+E32)*AB9*(1+AH9/100) -> 1075.2 | R9: =Q9/(A9*A9*3+A9*3+50+Q9) -> 0.27462199 | S9: =装备属性设计!X9*AB9*(1+AI9/100) -> 493.272 | T9: =装备属性设计!V9*AB9 -> 446.4 | U9: =(S9+D9*$C$26*(1+AI9/100))/($A9*50+S9+D9*$C$26*(1+AI9/100)+50) -> 0.62120675 | V9: =(T9+B9*$C$28)/($A9*50+T9+B9*$C$28+50) -> 0.32029469 | W9: =(装备属性设计!Z9*战斗力成长!AB9+D9*C$27*0.2)*(1+AJ9/100) -> 160.056 | X9: =W9/((3*$A9*$A9+3*$A9+50)/4+W9) -> 0.18396057 | Y9: =(N9/(1-R9))/(1-U9)/(1-X9) -> 54098.228 | Z9: =Y9/K9 -> 16.712768 | AA9: 1.3 | AB9: =(AA9-1)/1.5+1 -> 1.2 | AC9: =B9*C$29 -> 568 | AD9: =AC9/((A9*A9*3+A9*3+50)*2+AC9) -> 0.090909091 | AE9: 3 | AF9: =AE9*5 -> 15 | AG9: =AE9*2 -> 6 | AH9: =AE9*8/2 -> 12 | AI9: =AE9*7/2 -> 10.5 | AJ9: =AE9*8/3 -> 8 | AK9: =AE9*4 -> 12 | AL9: =AE9*8 -> 24 | AM9: =AE9*7 -> 21 | AN9: =AE9*8/(AE9*8+100) -> 0.19354839 | AO9: =AE9*8/(AE9*8+100) -> 0.19354839 | AP9: =VLOOKUP($A9,[1]怪物抗性与玩家穿透!$A$2:$E$74,4,0) -> 20 | AQ9: =VLOOKUP($A9,[1]怪物抗性与玩家穿透!$A$2:$E$74,5,0) -> 0 | AR9: =AG9*K9/100/(1-U9)/(1-R9)*(1-(AP9*(1-AN9)/(AP9*(1-AN9)+VLOOKUP(A9,[1]怪物抗性与玩家穿透!$A$2:$I$74,8,0))))*(1-(AQ9*(1-AO9)/(VLOOKUP(A9,[1]怪物抗性与玩家穿透!$A$2:$I$74,9,0)+AQ9*(1-AO9)))) -> 702.81014 | AS9: =Y9*AE9/1000*2 -> 324.58937 | AT9: =佣兵培养!AB5 -> 43754.725 | AU9: =佣兵培养!AE5 -> 1893.8499 | AV9: 1.1 | AW9: 1.06 | AX9: 1.05 | AY9: =(MIN(AT9/(Y9+(AR9+AS9)/2*BB9),1)*AU9+K9)*AW9 -> 4774.2341 | AZ9: =(Y9+AT9)*AX9*AV9 -> 113020.16 | BA9: =AY9*AZ9^(1/3) -> 230828.28 | BB9: 22
A10: 35 | B10: 3830 | C10: 285 | D10: =C10+B10 -> 4115 | E10: =装备属性设计!AB10*AA10 -> 823.2 | F10: =(E10+$C$27*D10+D33)*(1+AL10/100) -> 1531.028 | G10: =F10/(A10*A10*3+3*A10+50+F10) -> 0.28558478 | H10: =装备属性设计!Q10*AA10 -> 1860.6 | I10: =D10*1.5*MAX($C$26:$C$29) -> 3703.5 | J10: 1.55 | K10: =(I10+H10)/2*(1+AK10/100)*J10 -> 4829.6388 | L10: =$C$29*D10 -> 823 | M10: =装备属性设计!D10*AA10 -> 6860 | N10: =ROUND((L10*10+M10)*(100+AF10)/100,0) -> 17354 | O10: =M10/N10 -> 0.39529791 | P10: =(装备属性设计!I10+装备属性设计!F10) -> 586 | Q10: =(P10+E33)*AB10*(1+AH10/100) -> 1790.3573 | R10: =Q10/(A10*A10*3+A10*3+50+Q10) -> 0.31854867 | S10: =装备属性设计!X10*AB10*(1+AI10/100) -> 834.20133 | T10: =装备属性设计!V10*AB10 -> 686.53333 | U10: =(S10+D10*$C$26*(1+AI10/100))/($A10*50+S10+D10*$C$26*(1+AI10/100)+50) -> 0.66433231 | V10: =(T10+B10*$C$28)/($A10*50+T10+B10*$C$28+50) -> 0.3727203 | W10: =(装备属性设计!Z10*战斗力成长!AB10+D10*C$27*0.2)*(1+AJ10/100) -> 201.06 | X10: =W10/((3*$A10*$A10+3*$A10+50)/4+W10) -> 0.17354302 | Y10: =(N10/(1-R10))/(1-U10)/(1-X10) -> 91798.366 | Z10: =Y10/K10 -> 19.007294 | AA10: 1.4 | AB10: =(AA10-1)/1.5+1 -> 1.2666667 | AC10: =B10*C$29 -> 766 | AD10: =AC10/((A10*A10*3+A10*3+50)*2+AC10) -> 0.090909091 | AE10: 3 | AF10: =AE10*5 -> 15 | AG10: =AE10*2 -> 6 | AH10: =AE10*8/2 -> 12 | AI10: =AE10*7/2 -> 10.5 | AJ10: =AE10*8/3 -> 8 | AK10: =AE10*4 -> 12 | AL10: =AE10*8 -> 24 | AM10: =AE10*7 -> 21 | AN10: =AE10*8/(AE10*8+100) -> 0.19354839 | AO10: =AE10*8/(AE10*8+100) -> 0.19354839 | AP10: =VLOOKUP($A10,[1]怪物抗性与玩家穿透!$A$2:$E$74,4,0) -> 170 | AQ10: =VLOOKUP($A10,[1]怪物抗性与玩家穿透!$A$2:$E$74,5,0) -> 40 | AR10: =AG10*K10/100/(1-U10)/(1-R10)*(1-(AP10*(1-AN10)/(AP10*(1-AN10)+VLOOKUP(A10,[1]怪物抗性与玩家穿透!$A$2:$I$74,8,0))))*(1-(AQ10*(1-AO10)/(VLOOKUP(A10,[1]怪物抗性与玩家穿透!$A$2:$I$74,9,0)+AQ10*(1-AO10)))) -> 1201.1988 | AS10: =Y10*AE10/1000*2 -> 550.79019 | AT10: =佣兵培养!AB6 -> 77274.35 | AU10: =佣兵培养!AE6 -> 2779.434 | AV10: 1.1 | AW10: 1.06 | AX10: 1.1 | AY10: =(MIN(AT10/(Y10+(AR10+AS10)/2*BB10),1)*AU10+K10)*AW10 -> 7137.3323 | AZ10: =(Y10+AT10)*AX10*AV10 -> 204577.99 | BA10: =AY10*AZ10^(1/3) -> 420554.43 | BB10: 24
A11: 40 | B11: 4970 | C11: 320 | D11: =C11+B11 -> 5290 | E11: =装备属性设计!AB11*AA11 -> 1232 | F11: =(E11+$C$27*D11+D34)*(1+AL11/100) -> 2324.52 | G11: =F11/(A11*A11*3+3*A11+50+F11) -> 0.31866662 | H11: =装备属性设计!Q11*AA11 -> 2814 | I11: =D11*1.5*MAX($C$26:$C$29) -> 4761 | J11: 1.6 | K11: =(I11+H11)/2*(1+AK11/100)*J11 -> 7029.6 | L11: =$C$29*D11 -> 1058 | M11: =装备属性设计!D11*AA11 -> 9408 | N11: =ROUND((L11*10+M11)*(100+AF11)/100,0) -> 23986 | O11: =M11/N11 -> 0.3922288 | P11: =(装备属性设计!I11+装备属性设计!F11) -> 994 | Q11: =(P11+E34)*AB11*(1+AH11/100) -> 2753.5307 | R11: =Q11/(A11*A11*3+A11*3+50+Q11) -> 0.35651191 | S11: =装备属性设计!X11*AB11*(1+AI11/100) -> 1084.444 | T11: =装备属性设计!V11*AB11 -> 686.53333 | U11: =(S11+D11*$C$26*(1+AI11/100))/($A11*50+S11+D11*$C$26*(1+AI11/100)+50) -> 0.6964224 | V11: =(T11+B11*$C$28)/($A11*50+T11+B11*$C$28+50) -> 0.3660186 | W11: =(装备属性设计!Z11*战斗力成长!AB11+D11*C$27*0.2)*(1+AJ11/100) -> 268.47733 | X11: =W11/((3*$A11*$A11+3*$A11+50)/4+W11) -> 0.17768455 | Y11: =(N11/(1-R11))/(1-U11)/(1-X11) -> 149316.96 | Z11: =Y11/K11 -> 21.241175 | AA11: 1.4 | AB11: =(AA11-1)/1.5+1 -> 1.2666667 | AC11: =B11*C$29 -> 994 | AD11: =AC11/((A11*A11*3+A11*3+50)*2+AC11) -> 0.090909091 | AE11: 4 | AF11: =AE11*5 -> 20 | AG11: =AE11*2 -> 8 | AH11: =AE11*8/2 -> 16 | AI11: =AE11*7/2 -> 14 | AJ11: =AE11*8/3 -> 10.666667 | AK11: =AE11*4 -> 16 | AL11: =AE11*8 -> 32 | AM11: =AE11*7 -> 28 | AN11: =AE11*8/(AE11*8+100) -> 0.24242424 | AO11: =AE11*8/(AE11*8+100) -> 0.24242424 | AP11: =VLOOKUP($A11,[1]怪物抗性与玩家穿透!$A$2:$E$74,4,0) -> 320 | AQ11: =VLOOKUP($A11,[1]怪物抗性与玩家穿透!$A$2:$E$74,5,0) -> 90 | AR11: =AG11*K11/100/(1-U11)/(1-R11)*(1-(AP11*(1-AN11)/(AP11*(1-AN11)+VLOOKUP(A11,[1]怪物抗性与玩家穿透!$A$2:$I$74,8,0))))*(1-(AQ11*(1-AO11)/(VLOOKUP(A11,[1]怪物抗性与玩家穿透!$A$2:$I$74,9,0)+AQ11*(1-AO11)))) -> 2655.6718 | AS11: =Y11*AE11/1000*2 -> 1194.5357 | AT11: =佣兵培养!AB7 -> 128760.47 | AU11: =佣兵培养!AE7 -> 3885.2451 | AV11: 1.1 | AW11: 1.06 | AX11: 1.11 | AY11: =(MIN(AT11/(Y11+(AR11+AS11)/2*BB11),1)*AU11+K11)*AW11 -> 10111.168 | AZ11: =(Y11+AT11)*AX11*AV11 -> 339532.54 | BA11: =AY11*AZ11^(1/3) -> 705388.67 | BB11: 26
A12: 45 | B12: 6260 | C12: 355 | D12: =C12+B12 -> 6615 | E12: =装备属性设计!AB12*AA12 -> 1757 | F12: =(E12+$C$27*D12+D35)*(1+AL12/100) -> 3192.42 | G12: =F12/(A12*A12*3+3*A12+50+F12) -> 0.33773573 | H12: =装备属性设计!Q12*AA12 -> 3588.2 | I12: =D12*1.5*MAX($C$26:$C$29) -> 5953.5 | J12: 1.65 | K12: =(I12+H12)/2*(1+AK12/100)*J12 -> 9131.4069 | L12: =$C$29*D12 -> 1323 | M12: =装备属性设计!D12*AA12 -> 12376 | N12: =ROUND((L12*10+M12)*(100+AF12)/100,0) -> 30727 | O12: =M12/N12 -> 0.40277281 | P12: =(装备属性设计!I12+装备属性设计!F12) -> 1256 | Q12: =(P12+E35)*AB12*(1+AH12/100) -> 3686.5573 | R12: =Q12/(A12*A12*3+A12*3+50+Q12) -> 0.37063651 | S12: =装备属性设计!X12*AB12*(1+AI12/100) -> 1084.444 | T12: =装备属性设计!V12*AB12 -> 951.26667 | U12: =(S12+D12*$C$26*(1+AI12/100))/($A12*50+S12+D12*$C$26*(1+AI12/100)+50) -> 0.70919588 | V12: =(T12+B12*$C$28)/($A12*50+T12+B12*$C$28+50) -> 0.4067986 | W12: =(装备属性设计!Z12*战斗力成长!AB12+D12*C$27*0.2)*(1+AJ12/100) -> 338.45556 | X12: =W12/((3*$A12*$A12+3*$A12+50)/4+W12) -> 0.17781112 | Y12: =(N12/(1-R12))/(1-U12)/(1-X12) -> 204195.64 | Z12: =Y12/K12 -> 22.361904 | AA12: 1.4 | AB12: =(AA12-1)/1.5+1 -> 1.2666667 | AC12: =B12*C$29 -> 1252 | AD12: =AC12/((A12*A12*3+A12*3+50)*2+AC12) -> 0.090909091 | AE12: 4 | AF12: =AE12*5 -> 20 | AG12: =AE12*2 -> 8 | AH12: =AE12*8/2 -> 16 | AI12: =AE12*7/2 -> 14 | AJ12: =AE12*8/3 -> 10.666667 | AK12: =AE12*4 -> 16 | AL12: =AE12*8 -> 32 | AM12: =AE12*7 -> 28 | AN12: =AE12*8/(AE12*8+100) -> 0.24242424 | AO12: =AE12*8/(AE12*8+100) -> 0.24242424 | AP12: =VLOOKUP($A12,[1]怪物抗性与玩家穿透!$A$2:$E$74,4,0) -> 470 | AQ12: =VLOOKUP($A12,[1]怪物抗性与玩家穿透!$A$2:$E$74,5,0) -> 140 | AR12: =AG12*K12/100/(1-U12)/(1-R12)*(1-(AP12*(1-AN12)/(AP12*(1-AN12)+VLOOKUP(A12,[1]怪物抗性与玩家穿透!$A$2:$I$74,8,0))))*(1-(AQ12*(1-AO12)/(VLOOKUP(A12,[1]怪物抗性与玩家穿透!$A$2:$I$74,9,0)+AQ12*(1-AO12)))) -> 3608.8717 | AS12: =Y12*AE12/1000*2 -> 1633.5651 | AT12: =佣兵培养!AB8 -> 197466.89 | AU12: =佣兵培养!AE8 -> 5259.5285 | AV12: 1.1 | AW12: 1.06 | AX12: 1.12 | AY12: =(MIN(AT12/(Y12+(AR12+AS12)/2*BB12),1)*AU12+K12)*AW12 -> 13645.207 | AZ12: =(Y12+AT12)*AX12*AV12 -> 494848.24 | BA12: =AY12*AZ12^(1/3) -> 1079288.3 | BB12: 28
A13: 50 | B13: 7700 | C13: 390 | D13: =C13+B13 -> 8090 | E13: =装备属性设计!AB13*AA13 -> 2589 | F13: =(E13+$C$27*D13+D36)*(1+AL13/100) -> 4757.2 | G13: =F13/(A13*A13*3+3*A13+50+F13) -> 0.38188357 | H13: =装备属性设计!Q13*AA13 -> 4936.5 | I13: =D13*1.5*MAX($C$26:$C$29) -> 7281 | J13: 1.7 | K13: =(I13+H13)/2*(1+AK13/100)*J13 -> 12461.85 | L13: =$C$29*D13 -> 1618 | M13: =装备属性设计!D13*AA13 -> 17340 | N13: =ROUND((L13*10+M13)*(100+AF13)/100,0) -> 41900 | O13: =M13/N13 -> 0.41384248 | P13: =(装备属性设计!I13+装备属性设计!F13) -> 1560 | Q13: =(P13+E36)*AB13*(1+AH13/100) -> 4737.6 | R13: =Q13/(A13*A13*3+A13*3+50+Q13) -> 0.3809095 | S13: =装备属性设计!X13*AB13*(1+AI13/100) -> 1566.6667 | T13: =装备属性设计!V13*AB13 -> 1333.3333 | U13: =(S13+D13*$C$26*(1+AI13/100))/($A13*50+S13+D13*$C$26*(1+AI13/100)+50) -> 0.74032895 | V13: =(T13+B13*$C$28)/($A13*50+T13+B13*$C$28+50) -> 0.45200573 | W13: =(装备属性设计!Z13*战斗力成长!AB13+D13*C$27*0.2)*(1+AJ13/100) -> 443.28444 | X13: =W13/((3*$A13*$A13+3*$A13+50)/4+W13) -> 0.18717534 | Y13: =(N13/(1-R13))/(1-U13)/(1-X13) -> 320656.08 | Z13: =Y13/K13 -> 25.731017 | AA13: 1.5 | AB13: =(AA13-1)/1.5+1 -> 1.3333333 | AC13: =B13*C$29 -> 1540 | AD13: =AC13/((A13*A13*3+A13*3+50)*2+AC13) -> 0.090909091 | AE13: 5 | AF13: =AE13*5 -> 25 | AG13: =AE13*2 -> 10 | AH13: =AE13*8/2 -> 20 | AI13: =AE13*7/2 -> 17.5 | AJ13: =AE13*8/3 -> 13.333333 | AK13: =AE13*4 -> 20 | AL13: =AE13*8 -> 40 | AM13: =AE13*7 -> 35 | AN13: =AE13*8/(AE13*8+100) -> 0.28571429 | AO13: =AE13*8/(AE13*8+100) -> 0.28571429 | AP13: =VLOOKUP($A13,[1]怪物抗性与玩家穿透!$A$2:$E$74,4,0) -> 2500 | AQ13: =VLOOKUP($A13,[1]怪物抗性与玩家穿透!$A$2:$E$74,5,0) -> 750 | AR13: =AG13*K13/100/(1-U13)/(1-R13)*(1-(AP13*(1-AN13)/(AP13*(1-AN13)+VLOOKUP(A13,[1]怪物抗性与玩家穿透!$A$2:$I$74,8,0))))*(1-(AQ13*(1-AO13)/(VLOOKUP(A13,[1]怪物抗性与玩家穿透!$A$2:$I$74,9,0)+AQ13*(1-AO13)))) -> 5194.3314 | AS13: =Y13*AE13/1000*2 -> 3206.5608 | AT13: =佣兵培养!AB9 -> 297398.48 | AU13: =佣兵培养!AE9 -> 7187.7376 | AV13: 1.12 | AW13: 1.06 | AX13: 1.13 | AY13: =(MIN(AT13/(Y13+(AR13+AS13)/2*BB13),1)*AU13+K13)*AW13 -> 18282.394 | AZ13: =(Y13+AT13)*AX13*AV13 -> 782209.85 | BA13: =AY13*AZ13^(1/3) -> 1684512.2 | BB13: 30
A14: 55 | B14: 9290 | C14: 425 | D14: =C14+B14 -> 9715 | E14: =装备属性设计!AB14*AA14 -> 2589 | F14: =(E14+$C$27*D14+D37)*(1+AL14/100) -> 5269.54 | G14: =F14/(A14*A14*3+3*A14+50+F14) -> 0.36193039 | H14: =装备属性设计!Q14*AA14 -> 6342 | I14: =D14*1.5*MAX($C$26:$C$29) -> 8743.5 | J14: 1.75 | K14: =(I14+H14)/2*(1+AK14/100)*J14 -> 16367.767 | L14: =$C$29*D14 -> 1943 | M14: =装备属性设计!D14*AA14 -> 20880 | N14: =ROUND((L14*10+M14)*(100+AF14)/100,0) -> 52403 | O14: =M14/N14 -> 0.39845047 | P14: =(装备属性设计!I14+装备属性设计!F14) -> 2306 | Q14: =(P14+E37)*AB14*(1+AH14/100) -> 7087.84 | R14: =Q14/(A14*A14*3+A14*3+50+Q14) -> 0.43277013 | S14: =装备属性设计!X14*AB14*(1+AI14/100) -> 2082.8133 | T14: =装备属性设计!V14*AB14 -> 1721.3333 | U14: =(S14+D14*$C$26*(1+AI14/100))/($A14*50+S14+D14*$C$26*(1+AI14/100)+50) -> 0.76541365 | V14: =(T14+B14*$C$28)/($A14*50+T14+B14*$C$28+50) -> 0.48626995 | W14: =(装备属性设计!Z14*战斗力成长!AB14+D14*C$27*0.2)*(1+AJ14/100) -> 559.468 | X14: =W14/((3*$A14*$A14+3*$A14+50)/4+W14) -> 0.19412707 | Y14: =(N14/(1-R14))/(1-U14)/(1-X14) -> 488683.59 | Z14: =Y14/K14 -> 29.85646 | AA14: 1.5 | AB14: =(AA14-1)/1.5+1 -> 1.3333333 | AC14: =B14*C$29 -> 1858 | AD14: =AC14/((A14*A14*3+A14*3+50)*2+AC14) -> 0.090909091 | AE14: 6 | AF14: =AE14*5 -> 30 | AG14: =AE14*2 -> 12 | AH14: =AE14*8/2 -> 24 | AI14: =AE14*7/2 -> 21 | AJ14: =AE14*8/3 -> 16 | AK14: =AE14*4 -> 24 | AL14: =AE14*8 -> 48 | AM14: =AE14*7 -> 42 | AN14: =AE14*8/(AE14*8+100) -> 0.32432432 | AO14: =AE14*8/(AE14*8+100) -> 0.32432432 | AP14: =VLOOKUP($A14,[1]怪物抗性与玩家穿透!$A$2:$E$74,4,0) -> 5000 | AQ14: =VLOOKUP($A14,[1]怪物抗性与玩家穿透!$A$2:$E$74,5,0) -> 1500 | AR14: =AG14*K14/100/(1-U14)/(1-R14)*(1-(AP14*(1-AN14)/(AP14*(1-AN14)+VLOOKUP(A14,[1]怪物抗性与玩家穿透!$A$2:$I$74,8,0))))*(1-(AQ14*(1-AO14)/(VLOOKUP(A14,[1]怪物抗性与玩家穿透!$A$2:$I$74,9,0)+AQ14*(1-AO14)))) -> 7936.153 | AS14: =Y14*AE14/1000*2 -> 5864.2031 | AT14: =佣兵培养!AB10 -> 441587.36 | AU14: =佣兵培养!AE10 -> 9525.0209 | AV14: 1.14 | AW14: 1.07 | AX14: 1.14 | AY14: =(MIN(AT14/(Y14+(AR14+AS14)/2*BB14),1)*AU14+K14)*AW14 -> 23919.187 | AZ14: =(Y14+AT14)*AX14*AV14 -> 1208980.1 | BA14: =AY14*AZ14^(1/3) -> 2548117.6 | BB14: 31
A15: 60 | B15: 11030 | C15: 460 | D15: =C15+B15 -> 11490 | E15: =装备属性设计!AB15*AA15 -> 3795 | F15: =(E15+$C$27*D15+D38)*(1+AL15/100) -> 7712.64 | G15: =F15/(A15*A15*3+3*A15+50+F15) -> 0.41150233 | H15: =装备属性设计!Q15*AA15 -> 9934.65 | I15: =D15*1.5*MAX($C$26:$C$29) -> 10341 | J15: 1.8 | K15: =(I15+H15)/2*(1+AK15/100)*J15 -> 23357.549 | L15: =$C$29*D15 -> 2298 | M15: =装备属性设计!D15*AA15 -> 22968 | N15: =ROUND((L15*10+M15)*(100+AF15)/100,0) -> 62030 | O15: =M15/N15 -> 0.37027245 | P15: =(装备属性设计!I15+装备属性设计!F15) -> 2754 | Q15: =(P15+E38)*AB15*(1+AH15/100) -> 9666.8587 | R15: =Q15/(A15*A15*3+A15*3+50+Q15) -> 0.46706888 | S15: =装备属性设计!X15*AB15*(1+AI15/100) -> 2905.166 | T15: =装备属性设计!V15*AB15 -> 2333.4667 | U15: =(S15+D15*$C$26*(1+AI15/100))/($A15*50+S15+D15*$C$26*(1+AI15/100)+50) -> 0.79020781 | V15: =(T15+B15*$C$28)/($A15*50+T15+B15*$C$28+50) -> 0.52979023 | W15: =(装备属性设计!Z15*战斗力成长!AB15+D15*C$27*0.2)*(1+AJ15/100) -> 733.63689 | X15: =W15/((3*$A15*$A15+3*$A15+50)/4+W15) -> 0.21014269 | Y15: =(N15/(1-R15))/(1-U15)/(1-X15) -> 702413.32 | Z15: =Y15/K15 -> 30.072219 | AA15: 1.65 | AB15: =(AA15-1)/1.5+1 -> 1.4333333 | AC15: =B15*C$29 -> 2206 | AD15: =AC15/((A15*A15*3+A15*3+50)*2+AC15) -> 0.090909091 | AE15: 7 | AF15: =AE15*5 -> 35 | AG15: =AE15*2 -> 14 | AH15: =AE15*8/2 -> 28 | AI15: =AE15*7/2 -> 24.5 | AJ15: =AE15*8/3 -> 18.666667 | AK15: =AE15*4 -> 28 | AL15: =AE15*8 -> 56 | AM15: =AE15*7 -> 49 | AN15: =AE15*8/(AE15*8+100) -> 0.35897436 | AO15: =AE15*8/(AE15*8+100) -> 0.35897436 | AP15: =VLOOKUP($A15,[1]怪物抗性与玩家穿透!$A$2:$E$74,4,0) -> 7500 | AQ15: =VLOOKUP($A15,[1]怪物抗性与玩家穿透!$A$2:$E$74,5,0) -> 2250 | AR15: =AG15*K15/100/(1-U15)/(1-R15)*(1-(AP15*(1-AN15)/(AP15*(1-AN15)+VLOOKUP(A15,[1]怪物抗性与玩家穿透!$A$2:$I$74,8,0))))*(1-(AQ15*(1-AO15)/(VLOOKUP(A15,[1]怪物抗性与玩家穿透!$A$2:$I$74,9,0)+AQ15*(1-AO15)))) -> 13808.569 | AS15: =Y15*AE15/1000*2 -> 9833.7865 | AT15: =佣兵培养!AB11 -> 623569.15 | AU15: =佣兵培养!AE11 -> 11995.648 | AV15: 1.16 | AW15: 1.08 | AX15: 1.15 | AY15: =(MIN(AT15/(Y15+(AR15+AS15)/2*BB15),1)*AU15+K15)*AW15 -> 32701.486 | AZ15: =(Y15+AT15)*AX15*AV15 -> 1768860.6 | BA15: =AY15*AZ15^(1/3) -> 3954868.3 | BB15: 32
A16: 65 | B16: 12920 | C16: 495 | D16: =C16+B16 -> 13415 | E16: =装备属性设计!AB16*AA16 -> 6991.2 | F16: =(E16+$C$27*D16+D39)*(1+AL16/100) -> 13665.628 | G16: =F16/(A16*A16*3+3*A16+50+F16) -> 0.51402314 | H16: =装备属性设计!Q16*AA16 -> 14146.2 | I16: =D16*1.5*MAX($C$26:$C$29) -> 12073.5 | J16: 1.9 | K16: =(I16+H16)/2*(1+AK16/100)*J16 -> 32879.504 | L16: =$C$29*D16 -> 2683 | M16: =装备属性设计!D16*AA16 -> 30420 | N16: =ROUND((L16*10+M16)*(100+AF16)/100,0) -> 80150 | O16: =M16/N16 -> 0.37953837 | P16: =(装备属性设计!I16+装备属性设计!F16) -> 3256 | Q16: =(P16+E39)*AB16*(1+AH16/100) -> 12637.856 | R16: =Q16/(A16*A16*3+A16*3+50+Q16) -> 0.49448029 | S16: =装备属性设计!X16*AB16*(1+AI16/100) -> 3954.7733 | T16: =装备属性设计!V16*AB16 -> 3089.6667 | U16: =(S16+D16*$C$26*(1+AI16/100))/($A16*50+S16+D16*$C$26*(1+AI16/100)+50) -> 0.81204606 | V16: =(T16+B16*$C$28)/($A16*50+T16+B16*$C$28+50) -> 0.57040573 | W16: =(装备属性设计!Z16*战斗力成长!AB16+D16*C$27*0.2)*(1+AJ16/100) -> 980.41378 | X16: =W16/((3*$A16*$A16+3*$A16+50)/4+W16) -> 0.2328545 | Y16: =(N16/(1-R16))/(1-U16)/(1-X16) -> 1099603.9 | Z16: =Y16/K16 -> 33.443445 | AA16: 1.8 | AB16: =(AA16-1)/1.5+1 -> 1.5333333 | AC16: =B16*C$29 -> 2584 | AD16: =AC16/((A16*A16*3+A16*3+50)*2+AC16) -> 0.090909091 | AE16: 8 | AF16: =AE16*5 -> 40 | AG16: =AE16*2 -> 16 | AH16: =AE16*8/2 -> 32 | AI16: =AE16*7/2 -> 28 | AJ16: =AE16*8/3 -> 21.333333 | AK16: =AE16*4 -> 32 | AL16: =AE16*8 -> 64 | AM16: =AE16*7 -> 56 | AN16: =AE16*8/(AE16*8+100) -> 0.3902439 | AO16: =AE16*8/(AE16*8+100) -> 0.3902439 | AP16: =VLOOKUP($A16,[1]怪物抗性与玩家穿透!$A$2:$E$74,4,0) -> 10000 | AQ16: =VLOOKUP($A16,[1]怪物抗性与玩家穿透!$A$2:$E$74,5,0) -> 3000 | AR16: =AG16*K16/100/(1-U16)/(1-R16)*(1-(AP16*(1-AN16)/(AP16*(1-AN16)+VLOOKUP(A16,[1]怪物抗性与玩家穿透!$A$2:$I$74,8,0))))*(1-(AQ16*(1-AO16)/(VLOOKUP(A16,[1]怪物抗性与玩家穿透!$A$2:$I$74,9,0)+AQ16*(1-AO16)))) -> 24164.218 | AS16: =Y16*AE16/1000*2 -> 17593.662 | AT16: =佣兵培养!AB12 -> 847048.45 | AU16: =佣兵培养!AE12 -> 15317.716 | AV16: 1.18 | AW16: 1.09 | AX16: 1.16 | AY16: =(MIN(AT16/(Y16+(AR16+AS16)/2*BB16),1)*AU16+K16)*AW16 -> 43745.689 | AZ16: =(Y16+AT16)*AX16*AV16 -> 2664577.7 | BA16: =AY16*AZ16^(1/3) -> 6064728.9 | BB16: 33
A17: 70 | B17: 14960 | C17: 530 | D17: =C17+B17 -> 15490 | E17: =装备属性设计!AB17*AA17 -> 8168.55 | F17: =(E17+$C$27*D17+D40)*(1+AL17/100) -> 16714.186 | G17: =F17/(A17*A17*3+3*A17+50+F17) -> 0.5276911 | H17: =装备属性设计!Q17*AA17 -> 19125.6 | I17: =D17*1.5*MAX($C$26:$C$29) -> 13941 | J17: 2 | K17: =(I17+H17)/2*(1+AK17/100)*J17 -> 44970.576 | L17: =$C$29*D17 -> 3098 | M17: =装备属性设计!D17*AA17 -> 37440 | N17: =ROUND((L17*10+M17)*(100+AF17)/100,0) -> 99209 | O17: =M17/N17 -> 0.37738512 | P17: =(装备属性设计!I17+装备属性设计!F17) -> 3688 | Q17: =(P17+E40)*AB17*(1+AH17/100) -> 16015.813 | R17: =Q17/(A17*A17*3+A17*3+50+Q17) -> 0.51704254 | S17: =装备属性设计!X17*AB17*(1+AI17/100) -> 4845.512 | T17: =装备属性设计!V17*AB17 -> 3684.8 | U17: =(S17+D17*$C$26*(1+AI17/100))/($A17*50+S17+D17*$C$26*(1+AI17/100)+50) -> 0.82781302 | V17: =(T17+B17*$C$28)/($A17*50+T17+B17*$C$28+50) -> 0.5933935 | W17: =(装备属性设计!Z17*战斗力成长!AB17+D17*C$27*0.2)*(1+AJ17/100) -> 1279.3493 | X17: =W17/((3*$A17*$A17+3*$A17+50)/4+W17) -> 0.2548835 | Y17: =(N17/(1-R17))/(1-U17)/(1-X17) -> 1601097.2 | Z17: =Y17/K17 -> 35.603218 | AA17: 1.95 | AB17: =(AA17-1)/1.5+1 -> 1.6333333 | AC17: =B17*C$29 -> 2992 | AD17: =AC17/((A17*A17*3+A17*3+50)*2+AC17) -> 0.090909091 | AE17: 9 | AF17: =AE17*5 -> 45 | AG17: =AE17*2 -> 18 | AH17: =AE17*8/2 -> 36 | AI17: =AE17*7/2 -> 31.5 | AJ17: =AE17*8/3 -> 24 | AK17: =AE17*4 -> 36 | AL17: =AE17*8 -> 72 | AM17: =AE17*7 -> 63 | AN17: =AE17*8/(AE17*8+100) -> 0.41860465 | AO17: =AE17*8/(AE17*8+100) -> 0.41860465 | AP17: =VLOOKUP($A17,[1]怪物抗性与玩家穿透!$A$2:$E$74,4,0) -> 12500 | AQ17: =VLOOKUP($A17,[1]怪物抗性与玩家穿透!$A$2:$E$74,5,0) -> 3750 | AR17: =AG17*K17/100/(1-U17)/(1-R17)*(1-(AP17*(1-AN17)/(AP17*(1-AN17)+VLOOKUP(A17,[1]怪物抗性与玩家穿透!$A$2:$I$74,8,0))))*(1-(AQ17*(1-AO17)/(VLOOKUP(A17,[1]怪物抗性与玩家穿透!$A$2:$I$74,9,0)+AQ17*(1-AO17)))) -> 40529.456 | AS17: =Y17*AE17/1000*2 -> 28819.75 | AT17: =佣兵培养!AB13 -> 1178621.3 | AU17: =佣兵培养!AE13 -> 19701.124 | AV17: 1.2 | AW17: 1.1 | AX17: 1.17 | AY17: =(MIN(AT17/(Y17+(AR17+AS17)/2*BB17),1)*AU17+K17)*AW17 -> 58655.357 | AZ17: =(Y17+AT17)*AX17*AV17 -> 3902724.9 | BA17: =AY17*AZ17^(1/3) -> 9234860.3 | BB17: 34
A18: 75 | B18: 17150 | C18: 565 | D18: =C18+B18 -> 17715 | E18: =装备属性设计!AB18*AA18 -> 9725.1 | F18: =(E18+$C$27*D18+D41)*(1+AL18/100) -> 20693.88 | G18: =F18/(A18*A18*3+3*A18+50+F18) -> 0.54682237 | H18: =装备属性设计!Q18*AA18 -> 24009.3 | I18: =D18*1.5*MAX($C$26:$C$29) -> 15943.5 | J18: 2.1 | K18: =(I18+H18)/2*(1+AK18/100)*J18 -> 58730.616 | L18: =$C$29*D18 -> 3543 | M18: =装备属性设计!D18*AA18 -> 45360 | N18: =ROUND((L18*10+M18)*(100+AF18)/100,0) -> 121185 | O18: =M18/N18 -> 0.37430375 | P18: =(装备属性设计!I18+装备属性设计!F18) -> 4390 | Q18: =(P18+E41)*AB18*(1+AH18/100) -> 20226.267 | R18: =Q18/(A18*A18*3+A18*3+50+Q18) -> 0.54115267 | S18: =装备属性设计!X18*AB18*(1+AI18/100) -> 6161.22 | T18: =装备属性设计!V18*AB18 -> 4563.8667 | U18: =(S18+D18*$C$26*(1+AI18/100))/($A18*$A18*5+S18+D18*$C$26*(1+AI18/100)+24200-$A18*645) -> 0.8385143 | V18: =(T18+B18*$C$28)/($A18*$A18*5+T18+B18*$C$28+24200-$A18*645) -> 0.61383796 | W18: =(装备属性设计!Z18*战斗力成长!AB18+D18*C$27*0.2)*(1+AJ18/100) -> 1579.4911 | X18: =W18/((3*$A18*$A18+3*$A18+50)/4+W18) -> 0.26921655 | Y18: =(N18/(1-R18))/(1-U18)/(1-X18) -> 2237988.7 | Z18: =Y18/K18 -> 38.105997 | AA18: 2.1 | AB18: =(AA18-1)/1.5+1 -> 1.7333333 | AC18: =B18*C$29 -> 3430 | AD18: =AC18/((A18*A18*3+A18*3+50)*2+AC18) -> 0.090909091 | AE18: 10 | AF18: =AE18*5 -> 50 | AG18: =AE18*2 -> 20 | AH18: =AE18*8/2 -> 40 | AI18: =AE18*7/2 -> 35 | AJ18: =AE18*8/3 -> 26.666667 | AK18: =AE18*4 -> 40 | AL18: =AE18*8 -> 80 | AM18: =AE18*7 -> 70 | AN18: =AE18*8/(AE18*8+100) -> 0.44444444 | AO18: =AE18*8/(AE18*8+100) -> 0.44444444 | AP18: =VLOOKUP($A18,[1]怪物抗性与玩家穿透!$A$2:$E$74,4,0) -> 15000 | AQ18: =VLOOKUP($A18,[1]怪物抗性与玩家穿透!$A$2:$E$74,5,0) -> 4500 | AR18: =AG18*K18/100/(1-U18)/(1-R18)*(1-(AP18*(1-AN18)/(AP18*(1-AN18)+VLOOKUP(A18,[1]怪物抗性与玩家穿透!$A$2:$I$74,8,0))))*(1-(AQ18*(1-AO18)/(VLOOKUP(A18,[1]怪物抗性与玩家穿透!$A$2:$I$74,9,0)+AQ18*(1-AO18)))) -> 65246.3 | AS18: =Y18*AE18/1000*2 -> 44759.774 | AT18: =佣兵培养!AB14 -> 1819703.5 | AU18: =佣兵培养!AE14 -> 28762.982 | AV18: 1.22 | AW18: 1.11 | AX18: 1.18 | AY18: =(MIN(AT18/(Y18+(AR18+AS18)/2*BB18),1)*AU18+K18)*AW18 -> 79146.349 | AZ18: =(Y18+AT18)*AX18*AV18 -> 5841453.7 | BA18: =AY18*AZ18^(1/3) -> 14254036 | BB18: 35
A19: 80 | B19: 19490 | C19: 600 | D19: =C19+B19 -> 20090 | E19: =装备属性设计!AB19*AA19 -> 11400.75 | F19: =(E19+$C$27*D19+D42)*(1+AL19/100) -> 25210.33 | G19: =F19/(A19*A19*3+3*A19+50+F19) -> 0.56398532 | H19: =装备属性设计!Q19*AA19 -> 29234.25 | I19: =D19*1.5*MAX($C$26:$C$29) -> 18081 | J19: 2.2 | K19: =(I19+H19)/2*(1+AK19/100)*J19 -> 74947.356 | L19: =$C$29*D19 -> 4018 | M19: =装备属性设计!D19*AA19 -> 54180 | N19: =ROUND((L19*10+M19)*(100+AF19)/100,0) -> 146258 | O19: =M19/N19 -> 0.37044128 | P19: =(装备属性设计!I19+装备属性设计!F19) -> 5146 | Q19: =(P19+E42)*AB19*(1+AH19/100) -> 24905.76 | R19: =Q19/(A19*A19*3+A19*3+50+Q19) -> 0.56099411 | S19: =装备属性设计!X19*AB19*(1+AI19/100) -> 7785.085 | T19: =装备属性设计!V19*AB19 -> 5621 | U19: =(S19+D19*$C$26*(1+AI19/100))/($A19*$A19*5+S19+D19*$C$26*(1+AI19/100)+24200-$A19*645) -> 0.841815 | V19: =(T19+B19*$C$28)/($A19*$A19*5+T19+B19*$C$28+24200-$A19*645) -> 0.62202136 | W19: =(装备属性设计!Z19*战斗力成长!AB19+D19*C$27*0.2)*(1+AJ19/100) -> 1866.4524 | X19: =W19/((3*$A19*$A19+3*$A19+50)/4+W19) -> 0.27696477 | Y19: =(N19/(1-R19))/(1-U19)/(1-X19) -> 2912893 | Z19: =Y19/K19 -> 38.865854 | AA19: 2.25 | AB19: =(AA19-1)/1.5+1 -> 1.8333333 | AC19: =B19*C$29 -> 3898 | AD19: =AC19/((A19*A19*3+A19*3+50)*2+AC19) -> 0.090909091 | AE19: 11 | AF19: =AE19*5 -> 55 | AG19: =AE19*2 -> 22 | AH19: =AE19*8/2 -> 44 | AI19: =AE19*7/2 -> 38.5 | AJ19: =AE19*8/3 -> 29.333333 | AK19: =AE19*4 -> 44 | AL19: =AE19*8 -> 88 | AM19: =AE19*7 -> 77 | AN19: =AE19*8/(AE19*8+100) -> 0.46808511 | AO19: =AE19*8/(AE19*8+100) -> 0.46808511 | AP19: =VLOOKUP($A19,[1]怪物抗性与玩家穿透!$A$2:$E$74,4,0) -> 17500 | AQ19: =VLOOKUP($A19,[1]怪物抗性与玩家穿透!$A$2:$E$74,5,0) -> 5250 | AR19: =AG19*K19/100/(1-U19)/(1-R19)*(1-(AP19*(1-AN19)/(AP19*(1-AN19)+VLOOKUP(A19,[1]怪物抗性与玩家穿透!$A$2:$I$74,8,0))))*(1-(AQ19*(1-AO19)/(VLOOKUP(A19,[1]怪物抗性与玩家穿透!$A$2:$I$74,9,0)+AQ19*(1-AO19)))) -> 99863.459 | AS19: =Y19*AE19/1000*2 -> 64083.646 | AT19: =佣兵培养!AB15 -> 2555862.5 | AU19: =佣兵培养!AE15 -> 40436.063 | AV19: 1.24 | AW19: 1.12 | AX19: 1.19 | AY19: =(MIN(AT19/(Y19+(AR19+AS19)/2*BB19),1)*AU19+K19)*AW19 -> 103680.48 | AZ19: =(Y19+AT19)*AX19*AV19 -> 8069695.6 | BA19: =AY19*AZ19^(1/3) -> 20796139 | BB19: 36
A20: 85 | B20: 21980 | C20: 635 | D20: =C20+B20 -> 22615 | E20: =装备属性设计!AB20*AA20 -> 13188 | F20: =(E20+$C$27*D20+D43)*(1+AL20/100) -> 30281.02 | G20: =F20/(A20*A20*3+3*A20+50+F20) -> 0.57941885 | H20: =装备属性设计!Q20*AA20 -> 35167.2 | I20: =D20*1.5*MAX($C$26:$C$29) -> 20353.5 | J20: 2.3 | K20: =(I20+H20)/2*(1+AK20/100)*J20 -> 94496.231 | L20: =$C$29*D20 -> 4523 | M20: =装备属性设计!D20*AA20 -> 64896 | N20: =ROUND((L20*10+M20)*(100+AF20)/100,0) -> 176202 | O20: =M20/N20 -> 0.36830456 | P20: =(装备属性设计!I20+装备属性设计!F20) -> 5978 | Q20: =(P20+E43)*AB20*(1+AH20/100) -> 30312.965 | R20: =Q20/(A20*A20*3+A20*3+50+Q20) -> 0.57967578 | S20: =装备属性设计!X20*AB20*(1+AI20/100) -> 10080.864 | T20: =装备属性设计!V20*AB20 -> 7099.2 | U20: =(S20+D20*$C$26*(1+AI20/100))/($A20*$A20*5+S20+D20*$C$26*(1+AI20/100)+24200-$A20*645) -> 0.84217554 | V20: =(T20+B20*$C$28)/($A20*$A20*5+T20+B20*$C$28+24200-$A20*645) -> 0.62830806 | W20: =(装备属性设计!Z20*战斗力成长!AB20+D20*C$27*0.2)*(1+AJ20/100) -> 2283.908 | X20: =W20/((3*$A20*$A20+3*$A20+50)/4+W20) -> 0.29360265 | Y20: =(N20/(1-R20))/(1-U20)/(1-X20) -> 3760131.6 | Z20: =Y20/K20 -> 39.791339 | AA20: 2.4 | AB20: =(AA20-1)/1.5+1 -> 1.9333333 | AC20: =B20*C$29 -> 4396 | AD20: =AC20/((A20*A20*3+A20*3+50)*2+AC20) -> 0.090909091 | AE20: 12 | AF20: =AE20*5 -> 60 | AG20: =AE20*2 -> 24 | AH20: =AE20*8/2 -> 48 | AI20: =AE20*7/2 -> 42 | AJ20: =AE20*8/3 -> 32 | AK20: =AE20*4 -> 48 | AL20: =AE20*8 -> 96 | AM20: =AE20*7 -> 84 | AN20: =AE20*8/(AE20*8+100) -> 0.48979592 | AO20: =AE20*8/(AE20*8+100) -> 0.48979592 | AP20: 20000 | AQ20: 6000 | AR20: =AG20*K20/100/(1-U20)/(1-R20)*(1-(AP20*(1-AN20)/(AP20*(1-AN20)+VLOOKUP(A20,[1]怪物抗性与玩家穿透!$A$2:$I$74,8,0))))*(1-(AQ20*(1-AO20)/(VLOOKUP(A20,[1]怪物抗性与玩家穿透!$A$2:$I$74,9,0)+AQ20*(1-AO20)))) -> 149822.72 | AS20: =Y20*AE20/1000*2 -> 90243.157 | AT20: =佣兵培养!AB16 -> 3375293 | AU20: =佣兵培养!AE16 -> 55421.923 | AV20: 1.26 | AW20: 1.13 | AX20: 1.2 | AY20: =(MIN(AT20/(Y20+(AR20+AS20)/2*BB20),1)*AU20+K20)*AW20 -> 132555 | AZ20: =(Y20+AT20)*AX20*AV20 -> 10788762 | BA20: =AY20*AZ20^(1/3) -> 29290041 | BB20: 37
A21: 90 | B21: 24620 | C21: 670 | D21: =C21+B21 -> 25290 | E21: =装备属性设计!AB21*AA21 -> 15695.25 | F21: =(E21+$C$27*D21+D44)*(1+AL21/100) -> 37177.47 | G21: =F21/(A21*A21*3+3*A21+50+F21) -> 0.60160181 | H21: =装备属性设计!Q21*AA21 -> 41853.15 | I21: =D21*1.5*MAX($C$26:$C$29) -> 22761 | J21: 2.4 | K21: =(I21+H21)/2*(1+AK21/100)*J21 -> 117856.21 | L21: =$C$29*D21 -> 5058 | M21: =装备属性设计!D21*AA21 -> 75990 | N21: =ROUND((L21*10+M21)*(100+AF21)/100,0) -> 208841 | O21: =M21/N21 -> 0.36386533 | P21: =(装备属性设计!I21+装备属性设计!F21) -> 6894 | Q21: =(P21+E44)*AB21*(1+AH21/100) -> 36525.499 | R21: =Q21/(A21*A21*3+A21*3+50+Q21) -> 0.59735384 | S21: =装备属性设计!X21*AB21*(1+AI21/100) -> 13100.238 | T21: =装备属性设计!V21*AB21 -> 9003.6 | U21: =(S21+D21*$C$26*(1+AI21/100))/($A21*$A21*5+S21+D21*$C$26*(1+AI21/100)+24200-$A21*645) -> 0.84101714 | V21: =(T21+B21*$C$28)/($A21*$A21*5+T21+B21*$C$28+24200-$A21*645) -> 0.63291307 | W21: =(装备属性设计!Z21*战斗力成长!AB21+D21*C$27*0.2)*(1+AJ21/100) -> 2638.9729 | X21: =W21/((3*$A21*$A21+3*$A21+50)/4+W21) -> 0.30008881 | Y21: =(N21/(1-R21))/(1-U21)/(1-X21) -> 4661213.1 | Z21: =Y21/K21 -> 39.55 | AA21: 2.55 | AB21: =(AA21-1)/1.5+1 -> 2.0333333 | AC21: =B21*C$29 -> 4924 | AD21: =AC21/((A21*A21*3+A21*3+50)*2+AC21) -> 0.090909091 | AE21: 13 | AF21: =AE21*5 -> 65 | AG21: =AE21*2 -> 26 | AH21: =AE21*8/2 -> 52 | AI21: =AE21*7/2 -> 45.5 | AJ21: =AE21*8/3 -> 34.666667 | AK21: =AE21*4 -> 52 | AL21: =AE21*8 -> 104 | AM21: =AE21*7 -> 91 | AN21: =AE21*8/(AE21*8+100) -> 0.50980392 | AO21: =AE21*8/(AE21*8+100) -> 0.50980392 | AP21: 27000 | AQ21: 8000 | AR21: =AG21*K21/100/(1-U21)/(1-R21)*(1-(AP21*(1-AN21)/(AP21*(1-AN21)+VLOOKUP(A21,[1]怪物抗性与玩家穿透!$A$2:$I$74,8,0))))*(1-(AQ21*(1-AO21)/(VLOOKUP(A21,[1]怪物抗性与玩家穿透!$A$2:$I$74,9,0)+AQ21*(1-AO21)))) -> 195600.45 | AS21: =Y21*AE21/1000*2 -> 121191.54 | AT21: =佣兵培养!AB17 -> 4250447.3 | AU21: =佣兵培养!AE17 -> 72789.696 | AV21: 1.28 | AW21: 1.14 | AX21: 1.21 | AY21: =(MIN(AT21/(Y21+(AR21+AS21)/2*BB21),1)*AU21+K21)*AW21 -> 167379.92 | AZ21: =(Y21+AT21)*AX21*AV21 -> 13802380 | BA21: =AY21*AZ21^(1/3) -> 40150227 | BB21: 38
