Workbook

Sheet Sheet1
A1: 等级 | B1: 无佣兵玩家DPS | C1: 无佣兵玩家EHP | D1: 玩家DPS | E1: 玩家EHP | F1: 玩家HPS | G1: 回合数 | H1: 普通DPS | I1: 普通EHP | K1: minor1 | L1: minor1 | M1: minor2 | N1: minor2 | O1: BOSS3 | P1: BOSS3 | Q1: minor3 | R1: minor3 | S1: minor4 | T1: minor4 | U1: BOSS6 | V1: BOSS6 | W1: minor5 | X1: minor5 | Y1: minor6 | Z1: minor6 | AA1: BOSSDPS | AB1: BOSSEHP | AC1: 难度系数
A2: 30 | B2: =ROUND([1]战斗力成长!$K9,0) -> 3237 | C2: =ROUND([1]战斗力成长!$Y9,0) -> 54098 | D2: =ROUND([1]战斗力成长!$AY9,0) -> 4774 | E2: =ROUND([1]战斗力成长!$AZ9,0) -> 113020 | F2: =ROUND([1]战斗力成长!$AR9*0.4+[1]战斗力成长!$AS9,0) -> 606 | G2: 10 | H2: =ROUND(((F2+C2/G2)/2)*0.8,0) -> 2406 | I2: =ROUND(G2*0.8*B2,0) -> 25896 | J2: =I2/D2 -> 5.4243821 | K2: =ROUND(H2*(O2/H2)^0.3,0) -> 2549 | L2: =ROUND(I2*(P2/I2)^0.3,0) -> 32012 | M2: =ROUND(H2*(O2/H2)^0.6,0) -> 2700 | N2: =ROUND(I2*(P2/I2)^0.6,0) -> 39572 | O2: =ROUND(H2*0.7+AA2*0.3,0) -> 2915 | P2: =ROUND(I2*0.7+AB2*0.3,0) -> 52500 | Q2: =ROUND(O2*(U2/O2)^0.3,0) -> 3059 | R2: =ROUND(P2*(V2/P2)^0.3,0) -> 59371 | S2: =ROUND(O2*(U2/O2)^0.6,0) -> 3210 | T2: =ROUND(P2*(V2/P2)^0.6,0) -> 67140 | U2: =ROUND(H2*0.4+0.6*AA2,0) -> 3423 | V2: =ROUND(I2*0.4+0.6*AB2,0) -> 79104 | W2: =ROUND(U2*(AA2/U2)^0.3,0) -> 3614 | X2: =ROUND(V2*(AB2/V2)^0.3,0) -> 88403 | Y2: =ROUND(U2*(AA2/U2)^0.6,0) -> 3815 | Z2: =ROUND(V2*(AB2/V2)^0.6,0) -> 98795 | AA2: =ROUND(E2/25*AC2+AC2*F2,0) -> 4101 | AB2: =ROUND(D2*30*AC2,0) -> 114576 | AC2: 0.8
A3: 35 | B3: =ROUND([1]战斗力成长!$K10,0) -> 4830 | C3: =ROUND([1]战斗力成长!$Y10,0) -> 91798 | D3: =ROUND([1]战斗力成长!$AY10,0) -> 7137 | E3: =ROUND([1]战斗力成长!$AZ10,0) -> 204578 | F3: =ROUND([1]战斗力成长!$AR10*0.4+[1]战斗力成长!$AS10,0) -> 1031 | G3: 12 | H3: =ROUND(((F3+C3/G3)/2)*0.8,0) -> 3472 | I3: =ROUND(G3*0.8*B3,0) -> 46368 | J3: =I3/D3 -> 6.4968474 | K3: =ROUND(H3*(O3/H3)^0.3,0) -> 3815 | L3: =ROUND(I3*(P3/I3)^0.3,0) -> 55889 | M3: =ROUND(H3*(O3/H3)^0.6,0) -> 4191 | N3: =ROUND(I3*(P3/I3)^0.6,0) -> 67365 | O3: =ROUND(H3*0.7+AA3*0.3,0) -> 4752 | P3: =ROUND(I3*0.7+AB3*0.3,0) -> 86413 | Q3: =ROUND(O3*(U3/O3)^0.3,0) -> 5105 | R3: =ROUND(P3*(V3/P3)^0.3,0) -> 96870 | S3: =ROUND(O3*(U3/O3)^0.6,0) -> 5484 | T3: =ROUND(P3*(V3/P3)^0.6,0) -> 108592 | U3: =ROUND(H3*0.4+0.6*AA3,0) -> 6033 | V3: =ROUND(I3*0.4+0.6*AB3,0) -> 126458 | W3: =ROUND(U3*(AA3/U3)^0.3,0) -> 6501 | X3: =ROUND(V3*(AB3/V3)^0.3,0) -> 140552 | Y3: =ROUND(U3*(AA3/U3)^0.6,0) -> 7006 | Z3: =ROUND(V3*(AB3/V3)^0.6,0) -> 156217 | AA3: =ROUND(E3/25*AC3+AC3*F3,0) -> 7740 | AB3: =ROUND(D3*30*AC3,0) -> 179852 | AC3: 0.84
A4: 40 | B4: =ROUND([1]战斗力成长!$K11,0) -> 7030 | C4: =ROUND([1]战斗力成长!$Y11,0) -> 149317 | D4: =ROUND([1]战斗力成长!$AY11,0) -> 10111 | E4: =ROUND([1]战斗力成长!$AZ11,0) -> 339533 | F4: =ROUND([1]战斗力成长!$AR11*0.4+[1]战斗力成长!$AS11,0) -> 2257 | G4: 14 | H4: =ROUND(((F4+C4/G4)/2)*0.8,0) -> 5169 | I4: =ROUND(G4*0.8*B4,0) -> 78736 | J4: =I4/D4 -> 7.7871625 | K4: =ROUND(H4*(O4/H4)^0.3,0) -> 5848 | L4: =ROUND(I4*(P4/I4)^0.3,0) -> 92599 | M4: =ROUND(H4*(O4/H4)^0.6,0) -> 6616 | N4: =ROUND(I4*(P4/I4)^0.6,0) -> 108904 | O4: =ROUND(H4*0.7+AA4*0.3,0) -> 7800 | P4: =ROUND(I4*0.7+AB4*0.3,0) -> 135194 | Q4: =ROUND(O4*(U4/O4)^0.3,0) -> 8510 | R4: =ROUND(P4*(V4/P4)^0.3,0) -> 150115 | S4: =ROUND(O4*(U4/O4)^0.6,0) -> 9286 | T4: =ROUND(P4*(V4/P4)^0.6,0) -> 166683 | U4: =ROUND(H4*0.4+0.6*AA4,0) -> 10430 | V4: =ROUND(I4*0.4+0.6*AB4,0) -> 191652 | W4: =ROUND(U4*(AA4/U4)^0.3,0) -> 11378 | X4: =ROUND(V4*(AB4/V4)^0.3,0) -> 211679 | Y4: =ROUND(U4*(AA4/U4)^0.6,0) -> 12412 | Z4: =ROUND(V4*(AB4/V4)^0.6,0) -> 233800 | AA4: =ROUND(E4/25*AC4+AC4*F4,0) -> 13938 | AB4: =ROUND(D4*30*AC4,0) -> 266930 | AC4: 0.88
A5: 45 | B5: =ROUND([1]战斗力成长!$K12,0) -> 9131 | C5: =ROUND([1]战斗力成长!$Y12,0) -> 204196 | D5: =ROUND([1]战斗力成长!$AY12,0) -> 13645 | E5: =ROUND([1]战斗力成长!$AZ12,0) -> 494848 | F5: =ROUND([1]战斗力成长!$AR12*0.4+[1]战斗力成长!$AS12,0) -> 3077 | G5: 16 | H5: =ROUND(((F5+C5/G5)/2)*0.8,0) -> 6336 | I5: =ROUND(G5*0.8*B5,0) -> 116877 | J5: =I5/D5 -> 8.5655551 | K5: =ROUND(H5*(O5/H5)^0.3,0) -> 7425 | L5: =ROUND(I5*(P5/I5)^0.3,0) -> 136233 | M5: =ROUND(H5*(O5/H5)^0.6,0) -> 8700 | N5: =ROUND(I5*(P5/I5)^0.6,0) -> 158796 | O5: =ROUND(H5*0.7+AA5*0.3,0) -> 10748 | P5: =ROUND(I5*0.7+AB5*0.3,0) -> 194795 | Q5: =ROUND(O5*(U5/O5)^0.3,0) -> 11916 | R5: =ROUND(P5*(V5/P5)^0.3,0) -> 215484 | S5: =ROUND(O5*(U5/O5)^0.6,0) -> 13211 | T5: =ROUND(P5*(V5/P5)^0.6,0) -> 238371 | U5: =ROUND(H5*0.4+0.6*AA5,0) -> 15159 | V5: =ROUND(I5*0.4+0.6*AB5,0) -> 272712 | W5: =ROUND(U5*(AA5/U5)^0.3,0) -> 16726 | X5: =ROUND(V5*(AB5/V5)^0.3,0) -> 300440 | Y5: =ROUND(U5*(AA5/U5)^0.6,0) -> 18455 | Z5: =ROUND(V5*(AB5/V5)^0.6,0) -> 330987 | AA5: =ROUND(E5/25*AC5+AC5*F5,0) -> 21041 | AB5: =ROUND(D5*30*AC5,0) -> 376602 | AC5: 0.92
A6: 50 | B6: =ROUND([1]战斗力成长!$K13,0) -> 12462 | C6: =ROUND([1]战斗力成长!$Y13,0) -> 320656 | D6: =ROUND([1]战斗力成长!$AY13,0) -> 18282 | E6: =ROUND([1]战斗力成长!$AZ13,0) -> 782210 | F6: =ROUND([1]战斗力成长!$AR13*0.4+[1]战斗力成长!$AS13,0) -> 5284 | G6: 18 | H6: =ROUND(((F6+C6/G6)/2)*0.8,0) -> 9239 | I6: =ROUND(G6*0.8*B6,0) -> 179453 | J6: =I6/D6 -> 9.8158298 | K6: =ROUND(H6*(O6/H6)^0.3,0) -> 11094 | L6: =ROUND(I6*(P6/I6)^0.3,0) -> 205857 | M6: =ROUND(H6*(O6/H6)^0.6,0) -> 13320 | N6: =ROUND(I6*(P6/I6)^0.6,0) -> 236146 | O6: =ROUND(H6*0.7+AA6*0.3,0) -> 17000 | P6: =ROUND(I6*0.7+AB6*0.3,0) -> 283574 | Q6: =ROUND(O6*(U6/O6)^0.3,0) -> 19030 | R6: =ROUND(P6*(V6/P6)^0.3,0) -> 311468 | S6: =ROUND(O6*(U6/O6)^0.6,0) -> 21304 | T6: =ROUND(P6*(V6/P6)^0.6,0) -> 342105 | U6: =ROUND(H6*0.4+0.6*AA6,0) -> 24762 | V6: =ROUND(I6*0.4+0.6*AB6,0) -> 387694 | W6: =ROUND(U6*(AA6/U6)^0.3,0) -> 27497 | X6: =ROUND(V6*(AB6/V6)^0.3,0) -> 424979 | Y6: =ROUND(U6*(AA6/U6)^0.6,0) -> 30533 | Z6: =ROUND(V6*(AB6/V6)^0.6,0) -> 465849 | AA6: =ROUND(E6/25*AC6+AC6*F6,0) -> 35110 | AB6: =ROUND(D6*30*AC6,0) -> 526522 | AC6: 0.96
A7: 55 | B7: =ROUND([1]战斗力成长!$K14,0) -> 16368 | C7: =ROUND([1]战斗力成长!$Y14,0) -> 488684 | D7: =ROUND([1]战斗力成长!$AY14,0) -> 23919 | E7: =ROUND([1]战斗力成长!$AZ14,0) -> 1208980 | F7: =ROUND([1]战斗力成长!$AR14*0.4+[1]战斗力成长!$AS14,0) -> 9039 | G7: 20 | H7: =ROUND(((F7+C7/G7)/2)*0.8,0) -> 13389 | I7: =ROUND(G7*0.8*B7,0) -> 261888 | J7: =I7/D7 -> 10.948953 | K7: =ROUND(H7*(O7/H7)^0.3,0) -> 16449 | L7: =ROUND(I7*(P7/I7)^0.3,0) -> 297057 | M7: =ROUND(H7*(O7/H7)^0.6,0) -> 20209 | N7: =ROUND(I7*(P7/I7)^0.6,0) -> 336949 | O7: =ROUND(H7*0.7+AA7*0.3,0) -> 26592 | P7: =ROUND(I7*0.7+AB7*0.3,0) -> 398593 | Q7: =ROUND(O7*(U7/O7)^0.3,0) -> 30010 | R7: =ROUND(P7*(V7/P7)^0.3,0) -> 435461 | S7: =ROUND(O7*(U7/O7)^0.6,0) -> 33868 | T7: =ROUND(P7*(V7/P7)^0.6,0) -> 475739 | U7: =ROUND(H7*0.4+0.6*AA7,0) -> 39794 | V7: =ROUND(I7*0.4+0.6*AB7,0) -> 535297 | W7: =ROUND(U7*(AA7/U7)^0.3,0) -> 44416 | X7: =ROUND(V7*(AB7/V7)^0.3,0) -> 584488 | Y7: =ROUND(U7*(AA7/U7)^0.6,0) -> 49575 | Z7: =ROUND(V7*(AB7/V7)^0.6,0) -> 638200 | AA7: =ROUND(E7/25*AC7+AC7*F7,0) -> 57398 | AB7: =ROUND(D7*30*AC7,0) -> 717570 | AC7: 1
A8: 60 | B8: =ROUND([1]战斗力成长!$K15,0) -> 23358 | C8: =ROUND([1]战斗力成长!$Y15,0) -> 702413 | D8: =ROUND([1]战斗力成长!$AY15,0) -> 32701 | E8: =ROUND([1]战斗力成长!$AZ15,0) -> 1768861 | F8: =ROUND([1]战斗力成长!$AR15*0.4+[1]战斗力成长!$AS15,0) -> 15357 | G8: 21 | H8: =ROUND(((F8+C8/G8)/2)*0.8,0) -> 19522 | I8: =ROUND(G8*0.8*B8,0) -> 392414 | J8: =I8/D8 -> 12.000061 | K8: =ROUND(H8*(O8/H8)^0.3,0) -> 24306 | L8: =ROUND(I8*(P8/I8)^0.3,0) -> 441390 | M8: =ROUND(H8*(O8/H8)^0.6,0) -> 30261 | N8: =ROUND(I8*(P8/I8)^0.6,0) -> 496479 | O8: =ROUND(H8*0.7+AA8*0.3,0) -> 40532 | P8: =ROUND(I8*0.7+AB8*0.3,0) -> 580771 | Q8: =ROUND(O8*(U8/O8)^0.3,0) -> 45942 | R8: =ROUND(P8*(V8/P8)^0.3,0) -> 631834 | S8: =ROUND(O8*(U8/O8)^0.6,0) -> 52074 | T8: =ROUND(P8*(V8/P8)^0.6,0) -> 687387 | U8: =ROUND(H8*0.4+0.6*AA8,0) -> 61542 | V8: =ROUND(I8*0.4+0.6*AB8,0) -> 769128 | W8: =ROUND(U8*(AA8/U8)^0.3,0) -> 68873 | X8: =ROUND(V8*(AB8/V8)^0.3,0) -> 837170 | Y8: =ROUND(U8*(AA8/U8)^0.6,0) -> 77077 | Z8: =ROUND(V8*(AB8/V8)^0.6,0) -> 911232 | AA8: =ROUND(E8/25*AC8+AC8*F8,0) -> 89556 | AB8: =ROUND(D8*30*AC8,0) -> 1020271 | AC8: 1.04
A9: 65 | B9: =ROUND([1]战斗力成长!$K16,0) -> 32880 | C9: =ROUND([1]战斗力成长!$Y16,0) -> 1099604 | D9: =ROUND([1]战斗力成长!$AY16,0) -> 43746 | E9: =ROUND([1]战斗力成长!$AZ16,0) -> 2664578 | F9: =ROUND([1]战斗力成长!$AR16*0.4+[1]战斗力成长!$AS16,0) -> 27259 | G9: 22 | H9: =ROUND(((F9+C9/G9)/2)*0.8,0) -> 30896 | I9: =ROUND(G9*0.8*B9,0) -> 578688 | J9: =I9/D9 -> 13.228364 | K9: =ROUND(H9*(O9/H9)^0.3,0) -> 38618 | L9: =ROUND(I9*(P9/I9)^0.3,0) -> 644882 | M9: =ROUND(H9*(O9/H9)^0.6,0) -> 48270 | N9: =ROUND(I9*(P9/I9)^0.6,0) -> 718649 | O9: =ROUND(H9*0.7+AA9*0.3,0) -> 64992 | P9: =ROUND(I9*0.7+AB9*0.3,0) -> 830293 | Q9: =ROUND(O9*(U9/O9)^0.3,0) -> 73758 | R9: =ROUND(P9*(V9/P9)^0.3,0) -> 898913 | S9: =ROUND(O9*(U9/O9)^0.6,0) -> 83706 | T9: =ROUND(P9*(V9/P9)^0.6,0) -> 973204 | U9: =ROUND(H9*0.4+0.6*AA9,0) -> 99088 | V9: =ROUND(I9*0.4+0.6*AB9,0) -> 1081897 | W9: =ROUND(U9*(AA9/U9)^0.3,0) -> 110973 | X9: =ROUND(V9*(AB9/V9)^0.3,0) -> 1173208 | Y9: =ROUND(U9*(AA9/U9)^0.6,0) -> 124285 | Z9: =ROUND(V9*(AB9/V9)^0.6,0) -> 1272226 | AA9: =ROUND(E9/25*AC9+AC9*F9,0) -> 144549 | AB9: =ROUND(D9*30*AC9,0) -> 1417370 | AC9: 1.08
A10: 70 | B10: =ROUND([1]战斗力成长!$K17,0) -> 44971 | C10: =ROUND([1]战斗力成长!$Y17,0) -> 1601097 | D10: =ROUND([1]战斗力成长!$AY17,0) -> 58655 | E10: =ROUND([1]战斗力成长!$AZ17,0) -> 3902725 | F10: =ROUND([1]战斗力成长!$AR17*0.4+[1]战斗力成长!$AS17,0) -> 45032 | G10: 23 | H10: =ROUND(((F10+C10/G10)/2)*0.8,0) -> 45858 | I10: =ROUND(G10*0.8*B10,0) -> 827466 | J10: =I10/D10 -> 14.10734 | K10: =ROUND(H10*(O10/H10)^0.3,0) -> 57887 | L10: =ROUND(I10*(P10/I10)^0.3,0) -> 918191 | M10: =ROUND(H10*(O10/H10)^0.6,0) -> 73070 | N10: =ROUND(I10*(P10/I10)^0.6,0) -> 1018864 | O10: =ROUND(H10*0.7+AA10*0.3,0) -> 99684 | P10: =ROUND(I10*0.7+AB10*0.3,0) -> 1170469 | Q10: =ROUND(O10*(U10/O10)^0.3,0) -> 113469 | R10: =ROUND(P10*(V10/P10)^0.3,0) -> 1264283 | S10: =ROUND(O10*(U10/O10)^0.6,0) -> 129161 | T10: =ROUND(P10*(V10/P10)^0.6,0) -> 1365615 | U10: =ROUND(H10*0.4+0.6*AA10,0) -> 153510 | V10: =ROUND(I10*0.4+0.6*AB10,0) -> 1513471 | W10: =ROUND(U10*(AA10/U10)^0.3,0) -> 172231 | X10: =ROUND(V10*(AB10/V10)^0.3,0) -> 1638231 | Y10: =ROUND(U10*(AA10/U10)^0.6,0) -> 193235 | Z10: =ROUND(V10*(AB10/V10)^0.6,0) -> 1773276 | AA10: =ROUND(E10/25*AC10+AC10*F10,0) -> 225278 | AB10: =ROUND(D10*30*AC10,0) -> 1970808 | AC10: 1.12
A11: 75 | B11: =ROUND([1]战斗力成长!$K18,0) -> 58731 | C11: =ROUND([1]战斗力成长!$Y18,0) -> 2237989 | D11: =ROUND([1]战斗力成长!$AY18,0) -> 79146 | E11: =ROUND([1]战斗力成长!$AZ18,0) -> 5841454 | F11: =ROUND([1]战斗力成长!$AR18*0.4+[1]战斗力成长!$AS18,0) -> 70858 | G11: 24 | H11: =ROUND(((F11+C11/G11)/2)*0.8,0) -> 65643 | I11: =ROUND(G11*0.8*B11,0) -> 1127635 | J11: =I11/D11 -> 14.24753 | K11: =ROUND(H11*(O11/H11)^0.3,0) -> 84434 | L11: =ROUND(I11*(P11/I11)^0.3,0) -> 1256089 | M11: =ROUND(H11*(O11/H11)^0.6,0) -> 108604 | N11: =ROUND(I11*(P11/I11)^0.6,0) -> 1399176 | O11: =ROUND(H11*0.7+AA11*0.3,0) -> 151922 | P11: =ROUND(I11*0.7+AB11*0.3,0) -> 1615629 | Q11: =ROUND(O11*(U11/O11)^0.3,0) -> 173867 | R11: =ROUND(P11*(V11/P11)^0.3,0) -> 1748757 | S11: =ROUND(O11*(U11/O11)^0.6,0) -> 198982 | T11: =ROUND(P11*(V11/P11)^0.6,0) -> 1892855 | U11: =ROUND(H11*0.4+0.6*AA11,0) -> 238201 | V11: =ROUND(I11*0.4+0.6*AB11,0) -> 2103623 | W11: =ROUND(U11*(AA11/U11)^0.3,0) -> 268090 | X11: =ROUND(V11*(AB11/V11)^0.3,0) -> 2280762 | Y11: =ROUND(U11*(AA11/U11)^0.6,0) -> 301730 | Z11: =ROUND(V11*(AB11/V11)^0.6,0) -> 2472818 | AA11: =ROUND(E11/25*AC11+AC11*F11,0) -> 353239 | AB11: =ROUND(D11*30*AC11,0) -> 2754281 | AC11: 1.16
A12: 80 | B12: =ROUND([1]战斗力成长!$K19,0) -> 74947 | C12: =ROUND([1]战斗力成长!$Y19,0) -> 2912893 | D12: =ROUND([1]战斗力成长!$AY19,0) -> 103680 | E12: =ROUND([1]战斗力成长!$AZ19,0) -> 8069696 | F12: =ROUND([1]战斗力成长!$AR19*0.4+[1]战斗力成长!$AS19,0) -> 104029 | G12: 25 | H12: =ROUND(((F12+C12/G12)/2)*0.8,0) -> 88218 | I12: =ROUND(G12*0.8*B12,0) -> 1498940 | J12: =I12/D12 -> 14.457369 | K12: =ROUND(H12*(O12/H12)^0.3,0) -> 115310 | L12: =ROUND(I12*(P12/I12)^0.3,0) -> 1674661 | M12: =ROUND(H12*(O12/H12)^0.6,0) -> 150723 | N12: =ROUND(I12*(P12/I12)^0.6,0) -> 1870982 | O12: =ROUND(H12*0.7+AA12*0.3,0) -> 215407 | P12: =ROUND(I12*0.7+AB12*0.3,0) -> 2169002 | Q12: =ROUND(O12*(U12/O12)^0.3,0) -> 247580 | R12: =ROUND(P12*(V12/P12)^0.3,0) -> 2351443 | S12: =ROUND(O12*(U12/O12)^0.6,0) -> 284559 | T12: =ROUND(P12*(V12/P12)^0.6,0) -> 2549230 | U12: =ROUND(H12*0.4+0.6*AA12,0) -> 342595 | V12: =ROUND(I12*0.4+0.6*AB12,0) -> 2839064 | W12: =ROUND(U12*(AA12/U12)^0.3,0) -> 386521 | X12: =ROUND(V12*(AB12/V12)^0.3,0) -> 3081924 | Y12: =ROUND(U12*(AA12/U12)^0.6,0) -> 436080 | Z12: =ROUND(V12*(AB12/V12)^0.6,0) -> 3345558 | AA12: =ROUND(E12/25*AC12+AC12*F12,0) -> 512180 | AB12: =ROUND(D12*30*AC12,0) -> 3732480 | AC12: 1.2
A13: 85 | B13: =ROUND([1]战斗力成长!$K20,0) -> 94496 | C13: =ROUND([1]战斗力成长!$Y20,0) -> 3760132 | D13: =ROUND([1]战斗力成长!$AY20,0) -> 132555 | E13: =ROUND([1]战斗力成长!$AZ20,0) -> 10788762 | F13: =ROUND([1]战斗力成长!$AR20+[1]战斗力成长!$AS20,0) -> 240066 | G13: 26 | H13: =ROUND(((F13+C13/G13)/2)*0.8,0) -> 153875 | I13: =ROUND(G13*0.8*B13,0) -> 1965517 | J13: =I13/D13 -> 14.827936 | K13: =ROUND(H13*(O13/H13)^0.3,0) -> 198162 | L13: =ROUND(I13*(P13/I13)^0.3,0) -> 2198486 | M13: =ROUND(H13*(O13/H13)^0.6,0) -> 255195 | N13: =ROUND(I13*(P13/I13)^0.6,0) -> 2459068 | O13: =ROUND(H13*0.7+AA13*0.3,0) -> 357554 | P13: =ROUND(I13*0.7+AB13*0.3,0) -> 2855176 | Q13: =ROUND(O13*(U13/O13)^0.3,0) -> 409338 | R13: =ROUND(P13*(V13/P13)^0.3,0) -> 3097225 | S13: =ROUND(O13*(U13/O13)^0.6,0) -> 468621 | T13: =ROUND(P13*(V13/P13)^0.6,0) -> 3359794 | U13: =ROUND(H13*0.4+0.6*AA13,0) -> 561232 | V13: =ROUND(I13*0.4+0.6*AB13,0) -> 3744834 | W13: =ROUND(U13*(AA13/U13)^0.3,0) -> 631775 | X13: =ROUND(V13*(AB13/V13)^0.3,0) -> 4067097 | Y13: =ROUND(U13*(AA13/U13)^0.6,0) -> 711185 | Z13: =ROUND(V13*(AB13/V13)^0.6,0) -> 4417092 | AA13: =ROUND(E13/25*AC13+AC13*F13,0) -> 832804 | AB13: =ROUND(D13*30*AC13,0) -> 4931046 | AC13: 1.24
A14: 90 | B14: =ROUND([1]战斗力成长!$K21,0) -> 117856 | C14: =ROUND([1]战斗力成长!$Y21,0) -> 4661213 | D14: =ROUND([1]战斗力成长!$AY21,0) -> 167380 | E14: =ROUND([1]战斗力成长!$AZ21,0) -> 13802380 | F14: =ROUND([1]战斗力成长!$AR21+[1]战斗力成长!$AS21,0) -> 316792 | G14: 27 | H14: =ROUND(((F14+C14/G14)/2)*0.8,0) -> 195772 | I14: =ROUND(G14*0.8*B14,0) -> 2545690 | J14: =I14/D14 -> 15.209045 | K14: =ROUND(H14*(O14/H14)^0.3,0) -> 254710 | L14: =ROUND(I14*(P14/I14)^0.3,0) -> 2850251 | M14: =ROUND(H14*(O14/H14)^0.6,0) -> 331393 | N14: =ROUND(I14*(P14/I14)^0.6,0) -> 3191249 | O14: =ROUND(H14*0.7+AA14*0.3,0) -> 470693 | P14: =ROUND(I14*0.7+AB14*0.3,0) -> 3710201 | Q14: =ROUND(O14*(U14/O14)^0.3,0) -> 540344 | R14: =ROUND(P14*(V14/P14)^0.3,0) -> 4026826 | S14: =ROUND(O14*(U14/O14)^0.6,0) -> 620302 | T14: =ROUND(P14*(V14/P14)^0.6,0) -> 4370472 | U14: =ROUND(H14*0.4+0.6*AA14,0) -> 745614 | V14: =ROUND(I14*0.4+0.6*AB14,0) -> 4874711 | W14: =ROUND(U14*(AA14/U14)^0.3,0) -> 840644 | X14: =ROUND(V14*(AB14/V14)^0.3,0) -> 5296325 | Y14: =ROUND(U14*(AA14/U14)^0.6,0) -> 947785 | Z14: =ROUND(V14*(AB14/V14)^0.6,0) -> 5754405 | AA14: =ROUND(E14/25*AC14+AC14*F14,0) -> 1112176 | AB14: =ROUND(D14*30*AC14,0) -> 6427392 | AC14: 1.28
A15: 95 | B15: =ROUND([1]战斗力成长!$K22,0) -> 145549 | C15: =ROUND([1]战斗力成长!$Y22,0) -> 5769011 | D15: =ROUND([1]战斗力成长!$AY22,0) -> 206858 | E15: =ROUND([1]战斗力成长!$AZ22,0) -> 17315841 | F15: =ROUND([1]战斗力成长!$AR22+[1]战斗力成长!$AS22,0) -> 423674 | G15: 28 | H15: =ROUND(((F15+C15/G15)/2)*0.8,0) -> 251884 | I15: =ROUND(G15*0.8*B15,0) -> 3260298 | J15: =I15/D15 -> 15.761044 | K15: =ROUND(H15*(O15/H15)^0.3,0) -> 329774 | L15: =ROUND(I15*(P15/I15)^0.3,0) -> 3647580 | M15: =ROUND(H15*(O15/H15)^0.6,0) -> 431750 | N15: =ROUND(I15*(P15/I15)^0.6,0) -> 4080867 | O15: =ROUND(H15*0.7+AA15*0.3,0) -> 618377 | P15: =ROUND(I15*0.7+AB15*0.3,0) -> 4739682 | Q15: =ROUND(O15*(U15/O15)^0.3,0) -> 711035 | R15: =ROUND(P15*(V15/P15)^0.3,0) -> 5142117 | S15: =ROUND(O15*(U15/O15)^0.6,0) -> 817577 | T15: =ROUND(P15*(V15/P15)^0.6,0) -> 5578722 | U15: =ROUND(H15*0.4+0.6*AA15,0) -> 984869 | V15: =ROUND(I15*0.4+0.6*AB15,0) -> 6219065 | W15: =ROUND(U15*(AA15/U15)^0.3,0) -> 1111405 | X15: =ROUND(V15*(AB15/V15)^0.3,0) -> 6754883 | Y15: =ROUND(U15*(AA15/U15)^0.6,0) -> 1254198 | Z15: =ROUND(V15*(AB15/V15)^0.6,0) -> 7336865 | AA15: =ROUND(E15/25*AC15+AC15*F15,0) -> 1473526 | AB15: =ROUND(D15*30*AC15,0) -> 8191577 | AC15: 1.32
A16: 100 | B16: =ROUND([1]战斗力成长!$K23,0) -> 178142 | C16: =ROUND([1]战斗力成长!$Y23,0) -> 7169649 | D16: =ROUND([1]战斗力成长!$AY23,0) -> 256188 | E16: =ROUND([1]战斗力成长!$AZ23,0) -> 22528951 | F16: =ROUND([1]战斗力成长!$AR23+[1]战斗力成长!$AS23,0) -> 574835 | G16: 29 | H16: =ROUND(((F16+C16/G16)/2)*0.8,0) -> 328826 | I16: =ROUND(G16*0.8*B16,0) -> 4132894 | J16: =I16/D16 -> 16.13227 | K16: =ROUND(H16*(O16/H16)^0.3,0) -> 434484 | L16: =ROUND(I16*(P16/I16)^0.3,0) -> 4628567 | M16: =ROUND(H16*(O16/H16)^0.6,0) -> 574091 | N16: =ROUND(I16*(P16/I16)^0.6,0) -> 5183687 | O16: =ROUND(H16*0.7+AA16*0.3,0) -> 832384 | P16: =ROUND(I16*0.7+AB16*0.3,0) -> 6028767 | Q16: =ROUND(O16*(U16/O16)^0.3,0) -> 959318 | R16: =ROUND(P16*(V16/P16)^0.3,0) -> 6544159 | S16: =ROUND(O16*(U16/O16)^0.6,0) -> 1105610 | T16: =ROUND(P16*(V16/P16)^0.6,0) -> 7103610 | U16: =ROUND(H16*0.4+0.6*AA16,0) -> 1335941 | V16: =ROUND(I16*0.4+0.6*AB16,0) -> 7924640 | W16: =ROUND(U16*(AA16/U16)^0.3,0) -> 1509517 | X16: =ROUND(V16*(AB16/V16)^0.3,0) -> 8610956 | Y16: =ROUND(U16*(AA16/U16)^0.6,0) -> 1705646 | Z16: =ROUND(V16*(AB16/V16)^0.6,0) -> 9356710 | AA16: =ROUND(E16/25*AC16+AC16*F16,0) -> 2007351 | AB16: =ROUND(D16*30*AC16,0) -> 10452470 | AC16: 1.36
T21: =AA2/H2 -> 1.7044888 | U21: =AB2/I2 -> 4.4244671 | V21: =U21*T21 -> 7.5414545
T22: =AA3/H3 -> 2.2292627 | U22: =AB3/I3 -> 3.8787957 | V22: =U22*T22 -> 8.6468545
T23: =AA4/H4 -> 2.6964597 | U23: =AB4/I4 -> 3.39019 | V23: =U23*T23 -> 9.1415106
T24: =AA5/H5 -> 3.3208649 | U24: =AB5/I5 -> 3.222208 | V24: =U24*T24 -> 10.700517
T25: =AA6/H6 -> 3.8001948 | U25: =AB6/I6 -> 2.9340384 | V25: =U25*T25 -> 11.149918
T26: =AA7/H7 -> 4.286952 | U26: =AB7/I7 -> 2.7399881 | V26: =U26*T26 -> 11.746197
T27: =AA8/H8 -> 4.5874398 | U27: =AB8/I8 -> 2.5999862 | V27: =U27*T27 -> 11.92728
T28: =AA9/H9 -> 4.6785668 | U28: =AB9/I9 -> 2.4492818 | V28: =U28*T28 -> 11.459129
T29: =AA10/H10 -> 4.9125125 | U29: =AB10/I10 -> 2.3817389 | V29: =U29*T29 -> 11.700322
T30: =AA11/H11 -> 5.3812135 | U30: =AB11/I11 -> 2.4425288 | V30: =U30*T30 -> 13.143769
T31: =AA12/H12 -> 5.8058446 | U31: =AB12/I12 -> 2.4900797 | V31: =U31*T31 -> 14.457016
T32: =AA13/H13 -> 5.4122112 | U32: =AB13/I13 -> 2.5087781 | V32: =U32*T32 -> 13.578037
... T35: =AA16/H16 -> 6.1045994 | U35: =AB16/I16 -> 2.5290922 | V35: =U35*T35 -> 15.439095
A49: 等级 | B49: 无佣兵玩家DPS | C49: 无佣兵玩家EHP | D49: 玩家DPS | E49: 玩家EHP | F49: 玩家HPS | G49: 回合数 | H49: 普通DPS | I49: 普通EHP | K49: minor1 | L49: minor1 | M49: minor2 | N49: minor2 | O49: BOSS3 | P49: BOSS3 | Q49: minor3 | R49: minor3 | S49: minor4 | T49: minor4 | U49: BOSS6 | V49: BOSS6 | W49: minor5 | X49: minor5 | Y49: minor6 | Z49: minor6 | AA49: BOSSDPS | AB49: BOSSEHP | AC49: 难度系数
A50: 30 | B50: =ROUND([1]战斗力成长!$K57,0) -> 6832 | C50: =ROUND([1]战斗力成长!$Y57,0) -> 38123 | D50: =ROUND([1]战斗力成长!$AY57,0) -> 9036 | E50: =ROUND([1]战斗力成长!$Y57,0) -> 38123 | F50: =ROUND([1]战斗力成长!$AR57*0.4*0.8+[1]战斗力成长!$AS57,0) -> 471 | G50: 10 | H50: =ROUND(((F50+C50/G50)/2)*MIN(AC50,1),0) -> 1713 | I50: =ROUND(G50*MIN(AC50,1)*B50,0) -> 54656 | K50: =ROUND(H50*(O50/H50)^0.3,0) -> 1702 | L50: =ROUND(I50*(P50/I50)^0.3,0) -> 66161 | M50: =ROUND(H50*(O50/H50)^0.6,0) -> 1692 | N50: =ROUND(I50*(P50/I50)^0.6,0) -> 80087 | O50: =ROUND(H50*0.7+AA50*0.3,0) -> 1678 | P50: =ROUND(I50*0.7+AB50*0.3,0) -> 103318 | Q50: =ROUND(O50*(U50/O50)^0.3,0) -> 1667 | R50: =ROUND(P50*(V50/P50)^0.3,0) -> 116001 | S50: =ROUND(O50*(U50/O50)^0.6,0) -> 1657 | T50: =ROUND(P50*(V50/P50)^0.6,0) -> 130240 | U50: =ROUND(H50*0.4+0.6*AA50,0) -> 1643 | V50: =ROUND(I50*0.4+0.6*AB50,0) -> 151981 | W50: =ROUND(U50*(AA50/U50)^0.3,0) -> 1629 | X50: =ROUND(V50*(AB50/V50)^0.3,0) -> 169086 | Y50: =ROUND(U50*(AA50/U50)^0.6,0) -> 1615 | Z50: =ROUND(V50*(AB50/V50)^0.6,0) -> 188117 | AA50: =ROUND(E50/25*AC50+AC50*F50,0) -> 1597 | AB50: =ROUND(D50*30*AC50,0) -> 216864 | AC50: 0.8
A51: 35 | B51: =ROUND([1]战斗力成长!$K58,0) -> 10006 | C51: =ROUND([1]战斗力成长!$Y58,0) -> 60953 | D51: =ROUND([1]战斗力成长!$AY58,0) -> 13463 | E51: =ROUND([1]战斗力成长!$Y58,0) -> 60953 | F51: =ROUND([1]战斗力成长!$AR58*0.4*0.8+[1]战斗力成长!$AS58,0) -> 748 | G51: 12 | H51: =ROUND(((F51+C51/G51)/2)*MIN(AC51,1),0) -> 2448 | I51: =ROUND(G51*MIN(AC51,1)*B51,0) -> 100860 | K51: =ROUND(H51*(O51/H51)^0.3,0) -> 2468 | L51: =ROUND(I51*(P51/I51)^0.3,0) -> 118454 | M51: =ROUND(H51*(O51/H51)^0.6,0) -> 2489 | N51: =ROUND(I51*(P51/I51)^0.6,0) -> 139118 | O51: =ROUND(H51*0.7+AA51*0.3,0) -> 2516 | P51: =ROUND(I51*0.7+AB51*0.3,0) -> 172382 | Q51: =ROUND(O51*(U51/O51)^0.3,0) -> 2537 | R51: =ROUND(P51*(V51/P51)^0.3,0) -> 191298 | S51: =ROUND(O51*(U51/O51)^0.6,0) -> 2557 | T51: =ROUND(P51*(V51/P51)^0.6,0) -> 212290 | U51: =ROUND(H51*0.4+0.6*AA51,0) -> 2585 | V51: =ROUND(I51*0.4+0.6*AB51,0) -> 243905 | W51: =ROUND(U51*(AA51/U51)^0.3,0) -> 2612 | X51: =ROUND(V51*(AB51/V51)^0.3,0) -> 269288 | Y51: =ROUND(U51*(AA51/U51)^0.6,0) -> 2639 | Z51: =ROUND(V51*(AB51/V51)^0.6,0) -> 297313 | AA51: =ROUND(E51/25*AC51+AC51*F51,0) -> 2676 | AB51: =ROUND(D51*30*AC51,0) -> 339268 | AC51: 0.84
A52: 40 | B52: =ROUND([1]战斗力成长!$K59,0) -> 14779 | C52: =ROUND([1]战斗力成长!$Y59,0) -> 95813 | D52: =ROUND([1]战斗力成长!$AY59,0) -> 19471 | E52: =ROUND([1]战斗力成长!$Y59,0) -> 95813 | F52: =ROUND([1]战斗力成长!$AR59*0.4*0.8+[1]战斗力成长!$AS59,0) -> 1593 | G52: 14 | H52: =ROUND(((F52+C52/G52)/2)*MIN(AC52,1),0) -> 3712 | I52: =ROUND(G52*MIN(AC52,1)*B52,0) -> 182077 | K52: =ROUND(H52*(O52/H52)^0.3,0) -> 3805 | L52: =ROUND(I52*(P52/I52)^0.3,0) -> 207538 | M52: =ROUND(H52*(O52/H52)^0.6,0) -> 3900 | N52: =ROUND(I52*(P52/I52)^0.6,0) -> 236560 | O52: =ROUND(H52*0.7+AA52*0.3,0) -> 4031 | P52: =ROUND(I52*0.7+AB52*0.3,0) -> 281664 | Q52: =ROUND(O52*(U52/O52)^0.3,0) -> 4124 | R52: =ROUND(P52*(V52/P52)^0.3,0) -> 308443 | S52: =ROUND(O52*(U52/O52)^0.6,0) -> 4219 | T52: =ROUND(P52*(V52/P52)^0.6,0) -> 337768 | U52: =ROUND(H52*0.4+0.6*AA52,0) -> 4349 | V52: =ROUND(I52*0.4+0.6*AB52,0) -> 381251 | W52: =ROUND(U52*(AA52/U52)^0.3,0) -> 4472 | X52: =ROUND(V52*(AB52/V52)^0.3,0) -> 417009 | Y52: =ROUND(U52*(AA52/U52)^0.6,0) -> 4599 | Z52: =ROUND(V52*(AB52/V52)^0.6,0) -> 456120 | AA52: =ROUND(E52/25*AC52+AC52*F52,0) -> 4774 | AB52: =ROUND(D52*30*AC52,0) -> 514034 | AC52: 0.88
A53: 45 | B53: =ROUND([1]战斗力成长!$K60,0) -> 18760 | C53: =ROUND([1]战斗力成长!$Y60,0) -> 120685 | D53: =ROUND([1]战斗力成长!$AY60,0) -> 25461 | E53: =ROUND([1]战斗力成长!$Y60,0) -> 120685 | F53: =ROUND([1]战斗力成长!$AR60*0.4*0.8+[1]战斗力成长!$AS60,0) -> 1978 | G53: 16 | H53: =ROUND(((F53+C53/G53)/2)*MIN(AC53,1),0) -> 4380 | I53: =ROUND(G53*MIN(AC53,1)*B53,0) -> 276147 | K53: =ROUND(H53*(O53/H53)^0.3,0) -> 4542 | L53: =ROUND(I53*(P53/I53)^0.3,0) -> 309565 | M53: =ROUND(H53*(O53/H53)^0.6,0) -> 4710 | N53: =ROUND(I53*(P53/I53)^0.6,0) -> 347026 | O53: =ROUND(H53*0.7+AA53*0.3,0) -> 4944 | P53: =ROUND(I53*0.7+AB53*0.3,0) -> 404120 | Q53: =ROUND(O53*(U53/O53)^0.3,0) -> 5107 | R53: =ROUND(P53*(V53/P53)^0.3,0) -> 438888 | S53: =ROUND(O53*(U53/O53)^0.6,0) -> 5276 | T53: =ROUND(P53*(V53/P53)^0.6,0) -> 476647 | U53: =ROUND(H53*0.4+0.6*AA53,0) -> 5509 | V53: =ROUND(I53*0.4+0.6*AB53,0) -> 532093 | W53: =ROUND(U53*(AA53/U53)^0.3,0) -> 5725 | X53: =ROUND(V53*(AB53/V53)^0.3,0) -> 578398 | Y53: =ROUND(U53*(AA53/U53)^0.6,0) -> 5949 | Z53: =ROUND(V53*(AB53/V53)^0.6,0) -> 628732 | AA53: =ROUND(E53/25*AC53+AC53*F53,0) -> 6261 | AB53: =ROUND(D53*30*AC53,0) -> 702724 | AC53: 0.92
A54: 50 | B54: =ROUND([1]战斗力成长!$K61,0) -> 26032 | C54: =ROUND([1]战斗力成长!$Y61,0) -> 188492 | D54: =ROUND([1]战斗力成长!$AY61,0) -> 35213 | E54: =ROUND([1]战斗力成长!$Y61,0) -> 188492 | F54: =ROUND([1]战斗力成长!$AR61*0.4*0.8+[1]战斗力成长!$AS61,0) -> 3356 | G54: 18 | H54: =ROUND(((F54+C54/G54)/2)*MIN(AC54,1),0) -> 6637 | I54: =ROUND(G54*MIN(AC54,1)*B54,0) -> 449833 | K54: =ROUND(H54*(O54/H54)^0.3,0) -> 6962 | L54: =ROUND(I54*(P54/I54)^0.3,0) -> 495073 | M54: =ROUND(H54*(O54/H54)^0.6,0) -> 7303 | N54: =ROUND(I54*(P54/I54)^0.6,0) -> 544862 | O54: =ROUND(H54*0.7+AA54*0.3,0) -> 7784 | P54: =ROUND(I54*0.7+AB54*0.3,0) -> 619123 | Q54: =ROUND(O54*(U54/O54)^0.3,0) -> 8112 | R54: =ROUND(P54*(V54/P54)^0.3,0) -> 665687 | S54: =ROUND(O54*(U54/O54)^0.6,0) -> 8453 | T54: =ROUND(P54*(V54/P54)^0.6,0) -> 715753 | U54: =ROUND(H54*0.4+0.6*AA54,0) -> 8931 | V54: =ROUND(I54*0.4+0.6*AB54,0) -> 788414 | W54: =ROUND(U54*(AA54/U54)^0.3,0) -> 9365 | X54: =ROUND(V54*(AB54/V54)^0.3,0) -> 850270 | Y54: =ROUND(U54*(AA54/U54)^0.6,0) -> 9819 | Z54: =ROUND(V54*(AB54/V54)^0.6,0) -> 916978 | AA54: =ROUND(E54/25*AC54+AC54*F54,0) -> 10460 | AB54: =ROUND(D54*30*AC54,0) -> 1014134 | AC54: 0.96
A55: 55 | B55: =ROUND([1]战斗力成长!$K62,0) -> 34440 | C55: =ROUND([1]战斗力成长!$Y62,0) -> 276440 | D55: =ROUND([1]战斗力成长!$AY62,0) -> 47043 | E55: =ROUND([1]战斗力成长!$Y62,0) -> 276440 | F55: =ROUND([1]战斗力成长!$AR62*0.4*0.8+[1]战斗力成长!$AS62,0) -> 5490 | G55: 20 | H55: =ROUND(((F55+C55/G55)/2)*MIN(AC55,1),0) -> 9656 | I55: =ROUND(G55*MIN(AC55,1)*B55,0) -> 688800 | K55: =ROUND(H55*(O55/H55)^0.3,0) -> 10235 | L55: =ROUND(I55*(P55/I55)^0.3,0) -> 747719 | M55: =ROUND(H55*(O55/H55)^0.6,0) -> 10848 | N55: =ROUND(I55*(P55/I55)^0.6,0) -> 811678 | O55: =ROUND(H55*0.7+AA55*0.3,0) -> 11724 | P55: =ROUND(I55*0.7+AB55*0.3,0) -> 905547 | Q55: =ROUND(O55*(U55/O55)^0.3,0) -> 12309 | R55: =ROUND(P55*(V55/P55)^0.3,0) -> 965761 | S55: =ROUND(O55*(U55/O55)^0.6,0) -> 12924 | T55: =ROUND(P55*(V55/P55)^0.6,0) -> 1029979 | U55: =ROUND(H55*0.4+0.6*AA55,0) -> 13791 | V55: =ROUND(I55*0.4+0.6*AB55,0) -> 1122294 | W55: =ROUND(U55*(AA55/U55)^0.3,0) -> 14566 | X55: =ROUND(V55*(AB55/V55)^0.3,0) -> 1202152 | Y55: =ROUND(U55*(AA55/U55)^0.6,0) -> 15385 | Z55: =ROUND(V55*(AB55/V55)^0.6,0) -> 1287693 | AA55: =ROUND(E55/25*AC55+AC55*F55,0) -> 16548 | AB55: =ROUND(D55*30*AC55,0) -> 1411290 | AC55: 1
A56: 60 | B56: =ROUND([1]战斗力成长!$K63,0) -> 50285 | C56: =ROUND([1]战斗力成长!$Y63,0) -> 388497 | D56: =ROUND([1]战斗力成长!$AY63,0) -> 66461 | E56: =ROUND([1]战斗力成长!$Y63,0) -> 388497 | F56: =ROUND([1]战斗力成长!$AR63*0.4*0.8+[1]战斗力成长!$AS63,0) -> 9223 | G56: 21 | H56: =ROUND(((F56+C56/G56)/2)*MIN(AC56,1),0) -> 13861 | I56: =ROUND(G56*MIN(AC56,1)*B56,0) -> 1055985 | K56: =ROUND(H56*(O56/H56)^0.3,0) -> 14847 | L56: =ROUND(I56*(P56/I56)^0.3,0) -> 1139576 | M56: =ROUND(H56*(O56/H56)^0.6,0) -> 15903 | N56: =ROUND(I56*(P56/I56)^0.6,0) -> 1229783 | O56: =ROUND(H56*0.7+AA56*0.3,0) -> 17429 | P56: =ROUND(I56*0.7+AB56*0.3,0) -> 1361264 | Q56: =ROUND(O56*(U56/O56)^0.3,0) -> 18430 | R56: =ROUND(P56*(V56/P56)^0.3,0) -> 1446454 | S56: =ROUND(O56*(U56/O56)^0.6,0) -> 19489 | T56: =ROUND(P56*(V56/P56)^0.6,0) -> 1536976 | U56: =ROUND(H56*0.4+0.6*AA56,0) -> 20996 | V56: =ROUND(I56*0.4+0.6*AB56,0) -> 1666544 | W56: =ROUND(U56*(AA56/U56)^0.3,0) -> 22323 | X56: =ROUND(V56*(AB56/V56)^0.3,0) -> 1779460 | Y56: =ROUND(U56*(AA56/U56)^0.6,0) -> 23733 | Z56: =ROUND(V56*(AB56/V56)^0.6,0) -> 1900026 | AA56: =ROUND(E56/25*AC56+AC56*F56,0) -> 25753 | AB56: =ROUND(D56*30*AC56,0) -> 2073583 | AC56: 1.04
A57: 65 | B57: =ROUND([1]战斗力成长!$K64,0) -> 71466 | C57: =ROUND([1]战斗力成长!$Y64,0) -> 603334 | D57: =ROUND([1]战斗力成长!$AY64,0) -> 90690 | E57: =ROUND([1]战斗力成长!$Y64,0) -> 603334 | F57: =ROUND([1]战斗力成长!$AR64*0.4*0.8+[1]战斗力成长!$AS64,0) -> 16304 | G57: 22 | H57: =ROUND(((F57+C57/G57)/2)*MIN(AC57,1),0) -> 21864 | I57: =ROUND(G57*MIN(AC57,1)*B57,0) -> 1572252 | K57: =ROUND(H57*(O57/H57)^0.3,0) -> 23650 | L57: =ROUND(I57*(P57/I57)^0.3,0) -> 1685396 | M57: =ROUND(H57*(O57/H57)^0.6,0) -> 25582 | N57: =ROUND(I57*(P57/I57)^0.6,0) -> 1806683 | O57: =ROUND(H57*0.7+AA57*0.3,0) -> 28406 | P57: =ROUND(I57*0.7+AB57*0.3,0) -> 1982083 | Q57: =ROUND(O57*(U57/O57)^0.3,0) -> 30229 | R57: =ROUND(P57*(V57/P57)^0.3,0) -> 2097051 | S57: =ROUND(O57*(U57/O57)^0.6,0) -> 32168 | T57: =ROUND(P57*(V57/P57)^0.6,0) -> 2218687 | U57: =ROUND(H57*0.4+0.6*AA57,0) -> 34949 | V57: =ROUND(I57*0.4+0.6*AB57,0) -> 2391914 | W57: =ROUND(U57*(AA57/U57)^0.3,0) -> 37365 | X57: =ROUND(V57*(AB57/V57)^0.3,0) -> 2544212 | Y57: =ROUND(U57*(AA57/U57)^0.6,0) -> 39948 | Z57: =ROUND(V57*(AB57/V57)^0.6,0) -> 2706206 | AA57: =ROUND(E57/25*AC57+AC57*F57,0) -> 43672 | AB57: =ROUND(D57*30*AC57,0) -> 2938356 | AC57: 1.08
A58: 70 | B58: =ROUND([1]战斗力成长!$K65,0) -> 96511 | C58: =ROUND([1]战斗力成长!$Y65,0) -> 852863 | D58: =ROUND([1]战斗力成长!$AY65,0) -> 121334 | E58: =ROUND([1]战斗力成长!$Y65,0) -> 852863 | F58: =ROUND([1]战斗力成长!$AR65*0.4*0.8+[1]战斗力成长!$AS65,0) -> 26074 | G58: 23 | H58: =ROUND(((F58+C58/G58)/2)*MIN(AC58,1),0) -> 31578 | I58: =ROUND(G58*MIN(AC58,1)*B58,0) -> 2219753 | K58: =ROUND(H58*(O58/H58)^0.3,0) -> 34479 | L58: =ROUND(I58*(P58/I58)^0.3,0) -> 2373997 | M58: =ROUND(H58*(O58/H58)^0.6,0) -> 37647 | N58: =ROUND(I58*(P58/I58)^0.6,0) -> 2538958 | O58: =ROUND(H58*0.7+AA58*0.3,0) -> 42328 | P58: =ROUND(I58*0.7+AB58*0.3,0) -> 2776874 | Q58: =ROUND(O58*(U58/O58)^0.3,0) -> 45302 | R58: =ROUND(P58*(V58/P58)^0.3,0) -> 2933451 | S58: =ROUND(O58*(U58/O58)^0.6,0) -> 48484 | T58: =ROUND(P58*(V58/P58)^0.6,0) -> 3098856 | U58: =ROUND(H58*0.4+0.6*AA58,0) -> 53078 | V58: =ROUND(I58*0.4+0.6*AB58,0) -> 3333994 | W58: =ROUND(U58*(AA58/U58)^0.3,0) -> 57024 | X58: =ROUND(V58*(AB58/V58)^0.3,0) -> 3541375 | Y58: =ROUND(U58*(AA58/U58)^0.6,0) -> 61264 | Z58: =ROUND(V58*(AB58/V58)^0.6,0) -> 3761655 | AA58: =ROUND(E58/25*AC58+AC58*F58,0) -> 67411 | AB58: =ROUND(D58*30*AC58,0) -> 4076822 | AC58: 1.12
A59: 75 | B59: =ROUND([1]战斗力成长!$K66,0) -> 124722 | C59: =ROUND([1]战斗力成长!$Y66,0) -> 1208670 | D59: =ROUND([1]战斗力成长!$AY66,0) -> 160969 | E59: =ROUND([1]战斗力成长!$Y66,0) -> 1208670 | F59: =ROUND([1]战斗力成长!$AR66*0.4*0.8+[1]战斗力成长!$AS66,0) -> 41495 | G59: 24 | H59: =ROUND(((F59+C59/G59)/2)*MIN(AC59,1),0) -> 45928 | I59: =ROUND(G59*MIN(AC59,1)*B59,0) -> 2993328 | K59: =ROUND(H59*(O59/H59)^0.3,0) -> 50595 | L59: =ROUND(I59*(P59/I59)^0.3,0) -> 3209315 | M59: =ROUND(H59*(O59/H59)^0.6,0) -> 55737 | N59: =ROUND(I59*(P59/I59)^0.6,0) -> 3440886 | O59: =ROUND(H59*0.7+AA59*0.3,0) -> 63414 | P59: =ROUND(I59*0.7+AB59*0.3,0) -> 3775846 | Q59: =ROUND(O59*(U59/O59)^0.3,0) -> 68221 | R59: =ROUND(P59*(V59/P59)^0.3,0) -> 3995330 | S59: =ROUND(O59*(U59/O59)^0.6,0) -> 73392 | T59: =ROUND(P59*(V59/P59)^0.6,0) -> 4227573 | U59: =ROUND(H59*0.4+0.6*AA59,0) -> 80901 | V59: =ROUND(I59*0.4+0.6*AB59,0) -> 4558364 | W59: =ROUND(U59*(AA59/U59)^0.3,0) -> 87287 | X59: =ROUND(V59*(AB59/V59)^0.3,0) -> 4849118 | Y59: =ROUND(U59*(AA59/U59)^0.6,0) -> 94176 | Z59: =ROUND(V59*(AB59/V59)^0.6,0) -> 5158417 | AA59: =ROUND(E59/25*AC59+AC59*F59,0) -> 104216 | AB59: =ROUND(D59*30*AC59,0) -> 5601721 | AC59: 1.16
...

Sheet 战士难度
A1: 1 | B1: =INDEX(Sheet1!$K$2:$AC$16,战士难度!F1,战士难度!D1) -> 2549 | C1: =INDEX(Sheet1!$K$2:$AC$16,战士难度!F1,战士难度!E1) -> 32012 | D1: =E1-1 -> 1 | E1: 2 | F1: 1 | H1: =B1*C1 -> 81598588
A2: =A1+1 -> 2 | B2: =INDEX(Sheet1!$K$2:$AC$16,战士难度!F2,战士难度!D2) -> 2700 | C2: =INDEX(Sheet1!$K$2:$AC$16,战士难度!F2,战士难度!E2) -> 39572 | D2: =E2-1 -> 3 | E2: 4 | F2: 1 | H2: =B2*C2 -> 106844400
A3: =A2+1 -> 3 | B3: =INDEX(Sheet1!$K$2:$AC$16,战士难度!F3,战士难度!D3) -> 2915 | C3: =INDEX(Sheet1!$K$2:$AC$16,战士难度!F3,战士难度!E3) -> 52500 | D3: =E3-1 -> 5 | E3: 6 | F3: 1 | H3: =B3*C3 -> 153037500
A4: =A3+1 -> 4 | B4: =INDEX(Sheet1!$K$2:$AC$16,战士难度!F4,战士难度!D4) -> 3059 | C4: =INDEX(Sheet1!$K$2:$AC$16,战士难度!F4,战士难度!E4) -> 59371 | D4: =E4-1 -> 7 | E4: 8 | F4: 1 | H4: =B4*C4 -> 181615889
A5: =A4+1 -> 5 | B5: =INDEX(Sheet1!$K$2:$AC$16,战士难度!F5,战士难度!D5) -> 3210 | C5: =INDEX(Sheet1!$K$2:$AC$16,战士难度!F5,战士难度!E5) -> 67140 | D5: =E5-1 -> 9 | E5: 10 | F5: 1 | H5: =B5*C5 -> 215519400
A6: =A5+1 -> 6 | B6: =INDEX(Sheet1!$K$2:$AC$16,战士难度!F6,战士难度!D6) -> 3423 | C6: =INDEX(Sheet1!$K$2:$AC$16,战士难度!F6,战士难度!E6) -> 79104 | D6: =E6-1 -> 11 | E6: 12 | F6: 1 | H6: =B6*C6 -> 270772992
A7: =A6+1 -> 7 | B7: =INDEX(Sheet1!$K$2:$AC$16,战士难度!F7,战士难度!D7) -> 3614 | C7: =INDEX(Sheet1!$K$2:$AC$16,战士难度!F7,战士难度!E7) -> 88403 | D7: =E7-1 -> 13 | E7: 14 | F7: 1 | H7: =B7*C7 -> 319488442
A8: =A7+1 -> 8 | B8: =INDEX(Sheet1!$K$2:$AC$16,战士难度!F8,战士难度!D8) -> 3815 | C8: =INDEX(Sheet1!$K$2:$AC$16,战士难度!F8,战士难度!E8) -> 98795 | D8: =E8-1 -> 15 | E8: 16 | F8: 1 | H8: =B8*C8 -> 376902925
A9: =A8+1 -> 9 | B9: =INDEX(Sheet1!$K$2:$AC$16,战士难度!F9,战士难度!D9) -> 4101 | C9: =INDEX(Sheet1!$K$2:$AC$16,战士难度!F9,战士难度!E9) -> 114576 | D9: =E9-1 -> 17 | E9: 18 | F9: 1 | H9: =B9*C9 -> 469876176
A10: =A9+1 -> 10 | B10: =INDEX(Sheet1!$K$2:$AC$16,战士难度!F10,战士难度!D10) -> 3815 | C10: =INDEX(Sheet1!$K$2:$AC$16,战士难度!F10,战士难度!E10) -> 55889 | D10: =E10-1 -> 1 | E10: 2 | F10: =F1+1 -> 2 | H10: =B10*C10 -> 213216535
A11: =A10+1 -> 11 | B11: =INDEX(Sheet1!$K$2:$AC$16,战士难度!F11,战士难度!D11) -> 4191 | C11: =INDEX(Sheet1!$K$2:$AC$16,战士难度!F11,战士难度!E11) -> 67365 | D11: =E11-1 -> 3 | E11: 4 | F11: =F2+1 -> 2 | H11: =B11*C11 -> 282326715
A12: =A11+1 -> 12 | B12: =INDEX(Sheet1!$K$2:$AC$16,战士难度!F12,战士难度!D12) -> 4752 | C12: =INDEX(Sheet1!$K$2:$AC$16,战士难度!F12,战士难度!E12) -> 86413 | D12: =E12-1 -> 5 | E12: 6 | F12: =F3+1 -> 2 | H12: =B12*C12 -> 410634576
A13: =A12+1 -> 13 | B13: =INDEX(Sheet1!$K$2:$AC$16,战士难度!F13,战士难度!D13) -> 5105 | C13: =INDEX(Sheet1!$K$2:$AC$16,战士难度!F13,战士难度!E13) -> 96870 | D13: =E13-1 -> 7 | E13: 8 | F13: =F4+1 -> 2 | H13: =B13*C13 -> 494521350
A14: =A13+1 -> 14 | B14: =INDEX(Sheet1!$K$2:$AC$16,战士难度!F14,战士难度!D14) -> 5484 | C14: =INDEX(Sheet1!$K$2:$AC$16,战士难度!F14,战士难度!E14) -> 108592 | D14: =E14-1 -> 9 | E14: 10 | F14: =F5+1 -> 2 | H14: =B14*C14 -> 595518528
A15: =A14+1 -> 15 | B15: =INDEX(Sheet1!$K$2:$AC$16,战士难度!F15,战士难度!D15) -> 6033 | C15: =INDEX(Sheet1!$K$2:$AC$16,战士难度!F15,战士难度!E15) -> 126458 | D15: =E15-1 -> 11 | E15: 12 | F15: =F6+1 -> 2 | H15: =B15*C15 -> 762921114
A16: =A15+1 -> 16 | B16: =INDEX(Sheet1!$K$2:$AC$16,战士难度!F16,战士难度!D16) -> 6501 | C16: =INDEX(Sheet1!$K$2:$AC$16,战士难度!F16,战士难度!E16) -> 140552 | D16: =E16-1 -> 13 | E16: 14 | F16: =F7+1 -> 2 | H16: =B16*C16 -> 913728552
A17: =A16+1 -> 17 | B17: =INDEX(Sheet1!$K$2:$AC$16,战士难度!F17,战士难度!D17) -> 7006 | C17: =INDEX(Sheet1!$K$2:$AC$16,战士难度!F17,战士难度!E17) -> 156217 | D17: =E17-1 -> 15 | E17: 16 | F17: =F8+1 -> 2 | H17: =B17*C17 -> 1094456302
A18: =A17+1 -> 18 | B18: =INDEX(Sheet1!$K$2:$AC$16,战士难度!F18,战士难度!D18) -> 7740 | C18: =INDEX(Sheet1!$K$2:$AC$16,战士难度!F18,战士难度!E18) -> 179852 | D18: =E18-1 -> 17 | E18: 18 | F18: =F9+1 -> 2 | H18: =B18*C18 -> 1392054480
A19: =A18+1 -> 19 | B19: =INDEX(Sheet1!$K$2:$AC$16,战士难度!F19,战士难度!D19) -> 5848 | C19: =INDEX(Sheet1!$K$2:$AC$16,战士难度!F19,战士难度!E19) -> 92599 | D19: =E19-1 -> 1 | E19: 2 | F19: =F10+1 -> 3 | H19: =B19*C19 -> 541518952
A20: =A19+1 -> 20 | B20: =INDEX(Sheet1!$K$2:$AC$16,战士难度!F20,战士难度!D20) -> 6616 | C20: =INDEX(Sheet1!$K$2:$AC$16,战士难度!F20,战士难度!E20) -> 108904 | D20: =E20-1 -> 3 | E20: 4 | F20: =F11+1 -> 3 | H20: =B20*C20 -> 720508864
A21: =A20+1 -> 21 | B21: =INDEX(Sheet1!$K$2:$AC$16,战士难度!F21,战士难度!D21) -> 7800 | C21: =INDEX(Sheet1!$K$2:$AC$16,战士难度!F21,战士难度!E21) -> 135194 | D21: =E21-1 -> 5 | E21: 6 | F21: =F12+1 -> 3 | H21: =B21*C21 -> 1054513200
... A135: =A134+1 -> 135 | B135: =INDEX(Sheet1!$K$2:$AC$16,战士难度!F135,战士难度!D135) -> 2007351 | C135: =INDEX(Sheet1!$K$2:$AC$16,战士难度!F135,战士难度!E135) -> 10452470 | D135: =E135-1 -> 17 | E135: 18 | F135: =F126+1 -> 15 | H135: =B135*C135 -> 20981776106970

Sheet 猎人难度
A1: 1 | B1: =INDEX(Sheet1!$K$50:$AB$64,F1,D1) -> 1702 | C1: =INDEX(Sheet1!$K$50:$AB$64,F1,E1) -> 66161 | D1: =E1-1 -> 1 | E1: 2 | F1: 1
A2: =A1+1 -> 2 | B2: =INDEX(Sheet1!$K$50:$AB$64,F2,D2) -> 1692 | C2: =INDEX(Sheet1!$K$50:$AB$64,F2,E2) -> 80087 | D2: =E2-1 -> 3 | E2: 4 | F2: 1
A3: =A2+1 -> 3 | B3: =INDEX(Sheet1!$K$50:$AB$64,F3,D3) -> 1678 | C3: =INDEX(Sheet1!$K$50:$AB$64,F3,E3) -> 103318 | D3: =E3-1 -> 5 | E3: 6 | F3: 1
A4: =A3+1 -> 4 | B4: =INDEX(Sheet1!$K$50:$AB$64,F4,D4) -> 1667 | C4: =INDEX(Sheet1!$K$50:$AB$64,F4,E4) -> 116001 | D4: =E4-1 -> 7 | E4: 8 | F4: 1
A5: =A4+1 -> 5 | B5: =INDEX(Sheet1!$K$50:$AB$64,F5,D5) -> 1657 | C5: =INDEX(Sheet1!$K$50:$AB$64,F5,E5) -> 130240 | D5: =E5-1 -> 9 | E5: 10 | F5: 1
A6: =A5+1 -> 6 | B6: =INDEX(Sheet1!$K$50:$AB$64,F6,D6) -> 1643 | C6: =INDEX(Sheet1!$K$50:$AB$64,F6,E6) -> 151981 | D6: =E6-1 -> 11 | E6: 12 | F6: 1
A7: =A6+1 -> 7 | B7: =INDEX(Sheet1!$K$50:$AB$64,F7,D7) -> 1629 | C7: =INDEX(Sheet1!$K$50:$AB$64,F7,E7) -> 169086 | D7: =E7-1 -> 13 | E7: 14 | F7: 1
A8: =A7+1 -> 8 | B8: =INDEX(Sheet1!$K$50:$AB$64,F8,D8) -> 1615 | C8: =INDEX(Sheet1!$K$50:$AB$64,F8,E8) -> 188117 | D8: =E8-1 -> 15 | E8: 16 | F8: 1
A9: =A8+1 -> 9 | B9: =INDEX(Sheet1!$K$50:$AB$64,F9,D9) -> 1597 | C9: =INDEX(Sheet1!$K$50:$AB$64,F9,E9) -> 216864 | D9: =E9-1 -> 17 | E9: 18 | F9: 1
A10: =A9+1 -> 10 | B10: =INDEX(Sheet1!$K$50:$AB$64,F10,D10) -> 2468 | C10: =INDEX(Sheet1!$K$50:$AB$64,F10,E10) -> 118454 | D10: =E10-1 -> 1 | E10: 2 | F10: =F1+1 -> 2
A11: =A10+1 -> 11 | B11: =INDEX(Sheet1!$K$50:$AB$64,F11,D11) -> 2489 | C11: =INDEX(Sheet1!$K$50:$AB$64,F11,E11) -> 139118 | D11: =E11-1 -> 3 | E11: 4 | F11: =F2+1 -> 2
A12: =A11+1 -> 12 | B12: =INDEX(Sheet1!$K$50:$AB$64,F12,D12) -> 2516 | C12: =INDEX(Sheet1!$K$50:$AB$64,F12,E12) -> 172382 | D12: =E12-1 -> 5 | E12: 6 | F12: =F3+1 -> 2
A13: =A12+1 -> 13 | B13: =INDEX(Sheet1!$K$50:$AB$64,F13,D13) -> 2537 | C13: =INDEX(Sheet1!$K$50:$AB$64,F13,E13) -> 191298 | D13: =E13-1 -> 7 | E13: 8 | F13: =F4+1 -> 2
A14: =A13+1 -> 14 | B14: =INDEX(Sheet1!$K$50:$AB$64,F14,D14) -> 2557 | C14: =INDEX(Sheet1!$K$50:$AB$64,F14,E14) -> 212290 | D14: =E14-1 -> 9 | E14: 10 | F14: =F5+1 -> 2
A15: =A14+1 -> 15 | B15: =INDEX(Sheet1!$K$50:$AB$64,F15,D15) -> 2585 | C15: =INDEX(Sheet1!$K$50:$AB$64,F15,E15) -> 243905 | D15: =E15-1 -> 11 | E15: 12 | F15: =F6+1 -> 2
A16: =A15+1 -> 16 | B16: =INDEX(Sheet1!$K$50:$AB$64,F16,D16) -> 2612 | C16: =INDEX(Sheet1!$K$50:$AB$64,F16,E16) -> 269288 | D16: =E16-1 -> 13 | E16: 14 | F16: =F7+1 -> 2
A17: =A16+1 -> 17 | B17: =INDEX(Sheet1!$K$50:$AB$64,F17,D17) -> 2639 | C17: =INDEX(Sheet1!$K$50:$AB$64,F17,E17) -> 297313 | D17: =E17-1 -> 15 | E17: 16 | F17: =F8+1 -> 2
A18: =A17+1 -> 18 | B18: =INDEX(Sheet1!$K$50:$AB$64,F18,D18) -> 2676 | C18: =INDEX(Sheet1!$K$50:$AB$64,F18,E18) -> 339268 | D18: =E18-1 -> 17 | E18: 18 | F18: =F9+1 -> 2
A19: =A18+1 -> 19 | B19: =INDEX(Sheet1!$K$50:$AB$64,F19,D19) -> 3805 | C19: =INDEX(Sheet1!$K$50:$AB$64,F19,E19) -> 207538 | D19: =E19-1 -> 1 | E19: 2 | F19: =F10+1 -> 3
A20: =A19+1 -> 20 | B20: =INDEX(Sheet1!$K$50:$AB$64,F20,D20) -> 3900 | C20: =INDEX(Sheet1!$K$50:$AB$64,F20,E20) -> 236560 | D20: =E20-1 -> 3 | E20: 4 | F20: =F11+1 -> 3
A21: =A20+1 -> 21 | B21: =INDEX(Sheet1!$K$50:$AB$64,F21,D21) -> 4031 | C21: =INDEX(Sheet1!$K$50:$AB$64,F21,E21) -> 281664 | D21: =E21-1 -> 5 | E21: 6 | F21: =F12+1 -> 3
... A135: =A134+1 -> 135 | B135: =INDEX(Sheet1!$K$50:$AB$64,F135,D135) -> 947767 | C135: =INDEX(Sheet1!$K$50:$AB$64,F135,E135) -> 19845406 | D135: =E135-1 -> 17 | E135: 18 | F135: =F126+1 -> 15

Sheet 法师难度
A1: 1 | B1: =INDEX(Sheet1!$K$98:$AB$112,F1,D1) -> 1234 | C1: =INDEX(Sheet1!$K$98:$AB$112,F1,E1) -> 41150 | D1: =E1-1 -> 1 | E1: 2 | F1: 1
A2: =A1+1 -> 2 | B2: =INDEX(Sheet1!$K$98:$AB$112,F2,D2) -> 1227 | C2: =INDEX(Sheet1!$K$98:$AB$112,F2,E2) -> 51351 | D2: =E2-1 -> 3 | E2: 4 | F2: 1
A3: =A2+1 -> 3 | B3: =INDEX(Sheet1!$K$98:$AB$112,F3,D3) -> 1217 | C3: =INDEX(Sheet1!$K$98:$AB$112,F3,E3) -> 68990 | D3: =E3-1 -> 5 | E3: 6 | F3: 1
A4: =A3+1 -> 4 | B4: =INDEX(Sheet1!$K$98:$AB$112,F4,D4) -> 1209 | C4: =INDEX(Sheet1!$K$98:$AB$112,F4,E4) -> 78255 | D4: =E4-1 -> 7 | E4: 8 | F4: 1
A5: =A4+1 -> 5 | B5: =INDEX(Sheet1!$K$98:$AB$112,F5,D5) -> 1202 | C5: =INDEX(Sheet1!$K$98:$AB$112,F5,E5) -> 88765 | D5: =E5-1 -> 9 | E5: 10 | F5: 1
A6: =A5+1 -> 6 | B6: =INDEX(Sheet1!$K$98:$AB$112,F6,D6) -> 1192 | C6: =INDEX(Sheet1!$K$98:$AB$112,F6,E6) -> 105005 | D6: =E6-1 -> 11 | E6: 12 | F6: 1
A7: =A6+1 -> 7 | B7: =INDEX(Sheet1!$K$98:$AB$112,F7,D7) -> 1182 | C7: =INDEX(Sheet1!$K$98:$AB$112,F7,E7) -> 117564 | D7: =E7-1 -> 13 | E7: 14 | F7: 1
A8: =A7+1 -> 8 | B8: =INDEX(Sheet1!$K$98:$AB$112,F8,D8) -> 1173 | C8: =INDEX(Sheet1!$K$98:$AB$112,F8,E8) -> 131625 | D8: =E8-1 -> 15 | E8: 16 | F8: 1
A9: =A8+1 -> 9 | B9: =INDEX(Sheet1!$K$98:$AB$112,F9,D9) -> 1160 | C9: =INDEX(Sheet1!$K$98:$AB$112,F9,E9) -> 153024 | D9: =E9-1 -> 17 | E9: 18 | F9: 1
A10: =A9+1 -> 10 | B10: =INDEX(Sheet1!$K$98:$AB$112,F10,D10) -> 1813 | C10: =INDEX(Sheet1!$K$98:$AB$112,F10,E10) -> 85868 | D10: =E10-1 -> 1 | E10: 2 | F10: =F1+1 -> 2
A11: =A10+1 -> 11 | B11: =INDEX(Sheet1!$K$98:$AB$112,F11,D11) -> 1831 | C11: =INDEX(Sheet1!$K$98:$AB$112,F11,E11) -> 102505 | D11: =E11-1 -> 3 | E11: 4 | F11: =F2+1 -> 2
A12: =A11+1 -> 12 | B12: =INDEX(Sheet1!$K$98:$AB$112,F12,D12) -> 1854 | C12: =INDEX(Sheet1!$K$98:$AB$112,F12,E12) -> 129807 | D12: =E12-1 -> 5 | E12: 6 | F12: =F3+1 -> 2
A13: =A12+1 -> 13 | B13: =INDEX(Sheet1!$K$98:$AB$112,F13,D13) -> 1871 | C13: =INDEX(Sheet1!$K$98:$AB$112,F13,E13) -> 144990 | D13: =E13-1 -> 7 | E13: 8 | F13: =F4+1 -> 2
A14: =A13+1 -> 14 | B14: =INDEX(Sheet1!$K$98:$AB$112,F14,D14) -> 1888 | C14: =INDEX(Sheet1!$K$98:$AB$112,F14,E14) -> 161948 | D14: =E14-1 -> 9 | E14: 10 | F14: =F5+1 -> 2
A15: =A14+1 -> 15 | B15: =INDEX(Sheet1!$K$98:$AB$112,F15,D15) -> 1911 | C15: =INDEX(Sheet1!$K$98:$AB$112,F15,E15) -> 187684 | D15: =E15-1 -> 11 | E15: 12 | F15: =F6+1 -> 2
A16: =A15+1 -> 16 | B16: =INDEX(Sheet1!$K$98:$AB$112,F16,D16) -> 1934 | C16: =INDEX(Sheet1!$K$98:$AB$112,F16,E16) -> 208113 | D16: =E16-1 -> 13 | E16: 14 | F16: =F7+1 -> 2
A17: =A16+1 -> 17 | B17: =INDEX(Sheet1!$K$98:$AB$112,F17,D17) -> 1957 | C17: =INDEX(Sheet1!$K$98:$AB$112,F17,E17) -> 230767 | D17: =E17-1 -> 15 | E17: 16 | F17: =F8+1 -> 2
A18: =A17+1 -> 18 | B18: =INDEX(Sheet1!$K$98:$AB$112,F18,D18) -> 1988 | C18: =INDEX(Sheet1!$K$98:$AB$112,F18,E18) -> 264852 | D18: =E18-1 -> 17 | E18: 18 | F18: =F9+1 -> 2
A19: =A18+1 -> 19 | B19: =INDEX(Sheet1!$K$98:$AB$112,F19,D19) -> 2817 | C19: =INDEX(Sheet1!$K$98:$AB$112,F19,E19) -> 153228 | D19: =E19-1 -> 1 | E19: 2 | F19: =F10+1 -> 3
A20: =A19+1 -> 20 | B20: =INDEX(Sheet1!$K$98:$AB$112,F20,D20) -> 2891 | C20: =INDEX(Sheet1!$K$98:$AB$112,F20,E20) -> 177345 | D20: =E20-1 -> 3 | E20: 4 | F20: =F11+1 -> 3
A21: =A20+1 -> 21 | B21: =INDEX(Sheet1!$K$98:$AB$112,F21,D21) -> 2994 | C21: =INDEX(Sheet1!$K$98:$AB$112,F21,E21) -> 215505 | D21: =E21-1 -> 5 | E21: 6 | F21: =F12+1 -> 3
... A135: =A134+1 -> 135 | B135: =INDEX(Sheet1!$K$98:$AB$112,F135,D135) -> 713780 | C135: =INDEX(Sheet1!$K$98:$AB$112,F135,E135) -> 16459454 | D135: =E135-1 -> 17 | E135: 18 | F135: =F126+1 -> 15

Sheet 怪物抗性与玩家穿透
A1: 等级 | B1: 护甲穿透 | C1: 物抗穿透 | D1: boss护甲 | E1: boss物抗 | F1: 穿透后护甲 | G1: 穿透后抗性 | H1: 护甲参数 | I1: 抗性参数 | L1: 护甲减伤 | M1: 抗性减伤 | N1: boss生命倍数 | O1: 穿透后护甲减伤 | P1: 穿透后抗性减伤 | Q1: 穿透后boss生命倍数
A2: 30 | B2: 16 | C2: 14 | D2: 20 | E2: 0 | F2: =D2*(1-B2/(B2+100)) -> 17.241379 | G2: =E2*(1-C2/(C2+100)) -> 0 | H2: 2815 | I2: 1550 | L2: =D2/($H2+D2) -> 0.0070546737 | M2: =E2/($I2+E2) -> 0 | N2: =1/(1-L2)/(1-M2) -> 1.0071048 | O2: =F2/($H2+F2) -> 0.0060875388 | P2: =G2/($I2+G2) -> 0 | Q2: =1/(1-O2)/(1-P2) -> 1.0061248
A3: 31 | B3: 18 | C3: 15 | D3: 50 | E3: 0 | F3: =D3*(1-B3/(B3+100)) -> 42.372881 | G3: =E3*(1-C3/(C3+100)) -> 0 | H3: 3000 | I3: 1600 | L3: =D3/($H3+D3) -> 0.016393443 | M3: =E3/($I3+E3) -> 0 | N3: =1/(1-L3)/(1-M3) -> 1.0166667 | O3: =F3/($H3+F3) -> 0.013927577 | P3: =G3/($I3+G3) -> 0 | Q3: =1/(1-O3)/(1-P3) -> 1.0141243
A4: 32 | B4: 20 | C4: 16 | D4: 80 | E4: 10 | F4: =D4*(1-B4/(B4+100)) -> 66.666667 | G4: =E4*(1-C4/(C4+100)) -> 8.6206897 | H4: 3191 | I4: 1650 | L4: =D4/($H4+D4) -> 0.024457352 | M4: =E4/($I4+E4) -> 0.0060240964 | N4: =1/(1-L4)/(1-M4) -> 1.0312831 | O4: =F4/($H4+F4) -> 0.020464545 | P4: =G4/($I4+G4) -> 0.0051975052 | Q4: =1/(1-O4)/(1-P4) -> 1.0262259
A5: 33 | B5: 22 | C5: 17 | D5: 110 | E5: 20 | F5: =D5*(1-B5/(B5+100)) -> 90.163934 | G5: =E5*(1-C5/(C5+100)) -> 17.094017 | H5: 3388 | I5: 1700 | L5: =D5/($H5+D5) -> 0.031446541 | M5: =E5/($I5+E5) -> 0.011627907 | N5: =1/(1-L5)/(1-M5) -> 1.0446142 | O5: =F5/($H5+F5) -> 0.025922854 | P5: =G5/($I5+G5) -> 0.0099552016 | Q5: =1/(1-O5)/(1-P5) -> 1.0369356
A6: 34 | B6: 24 | C6: 18 | D6: 140 | E6: 30 | F6: =D6*(1-B6/(B6+100)) -> 112.90323 | G6: =E6*(1-C6/(C6+100)) -> 25.423729 | H6: 3591 | I6: 1750 | L6: =D6/($H6+D6) -> 0.037523452 | M6: =E6/($I6+E6) -> 0.016853933 | N6: =1/(1-L6)/(1-M6) -> 1.0567975 | O6: =F6/($H6+F6) -> 0.030482229 | P6: =G6/($I6+G6) -> 0.014319809 | Q6: =1/(1-O6)/(1-P6) -> 1.0464252
A7: 35 | B7: 26 | C7: 19 | D7: 170 | E7: 40 | F7: =D7*(1-B7/(B7+100)) -> 134.92063 | G7: =E7*(1-C7/(C7+100)) -> 33.613445 | H7: 3800 | I7: 1800 | L7: =D7/($H7+D7) -> 0.042821159 | M7: =E7/($I7+E7) -> 0.02173913 | N7: =1/(1-L7)/(1-M7) -> 1.0679532 | O7: =F7/($H7+F7) -> 0.034288019 | P7: =G7/($I7+G7) -> 0.018331806 | Q7: =1/(1-O7)/(1-P7) -> 1.0548426
A8: 36 | B8: 28 | C8: 20 | D8: 200 | E8: 50 | F8: =D8*(1-B8/(B8+100)) -> 156.25 | G8: =E8*(1-C8/(C8+100)) -> 41.666667 | H8: 4015 | I8: 1850 | L8: =D8/($H8+D8) -> 0.047449585 | M8: =E8/($I8+E8) -> 0.026315789 | N8: =1/(1-L8)/(1-M8) -> 1.0781865 | O8: =F8/($H8+F8) -> 0.037458795 | P8: =G8/($I8+G8) -> 0.022026432 | Q8: =1/(1-O8)/(1-P8) -> 1.0623156
A9: 37 | B9: 30 | C9: 21 | D9: 230 | E9: 60 | F9: =D9*(1-B9/(B9+100)) -> 176.92308 | G9: =E9*(1-C9/(C9+100)) -> 49.586777 | H9: 4236 | I9: 1900 | L9: =D9/($H9+D9) -> 0.051500224 | M9: =E9/($I9+E9) -> 0.030612245 | N9: =1/(1-L9)/(1-M9) -> 1.0875901 | O9: =F9/($H9+F9) -> 0.040092037 | P9: =G9/($I9+G9) -> 0.025434506 | Q9: =1/(1-O9)/(1-P9) -> 1.0689549
A10: 38 | B10: 32 | C10: 22 | D10: 260 | E10: 70 | F10: =D10*(1-B10/(B10+100)) -> 196.9697 | G10: =E10*(1-C10/(C10+100)) -> 57.377049 | H10: 4463 | I10: 1950 | L10: =D10/($H10+D10) -> 0.055049757 | M10: =E10/($I10+E10) -> 0.034653465 | N10: =1/(1-L10)/(1-M10) -> 1.0962455 | O10: =F10/($H10+F10) -> 0.04226845 | P10: =G10/($I10+G10) -> 0.028583095 | Q10: =1/(1-O10)/(1-P10) -> 1.0748567
A11: 39 | B11: 34 | C11: 23 | D11: 290 | E11: 80 | F11: =D11*(1-B11/(B11+100)) -> 216.41791 | G11: =E11*(1-C11/(C11+100)) -> 65.04065 | H11: 4696 | I11: 2000 | L11: =D11/($H11+D11) -> 0.058162856 | M11: =E11/($I11+E11) -> 0.038461538 | N11: =1/(1-L11)/(1-M11) -> 1.1042249 | O11: =F11/($H11+F11) -> 0.044055273 | P11: =G11/($I11+G11) -> 0.031496063 | Q11: =1/(1-O11)/(1-P11) -> 1.0801046
A12: 40 | B12: 36 | C12: 24 | D12: 320 | E12: 90 | F12: =D12*(1-B12/(B12+100)) -> 235.29412 | G12: =E12*(1-C12/(C12+100)) -> 72.580645 | H12: 4935 | I12: 2050 | L12: =D12/($H12+D12) -> 0.060894386 | M12: =E12/($I12+E12) -> 0.042056075 | N12: =1/(1-L12)/(1-M12) -> 1.1115922 | O12: =F12/($H12+F12) -> 0.045508846 | P12: =G12/($I12+G12) -> 0.034194529 | Q12: =1/(1-O12)/(1-P12) -> 1.0847719
A13: 41 | B13: 38 | C13: 25 | D13: 350 | E13: 100 | F13: =D13*(1-B13/(B13+100)) -> 253.62319 | G13: =E13*(1-C13/(C13+100)) -> 80 | H13: 5180 | I13: 2100 | L13: =D13/($H13+D13) -> 0.063291139 | M13: =E13/($I13+E13) -> 0.045454545 | N13: =1/(1-L13)/(1-M13) -> 1.1184041 | O13: =F13/($H13+F13) -> 0.046676624 | P13: =G13/($I13+G13) -> 0.036697248 | Q13: =1/(1-O13)/(1-P13) -> 1.0889225
... A72: 100 | B72: 156 | C72: 84 | D72: 35000 | E72: 12000 | F72: =D72*(1-B72/(B72+100)) -> 13671.875 | G72: =E72*(1-C72/(C72+100)) -> 6521.7391 | H72: 30255 | I72: 9700 | L72: =D72/($H72+D72) -> 0.53635737 | M72: =E72/($I72+E72) -> 0.55299539 | N72: =1/(1-L72)/(1-M72) -> 4.8250813 | O72: =F72/($H72+F72) -> 0.31124169 | P72: =G72/($I72+G72) -> 0.40203699 | Q72: =1/(1-O72)/(1-P72) -> 2.4280567
A73: 101 | D73: 36000 | E73: 12400 | Q73: 2.4353208
A74: 102 | D74: 37000 | E74: 12800 | Q74: 2.4280567

Sheet 怪物模型
A1: 带小怪BOSS | B1: 伤害衰减 | C1: 血量衰减 | D1: 小怪血量为BOSS的20%
A2: 战士 | B2: 0.9 | C2: 0.75
A3: 法师 | B3: 0.9 | C3: 0.75
A4: 猎人 | B4: 0.9 | C4: 0.65
A5: 双BOSS
A6: 战士 | B6: 0.5 | C6: 0.65
A7: 法师 | B7: 0.5 | C7: 0.65
A8: 猎人 | B8: 0.5 | C8: 0.6
A9: 三BOSS
A10: 战士 | B10: 0.33 | C10: 0.45
A11: 法师 | B11: 0.33 | C11: 0.45
A12: 猎人 | B12: 0.33 | C12: 0.42
A14: 怪物 | B14: 技能 | C14: 伤害系数 | D14: 血量系数 | E14: 闪避% | F14: 暴击% | G14: 命中% | H14: 技能ID | I14: 标准MP | K14: 备注
A15: 法力风暴 | B15: 冥想、魔法盾 | C15: 1.5 | D15: 0.68 | E15: 13 | F15: 0 | G15: 0 | H15: 25,30 | I15: 1000 | K15: MP足够抵挡较高伤害。
A16: 荒野游侠 | B16: 致盲射击 | C16: 1 | D16: 0.8 | E16: 35 | F16: 0 | G16: 0 | H16: 16 | I16: 2000 | K16: 只是会闪避。。
A17: 勇猛的卡拉 | B17: 英勇打击 | C17: 1 | D17: 1 | E17: 13 | F17: 0 | G17: 0 | H17: 1 | I17: 1000
A18: 拉兹 | B18: 狂暴 | C18: 1.2 | D18: 1 | E18: 13 | F18: 0 | G18: 20 | H18: 10 | I18: 2000 | K18: 拉兹打人。。
A19: 卡雷 | B19: 冥想 | C19: 1.25 | D19: 1 | E19: 13 | F19: 0 | G19: 0 | H19: 25 | I19: 1000 | K19: 战5渣
A20: 疾风克鲁 | B20: 沉默射击 | C20: 1 | D20: 1 | E20: 13 | F20: 0 | G20: 0 | H20: 19 | I20: 1000
A21: 坚定的格雷格 | B21: 盾墙 | C21: 0.7 | D21: 0.8 | E21: 13 | F21: 0 | G21: 0 | H21: 3 | I21: 600 | K21: 我有盾墙
A22: 咒术大师 | B22: 冰霜新星、奥术冲击 | C22: 0.45 | D22: 0.7 | E22: 13 | F22: 0 | G22: 0 | H22: 22,27 | I22: 5000 | K22: 给个沉默
A23: 憾地者 | B23: 雷霆一击 | C23: 0.85 | D23: 1 | E23: 13 | F23: 0 | G23: 0 | H23: 4 | I23: 1000
A24: 迅捷的维恩 | B24: 多重射击 | C24: 1 | D24: 1 | E24: 0 | F24: 0 | G24: 0 | H24: 14 | I24: 1000
A25: 幻术师艾莉 | B25: 伪装 | C25: 1.2 | D25: 0.75 | E25: 0 | F25: 0 | G25: 0 | H25: 20 | I25: 1600 | K25: A到死
A26: 混乱的玛尔达 | B26: 风暴之锤、沉默射击、冰甲术 | C26: 1 | D26: 1.1 | E26: 13 | F26: 0 | G26: 0 | H26: 6,19,23 | I26: 1800 | K26: 啥是狂暴
A27: 暮光预言者 | B27: 吸取生命 | C27: 0.7 | D27: 1 | E27: 0 | F27: 0 | G27: 0 | H27: 13 | I27: 800
A28: 凝结水元素 | B28: 冰霜新星 | C28: 1 | D28: 0.92 | E28: 13 | F28: 0 | G28: 0 | H28: 22 | I28: 1000
A29: 拨弄的赛亚 | B29: 雄鹰守护、眼镜蛇射击、剑刃风暴 | C29: 1.2 | D29: 1 | E29: 13 | F29: 0 | G29: 0 | H29: 17,18,8 | I29: 3000 | K29: 给个控
A30: 火焰之王 | B30: 火冲、烈焰、炎爆 | C30: 1 | D30: 0.7 | E30: 13 | F30: 0 | G30: 0 | H30: 21,28,29 | I30: 1500
A31: 圣光约书亚 | B31: 治疗 | C31: 1 | D31: 0.7 | E31: 13 | F31: 0 | G31: 0 | H31: 2 | I31: 800
A32: 血誓审判者 | B32: 战斗怒吼 | C32: 0.28 | D32: 0.45 | E32: 13 | F32: 0 | G32: 0 | H32: 5 | I32: 1000 | K32: F4
A33: 血誓召唤者 | B33: 暴风雪 | C33: 0.36 | D33: 0.44 | E33: 13 | F33: 0 | G33: 0 | H33: 26 | I33: 1000
A34: 血誓领主 | B34: 多重射击 | C34: 0.36 | D34: 0.43 | E34: 13 | F34: 0 | G34: 0 | H34: 14 | I34: 1000
A35: 血誓预言者 | B35: 治疗 | C35: 0.3 | D35: 0.42 | E35: 13 | F35: 0 | G35: 0 | H35: 2 | I35: 800
A36: 驯兽师瓦纳 | B36: 治疗 | C36: 0.6 | D36: 0.6 | E36: 13 | F36: 0 | G36: 0 | H36: 2 | I36: 800 | K36: 就能奶两口
A37: 多兰 | B37: 破甲攻击 | C37: 0.35 | D37: 0.28 | E37: 13 | F37: 0 | G37: 0 | H37: 9 | I37: 1000
A38: 约翰 | B38: 狂暴 | C38: 0.35 | D38: 0.28 | E38: 13 | F38: 0 | G38: 0 | H38: 10 | I38: 1000
A39: 舞钢者拜伦 | B39: 剑刃风暴 | C39: 0.8 | D39: 1 | E39: 13 | F39: 0 | G39: 0 | H39: 8 | I39: 1000
A40: 塔克 | B40: 捍卫 | C40: 0.35 | D40: 0.6 | E40: 13 | F40: 0 | G40: 0 | H40: 3 | I40: 1000
A41: 迪皮斯 | B41: 奥术射击、多重射击 | C41: 0.6 | D41: 0.4 | E41: 13 | F41: 0 | G41: 0 | H41: 17,14 | I41: 1000 | K41: 缺少治疗
...

Sheet 怪物生成器
A1: 怪物名字 | B1: 等级 | C1: 怪物组别 | D1: 技能 | E1: 伤害系数 | F1: 血量系数 | G1: mp系数 | H1: 闪避% | I1: 暴击% | J1: 命中% | K1: 生命值(hp) | L1: 魔法值(mp) | M1: 最小伤害(minDmg) | N1: 最大伤害(maxDmg) | O1: 护甲(armor) | P1: 物抗(phyDef) | Q1: 魔抗(magDef) | R1: 暴击(critical) | S1: 命中(hit) | T1: 闪避(dodge) | U1: 韧性(resilience) | V1: 回合回魔
A2: =[2]monster.xml!$D347 -> 战士幻象 | B2: =[2]monster.xml!$C347 -> 30 | C2: 1 | D2: =VLOOKUP(A2,怪物模型!A$15:Z$70,8,0) -> 3 | E2: =VLOOKUP(A2,怪物模型!A$15:G$70,3,0) -> 1 | F2: =VLOOKUP(A2,怪物模型!A$15:G$77,4,0) -> 1 | G2: 1 | H2: =VLOOKUP(A2,怪物模型!A$15:G$77,5,0) -> 13 | I2: =VLOOKUP(A2,怪物模型!A$15:G$77,6,0) -> 0 | J2: =VLOOKUP(A2,怪物模型!A$15:G$77,7,0) -> 30 | K2: =ROUND(VLOOKUP(C2,战士难度!A$1:C$135,3,0)/VLOOKUP(B2,怪物抗性与玩家穿透!A$2:Q$74,17,0)*F2,0) -> 31817 | L2: =IF(A2="卡雷",42,IF(A2="法力风暴",ROUND(K2*0.1,0),VLOOKUP(A2,怪物模型!$A$15:$I$70,9,0)*(1+(B2-30)/100))) -> 500 | M2: =ROUND(VLOOKUP(C2,战士难度!A$1:C$135,2,0)*0.91*E2,0) -> 2320 | N2: =ROUND(M2*1.2,0) -> 2784 | O2: =VLOOKUP(B2,怪物抗性与玩家穿透!A$2:Q$74,4,0) -> 20 | P2: =VLOOKUP(B2,怪物抗性与玩家穿透!A$2:Q$74,5,0) -> 0 | Q2: =P2 -> 0 | R2: =VLOOKUP(B2,[3]battleParameter.xml!$A$6:$E$107,5,0)*(I2/100)/(1-I2/100) -> 0 | S2: =ROUND(VLOOKUP(B2,[3]battleParameter.xml!$A$6:$G$107,7,0)*(J2/100)/(1-J2/100),0) -> 1206 | T2: =ROUND(VLOOKUP(B2,[3]battleParameter.xml!$A$6:$Z$107,8,0)*(MIN(H2/100+0.2,0.99))/(1-MIN(H2/100+0.2,0.99)),0) -> 346 | U2: 0 | V2: 0
A3: =[2]monster.xml!$D348 -> 法力风暴 | B3: =[2]monster.xml!$C348 -> 30 | C3: =IF(OR(A3="塔克",A3="多兰",A3="约翰",A3="血誓预言者",A3="血誓召唤者",A3="血誓领主"),C2,C2+1) -> 2 | D3: =VLOOKUP(A3,怪物模型!A$15:Z$70,8,0) -> 25,30 | E3: =VLOOKUP(A3,怪物模型!A$15:G$70,3,0) -> 1.5 | F3: =VLOOKUP(A3,怪物模型!A$15:G$77,4,0) -> 0.68 | G3: 1 | H3: =VLOOKUP(A3,怪物模型!A$15:G$77,5,0) -> 13 | I3: =VLOOKUP(A3,怪物模型!A$15:G$77,6,0) -> 0 | J3: =VLOOKUP(A3,怪物模型!A$15:G$77,7,0) -> 0 | K3: =ROUND(VLOOKUP(C3,战士难度!A$1:C$135,3,0)/VLOOKUP(B3,怪物抗性与玩家穿透!A$2:Q$74,17,0)*F3,0) -> 26745 | L3: =IF(A3="卡雷",42,IF(A3="法力风暴",ROUND(K3*0.1,0),VLOOKUP(A3,怪物模型!$A$15:$I$70,9,0)*(1+(B3-30)/100))) -> 2675 | M3: =ROUND(VLOOKUP(C3,战士难度!A$1:C$135,2,0)*0.91*E3,0) -> 3686 | N3: =ROUND(M3*1.2,0) -> 4423 | O3: =VLOOKUP(B3,怪物抗性与玩家穿透!A$2:Q$74,4,0) -> 20 | P3: =VLOOKUP(B3,怪物抗性与玩家穿透!A$2:Q$74,5,0) -> 0 | Q3: =P3 -> 0 | R3: =VLOOKUP(B3,[3]battleParameter.xml!$A$6:$E$107,5,0)*(I3/100)/(1-I3/100) -> 0 | S3: =ROUND(VLOOKUP(B3,[3]battleParameter.xml!$A$6:$G$107,7,0)*(J3/100)/(1-J3/100),0) -> 0 | T3: =ROUND(VLOOKUP(B3,[3]battleParameter.xml!$A$6:$Z$107,8,0)*(MIN(H3/100+0.2,0.99))/(1-MIN(H3/100+0.2,0.99)),0) -> 346 | U3: 0 | V3: 0
A4: =[2]monster.xml!$D349 -> 角斗士里奥 | B4: =[2]monster.xml!$C349 -> 31 | C4: =IF(OR(A4="塔克",A4="多兰",A4="约翰",A4="血誓预言者",A4="血誓召唤者",A4="血誓领主"),C3,C3+1) -> 3 | D4: =VLOOKUP(A4,怪物模型!A$15:Z$70,8,0) -> 5 | E4: =VLOOKUP(A4,怪物模型!A$15:G$70,3,0) -> 1 | F4: =VLOOKUP(A4,怪物模型!A$15:G$77,4,0) -> 1 | G4: 1 | H4: =VLOOKUP(A4,怪物模型!A$15:G$77,5,0) -> 13 | I4: =VLOOKUP(A4,怪物模型!A$15:G$77,6,0) -> 0 | J4: =VLOOKUP(A4,怪物模型!A$15:G$77,7,0) -> 0 | K4: =ROUND(VLOOKUP(C4,战士难度!A$1:C$135,3,0)/VLOOKUP(B4,怪物抗性与玩家穿透!A$2:Q$74,17,0)*F4,0) -> 51769 | L4: =IF(A4="卡雷",42,IF(A4="法力风暴",ROUND(K4*0.1,0),VLOOKUP(A4,怪物模型!$A$15:$I$70,9,0)*(1+(B4-30)/100))) -> 1010 | M4: =ROUND(VLOOKUP(C4,战士难度!A$1:C$135,2,0)*0.91*E4,0) -> 2653 | N4: =ROUND(M4*1.2,0) -> 3184 | O4: =VLOOKUP(B4,怪物抗性与玩家穿透!A$2:Q$74,4,0) -> 50 | P4: =VLOOKUP(B4,怪物抗性与玩家穿透!A$2:Q$74,5,0) -> 0 | Q4: =P4 -> 0 | R4: =VLOOKUP(B4,[3]battleParameter.xml!$A$6:$E$107,5,0)*(I4/100)/(1-I4/100) -> 0 | S4: =ROUND(VLOOKUP(B4,[3]battleParameter.xml!$A$6:$G$107,7,0)*(J4/100)/(1-J4/100),0) -> 0 | T4: =ROUND(VLOOKUP(B4,[3]battleParameter.xml!$A$6:$Z$107,8,0)*(MIN(H4/100+0.2,0.99))/(1-MIN(H4/100+0.2,0.99)),0) -> 369 | U4: 0 | V4: 0
A5: =[2]monster.xml!$D350 -> 荒野游侠 | B5: =[2]monster.xml!$C350 -> 31 | C5: =IF(OR(A5="塔克",A5="多兰",A5="约翰",A5="血誓预言者",A5="血誓召唤者",A5="血誓领主"),C4,C4+1) -> 4 | D5: =VLOOKUP(A5,怪物模型!A$15:Z$70,8,0) -> 16 | E5: =VLOOKUP(A5,怪物模型!A$15:G$70,3,0) -> 1 | F5: =VLOOKUP(A5,怪物模型!A$15:G$77,4,0) -> 0.8 | G5: 1 | H5: =VLOOKUP(A5,怪物模型!A$15:G$77,5,0) -> 35 | I5: =VLOOKUP(A5,怪物模型!A$15:G$77,6,0) -> 0 | J5: =VLOOKUP(A5,怪物模型!A$15:G$77,7,0) -> 0 | K5: =ROUND(VLOOKUP(C5,战士难度!A$1:C$135,3,0)/VLOOKUP(B5,怪物抗性与玩家穿透!A$2:Q$74,17,0)*F5,0) -> 46835 | L5: =IF(A5="卡雷",42,IF(A5="法力风暴",ROUND(K5*0.1,0),VLOOKUP(A5,怪物模型!$A$15:$I$70,9,0)*(1+(B5-30)/100))) -> 2020 | M5: =ROUND(VLOOKUP(C5,战士难度!A$1:C$135,2,0)*0.91*E5,0) -> 2784 | N5: =ROUND(M5*1.2,0) -> 3341 | O5: =VLOOKUP(B5,怪物抗性与玩家穿透!A$2:Q$74,4,0) -> 50 | P5: =VLOOKUP(B5,怪物抗性与玩家穿透!A$2:Q$74,5,0) -> 0 | Q5: =P5 -> 0 | R5: =VLOOKUP(B5,[3]battleParameter.xml!$A$6:$E$107,5,0)*(I5/100)/(1-I5/100) -> 0 | S5: =ROUND(VLOOKUP(B5,[3]battleParameter.xml!$A$6:$G$107,7,0)*(J5/100)/(1-J5/100),0) -> 0 | T5: =ROUND(VLOOKUP(B5,[3]battleParameter.xml!$A$6:$Z$107,8,0)*(MIN(H5/100+0.2,0.99))/(1-MIN(H5/100+0.2,0.99)),0) -> 917 | U5: 0 | V5: 0
A6: =[2]monster.xml!$D351 -> 憾地者 | B6: =[2]monster.xml!$C351 -> 31 | C6: =IF(OR(A6="塔克",A6="多兰",A6="约翰",A6="血誓预言者",A6="血誓召唤者",A6="血誓领主"),C5,C5+1) -> 5 | D6: =VLOOKUP(A6,怪物模型!A$15:Z$70,8,0) -> 4 | E6: =VLOOKUP(A6,怪物模型!A$15:G$70,3,0) -> 0.85 | F6: =VLOOKUP(A6,怪物模型!A$15:G$77,4,0) -> 1 | G6: 1 | H6: =VLOOKUP(A6,怪物模型!A$15:G$77,5,0) -> 13 | I6: =VLOOKUP(A6,怪物模型!A$15:G$77,6,0) -> 0 | J6: =VLOOKUP(A6,怪物模型!A$15:G$77,7,0) -> 0 | K6: =ROUND(VLOOKUP(C6,战士难度!A$1:C$135,3,0)/VLOOKUP(B6,怪物抗性与玩家穿透!A$2:Q$74,17,0)*F6,0) -> 66205 | L6: =IF(A6="卡雷",42,IF(A6="法力风暴",ROUND(K6*0.1,0),VLOOKUP(A6,怪物模型!$A$15:$I$70,9,0)*(1+(B6-30)/100))) -> 1010 | M6: =ROUND(VLOOKUP(C6,战士难度!A$1:C$135,2,0)*0.91*E6,0) -> 2483 | N6: =ROUND(M6*1.2,0) -> 2980 | O6: =VLOOKUP(B6,怪物抗性与玩家穿透!A$2:Q$74,4,0) -> 50 | P6: =VLOOKUP(B6,怪物抗性与玩家穿透!A$2:Q$74,5,0) -> 0 | Q6: =P6 -> 0 | R6: =VLOOKUP(B6,[3]battleParameter.xml!$A$6:$E$107,5,0)*(I6/100)/(1-I6/100) -> 0 | S6: =ROUND(VLOOKUP(B6,[3]battleParameter.xml!$A$6:$G$107,7,0)*(J6/100)/(1-J6/100),0) -> 0 | T6: =ROUND(VLOOKUP(B6,[3]battleParameter.xml!$A$6:$Z$107,8,0)*(MIN(H6/100+0.2,0.99))/(1-MIN(H6/100+0.2,0.99)),0) -> 369 | U6: 0 | V6: 0
A7: =[2]monster.xml!$D352 -> 拉兹 | B7: =[2]monster.xml!$C352 -> 32 | C7: =IF(OR(A7="塔克",A7="多兰",A7="约翰",A7="血誓预言者",A7="血誓召唤者",A7="血誓领主"),C6,C6+1) -> 6 | D7: =VLOOKUP(A7,怪物模型!A$15:Z$70,8,0) -> 10 | E7: =VLOOKUP(A7,怪物模型!A$15:G$70,3,0) -> 1.2 | F7: =VLOOKUP(A7,怪物模型!A$15:G$77,4,0) -> 1 | G7: 1 | H7: =VLOOKUP(A7,怪物模型!A$15:G$77,5,0) -> 13 | I7: =VLOOKUP(A7,怪物模型!A$15:G$77,6,0) -> 0 | J7: =VLOOKUP(A7,怪物模型!A$15:G$77,7,0) -> 20 | K7: =ROUND(VLOOKUP(C7,战士难度!A$1:C$135,3,0)/VLOOKUP(B7,怪物抗性与玩家穿透!A$2:Q$74,17,0)*F7,0) -> 77082 | L7: =IF(A7="卡雷",42,IF(A7="法力风暴",ROUND(K7*0.1,0),VLOOKUP(A7,怪物模型!$A$15:$I$70,9,0)*(1+(B7-30)/100))) -> 2040 | M7: =ROUND(VLOOKUP(C7,战士难度!A$1:C$135,2,0)*0.91*E7,0) -> 3738 | N7: =ROUND(M7*1.2,0) -> 4486 | O7: =VLOOKUP(B7,怪物抗性与玩家穿透!A$2:Q$74,4,0) -> 80 | P7: =VLOOKUP(B7,怪物抗性与玩家穿透!A$2:Q$74,5,0) -> 10 | Q7: =P7 -> 10 | R7: =VLOOKUP(B7,[3]battleParameter.xml!$A$6:$E$107,5,0)*(I7/100)/(1-I7/100) -> 0 | S7: =ROUND(VLOOKUP(B7,[3]battleParameter.xml!$A$6:$G$107,7,0)*(J7/100)/(1-J7/100),0) -> 798 | T7: =ROUND(VLOOKUP(B7,[3]battleParameter.xml!$A$6:$Z$107,8,0)*(MIN(H7/100+0.2,0.99))/(1-MIN(H7/100+0.2,0.99)),0) -> 393 | U7: 0 | V7: 0
A8: =[2]monster.xml!$D353 -> 塔克 | B8: =[2]monster.xml!$C353 -> 32 | C8: =IF(OR(A8="塔克",A8="多兰",A8="约翰",A8="血誓预言者",A8="血誓召唤者",A8="血誓领主"),C7,C7+1) -> 6 | D8: =VLOOKUP(A8,怪物模型!A$15:Z$70,8,0) -> 3 | E8: =VLOOKUP(A8,怪物模型!A$15:G$70,3,0) -> 0.35 | F8: =VLOOKUP(A8,怪物模型!A$15:G$77,4,0) -> 0.6 | G8: 1 | H8: =VLOOKUP(A8,怪物模型!A$15:G$77,5,0) -> 13 | I8: =VLOOKUP(A8,怪物模型!A$15:G$77,6,0) -> 0 | J8: =VLOOKUP(A8,怪物模型!A$15:G$77,7,0) -> 0 | K8: =ROUND(VLOOKUP(C8,战士难度!A$1:C$135,3,0)/VLOOKUP(B8,怪物抗性与玩家穿透!A$2:Q$74,17,0)*F8,0) -> 46249 | L8: =IF(A8="卡雷",42,IF(A8="法力风暴",ROUND(K8*0.1,0),VLOOKUP(A8,怪物模型!$A$15:$I$70,9,0)*(1+(B8-30)/100))) -> 1020 | M8: =ROUND(VLOOKUP(C8,战士难度!A$1:C$135,2,0)*0.91*E8,0) -> 1090 | N8: =ROUND(M8*1.2,0) -> 1308 | O8: =VLOOKUP(B8,怪物抗性与玩家穿透!A$2:Q$74,4,0) -> 80 | P8: =VLOOKUP(B8,怪物抗性与玩家穿透!A$2:Q$74,5,0) -> 10 | Q8: =P8 -> 10 | R8: =VLOOKUP(B8,[3]battleParameter.xml!$A$6:$E$107,5,0)*(I8/100)/(1-I8/100) -> 0 | S8: =ROUND(VLOOKUP(B8,[3]battleParameter.xml!$A$6:$G$107,7,0)*(J8/100)/(1-J8/100),0) -> 0 | T8: =ROUND(VLOOKUP(B8,[3]battleParameter.xml!$A$6:$Z$107,8,0)*(MIN(H8/100+0.2,0.99))/(1-MIN(H8/100+0.2,0.99)),0) -> 393 | U8: 0 | V8: 0
A9: =[2]monster.xml!$D354 -> 迪皮斯 | B9: =[2]monster.xml!$C354 -> 32 | C9: =IF(OR(A9="塔克",A9="多兰",A9="约翰",A9="血誓预言者",A9="血誓召唤者",A9="血誓领主"),C8,C8+1) -> 7 | D9: =VLOOKUP(A9,怪物模型!A$15:Z$70,8,0) -> 17,14 | E9: =VLOOKUP(A9,怪物模型!A$15:G$70,3,0) -> 0.6 | F9: =VLOOKUP(A9,怪物模型!A$15:G$77,4,0) -> 0.4 | G9: 1 | H9: =VLOOKUP(A9,怪物模型!A$15:G$77,5,0) -> 13 | I9: =VLOOKUP(A9,怪物模型!A$15:G$77,6,0) -> 0 | J9: =VLOOKUP(A9,怪物模型!A$15:G$77,7,0) -> 0 | K9: =ROUND(VLOOKUP(C9,战士难度!A$1:C$135,3,0)/VLOOKUP(B9,怪物抗性与玩家穿透!A$2:Q$74,17,0)*F9,0) -> 34458 | L9: =IF(A9="卡雷",42,IF(A9="法力风暴",ROUND(K9*0.1,0),VLOOKUP(A9,怪物模型!$A$15:$I$70,9,0)*(1+(B9-30)/100))) -> 1020 | M9: =ROUND(VLOOKUP(C9,战士难度!A$1:C$135,2,0)*0.91*E9,0) -> 1973 | N9: =ROUND(M9*1.2,0) -> 2368 | O9: =VLOOKUP(B9,怪物抗性与玩家穿透!A$2:Q$74,4,0) -> 80 | P9: =VLOOKUP(B9,怪物抗性与玩家穿透!A$2:Q$74,5,0) -> 10 | Q9: =P9 -> 10 | R9: =VLOOKUP(B9,[3]battleParameter.xml!$A$6:$E$107,5,0)*(I9/100)/(1-I9/100) -> 0 | S9: =ROUND(VLOOKUP(B9,[3]battleParameter.xml!$A$6:$G$107,7,0)*(J9/100)/(1-J9/100),0) -> 0 | T9: =ROUND(VLOOKUP(B9,[3]battleParameter.xml!$A$6:$Z$107,8,0)*(MIN(H9/100+0.2,0.99))/(1-MIN(H9/100+0.2,0.99)),0) -> 393 | U9: 0 | V9: 0
