Workbook

Sheet Sheet1
A1: allianceBoss
B3: 攻击次数(id) | C3: 公会等级 | D3: 经验区间段 | E3: 经验区间段 | F3: 名字 | G3: Boss等级 | H3: 人数上限(popSize) | I3: 贡献 | J3: 活动时间 | K3: 怪物ID | L3: 怪物血量 | M3: 魔兽
B4: id | C4: level | D4: expStart | E4: expEnd | F4: name | G4: monsterLevel | H4: popSize | I4: contribution | J4: time | K4: bossId | L4: bossHp | M4: openBossVitality
B6: 1 | C6: 1 | D6: 0 | E6: 1000 | F6: 魔兽 | G6: 20 | H6: 20 | I6: 1000 | J6: 240 | K6: 1 | L6: 160000 | M6: 1000
B7: 2 | C7: 1 | D7: =E6+1 -> 1001 | E7: 2000 | F7: 魔兽 | G7: 25 | H7: 20 | I7: 1100 | J7: 240 | K7: 2 | L7: =ROUND(POWER(L$9/L$6,1/3)*L6,-2) -> 191900 | M7: 1050
B8: 3 | C8: 1 | D8: =E7+1 -> 2001 | E8: 3000 | F8: 魔兽 | G8: 30 | H8: 20 | I8: 1200 | J8: 240 | K8: 3 | L8: =ROUND(POWER(L$9/L$6,1/3)*L7,-2) -> 230100 | M8: 1100
B9: 4 | C9: 1 | D9: =E8+1 -> 3001 | E9: 4000 | F9: 魔兽 | G9: 35 | H9: 20 | I9: 1300 | J9: 240 | K9: 4 | L9: 275900 | M9: 1150
B10: 5 | C10: 2 | D10: 0 | E10: 2000 | F10: 魔兽 | G10: 40 | H10: 22 | I10: 1400 | J10: 240 | K10: 5 | L10: =ROUND(POWER(L13/L9,1/4)*L9,-2) -> 376200 | M10: 1200
B11: 6 | C11: 2 | D11: =E10+1 -> 2001 | E11: 4000 | F11: 魔兽 | G11: 45 | H11: 22 | I11: 1500 | J11: 240 | K11: 6 | L11: =ROUND(POWER(L13/L9,1/4)*L10,-2) -> 513000 | M11: 1250
B12: 7 | C12: 2 | D12: =E11+1 -> 4001 | E12: 6000 | F12: 魔兽 | G12: 50 | H12: 22 | I12: 1600 | J12: 240 | K12: 7 | L12: =ROUND(POWER(L13/L9,1/4)*L11,-2) -> 699500 | M12: 1300
B13: 8 | C13: 2 | D13: =E12+1 -> 6001 | E13: 8000 | F13: 魔兽 | G13: 55 | H13: 22 | I13: 1700 | J13: 240 | K13: 8 | L13: 953800 | M13: 1350
B14: 9 | C14: 3 | D14: 0 | E14: 3000 | F14: 魔兽 | G14: 60 | H14: 24 | I14: 1800 | J14: 240 | K14: 9 | L14: =ROUND(POWER(L17/L13,1/4)*L13,-2) -> 1127600 | M14: 1400
B15: 10 | C15: 3 | D15: =E14+1 -> 3001 | E15: 6000 | F15: 魔兽 | G15: 65 | H15: 24 | I15: 1900 | J15: 240 | K15: 10 | L15: =ROUND(POWER(L17/L13,1/4)*L14,-2) -> 1333100 | M15: 1450
B16: 11 | C16: 3 | D16: =E15+1 -> 6001 | E16: 9000 | F16: 魔兽 | G16: 70 | H16: 24 | I16: 2000 | J16: 240 | K16: 11 | L16: =ROUND(POWER(L17/L13,1/4)*L15,-2) -> 1576100 | M16: 1500
B17: 12 | C17: 3 | D17: =E16+1 -> 9001 | E17: 12000 | F17: 魔兽 | G17: 75 | H17: 24 | I17: 2100 | J17: 240 | K17: 12 | L17: 1863400 | M17: 1550
B18: 13 | C18: 4 | D18: 0 | E18: 4500 | F18: 魔兽 | G18: 80 | H18: 26 | I18: 2200 | J18: 240 | K18: 13 | L18: =ROUND(POWER(L21/L17,1/4)*L17,-2) -> 2092600 | M18: 1600
B19: 14 | C19: 4 | D19: =E18+1 -> 4501 | E19: 9000 | F19: 魔兽 | G19: 85 | H19: 26 | I19: 2300 | J19: 240 | K19: 14 | L19: =ROUND(POWER(L21/L17,1/4)*L18,-2) -> 2350000 | M19: 1650
B20: 15 | C20: 4 | D20: =E19+1 -> 9001 | E20: 13500 | F20: 魔兽 | G20: 90 | H20: 26 | I20: 2400 | J20: 240 | K20: 15 | L20: =ROUND(POWER(L21/L17,1/4)*L19,-2) -> 2639100 | M20: 1700
B21: 16 | C21: 4 | D21: =E20+1 -> 13501 | E21: 18000 | F21: 魔兽 | G21: 95 | H21: 26 | I21: 2500 | J21: 240 | K21: 16 | L21: 2963800 | M21: 1750
B22: 17 | C22: 5 | D22: 0 | E22: =(C22*C22+C22+20)*120 -> 6000 | F22: 魔兽 | G22: 100 | H22: 28 | I22: 2600 | J22: 240 | K22: 17 | L22: =ROUND(POWER(L25/L21,1/4)*L21,-2) -> 3330900 | M22: 1800
B23: 18 | C23: 5 | D23: =E22+1 -> 6001 | E23: =E22*2 -> 12000 | F23: 魔兽 | G23: 105 | H23: 28 | I23: 2700 | J23: 240 | K23: 18 | L23: =ROUND(POWER(L25/L21,1/4)*L22,-2) -> 3743500 | M23: 1850
B24: 19 | C24: 5 | D24: =E23+1 -> 12001 | E24: =E22*3 -> 18000 | F24: 魔兽 | G24: 110 | H24: 28 | I24: 2800 | J24: 240 | K24: 19 | L24: =ROUND(POWER(L25/L21,1/4)*L23,-2) -> 4207200 | M24: 1900
B25: 20 | C25: 5 | D25: =E24+1 -> 18001 | E25: =E22*4 -> 24000 | F25: 魔兽 | G25: 115 | H25: 28 | I25: 2900 | J25: 240 | K25: 20 | L25: 4728200 | M25: 1950
B26: 21 | C26: 6 | D26: 0 | E26: =(C26*C26+C26+20)*120 -> 7440 | F26: 魔兽 | G26: 120 | H26: 30 | I26: 3000 | J26: 240 | K26: 21 | L26: =ROUND(POWER(L29/L25,1/4)*L25,-2) -> 5419900 | M26: 2000
B27: 22 | C27: 6 | D27: =E26+1 -> 7441 | E27: =E26*2 -> 14880 | F27: 魔兽 | G27: 125 | H27: 30 | I27: 3100 | J27: 240 | K27: 22 | L27: =ROUND(POWER(L29/L25,1/4)*L26,-2) -> 6212800 | M27: 2050
B28: 23 | C28: 6 | D28: =E27+1 -> 14881 | E28: =E26*3 -> 22320 | F28: 魔兽 | G28: 130 | H28: 30 | I28: 3200 | J28: 240 | K28: 23 | L28: =ROUND(POWER(L29/L25,1/4)*L27,-2) -> 7121700 | M28: 2100
B29: 24 | C29: 6 | D29: =E28+1 -> 22321 | E29: =E26*4 -> 29760 | F29: 魔兽 | G29: 135 | H29: 30 | I29: 3300 | J29: 240 | K29: 24 | L29: 8163400 | M29: 2150
B30: 25 | C30: 7 | D30: 0 | E30: =(C30*C30+C30+20)*120 -> 9120 | F30: 魔兽 | G30: 140 | H30: 32 | I30: 3400 | J30: 240 | K30: 25 | L30: =ROUND(POWER(L33/L29,1/4)*L29,-2) -> 9074800 | M30: 2200
B31: 26 | C31: 7 | D31: =E30+1 -> 9121 | E31: =E30*2 -> 18240 | F31: 魔兽 | G31: 145 | H31: 32 | I31: 3500 | J31: 240 | K31: 26 | L31: =ROUND(POWER(L33/L29,1/4)*L30,-2) -> 10087900 | M31: 2250
B32: 27 | C32: 7 | D32: =E31+1 -> 18241 | E32: =E30*3 -> 27360 | F32: 魔兽 | G32: 150 | H32: 32 | I32: 3600 | J32: 240 | K32: 27 | L32: =ROUND(POWER(L33/L29,1/4)*L31,-2) -> 11214100 | M32: 2300
B33: 28 | C33: 7 | D33: =E32+1 -> 27361 | E33: =E30*4 -> 36480 | F33: 魔兽 | G33: 155 | H33: 32 | I33: 3700 | J33: 240 | K33: 28 | L33: 12466000 | M33: 2350
B34: 29 | C34: 8 | D34: 0 | E34: =(C34*C34+C34+20)*120 -> 11040 | F34: 魔兽 | G34: 160 | H34: 34 | I34: 3800 | J34: 240 | K34: 29 | L34: =ROUND(POWER(L37/L33,1/4)*L33,-2) -> 13271200 | M34: 2400
B35: 30 | C35: 8 | D35: =E34+1 -> 11041 | E35: =E34*2 -> 22080 | F35: 魔兽 | G35: 165 | H35: 34 | I35: 3900 | J35: 240 | K35: 30 | L35: =ROUND(POWER(L37/L33,1/4)*L34,-2) -> 14128400 | M35: 2450
B36: 31 | C36: 8 | D36: =E35+1 -> 22081 | E36: =E34*3 -> 33120 | F36: 魔兽 | G36: 170 | H36: 34 | I36: 4000 | J36: 240 | K36: 31 | L36: =ROUND(POWER(L37/L33,1/4)*L35,-2) -> 15041000 | M36: 2500
B37: 32 | C37: 8 | D37: =E36+1 -> 33121 | E37: =E34*4 -> 44160 | F37: 魔兽 | G37: 175 | H37: 34 | I37: 4100 | J37: 240 | K37: 32 | L37: 16012500 | M37: 2550
B38: 33 | C38: 9 | D38: 0 | E38: =(C38*C38+C38+20)*120 -> 13200 | F38: 魔兽 | G38: 180 | H38: 36 | I38: 4200 | J38: 240 | K38: 33 | L38: =ROUND(POWER(L41/L37,1/4)*L37,-2) -> 16774500 | M38: 2600
B39: 34 | C39: 9 | D39: =E38+1 -> 13201 | E39: =E38*2 -> 26400 | F39: 魔兽 | G39: 185 | H39: =C39*2+18 -> 36 | I39: 4300 | J39: 240 | K39: 34 | L39: =ROUND(POWER(L41/L37,1/4)*L38,-2) -> 17572800 | M39: 2650
B40: 35 | C40: 9 | D40: =E39+1 -> 26401 | E40: =E38*3 -> 39600 | F40: 魔兽 | G40: 190 | H40: =C40*2+18 -> 36 | I40: 4400 | J40: 240 | K40: 35 | L40: =ROUND(POWER(L41/L37,1/4)*L39,-2) -> 18409100 | M40: 2700
B41: 36 | C41: 9 | D41: =E40+1 -> 39601 | E41: =E38*4 -> 52800 | F41: 魔兽 | G41: 195 | H41: =C41*2+18 -> 36 | I41: 4500 | J41: 240 | K41: 36 | L41: 19285200 | M41: 2750
B42: 37 | C42: 10 | D42: 0 | E42: =(C42*C42+C42+20)*120 -> 15600 | F42: 魔兽 | G42: 200 | H42: =C42*2+18 -> 38 | I42: 4600 | J42: 240 | K42: 37 | L42: =ROUND(POWER(L45/L41,1/4)*L41,-2) -> 20157000 | M42: 2800
...

Sheet 公会-client
B1: 攻击次数(id) | C1: 名字 | D1: Boss等级 | E1: 贡献 | F1: 怪物名称 | G1: 怪物血量
B2: =Sheet1!B6 -> 1 | C2: =Sheet1!F6 -> 魔兽 | D2: =Sheet1!G6 -> 20 | E2: =Sheet1!I6 -> 1000 | F2: =Sheet1!K6 -> 1 | G2: =Sheet1!L6 -> 160000
B3: =Sheet1!B7 -> 2 | C3: =Sheet1!F7 -> 魔兽 | D3: =Sheet1!G7 -> 25 | E3: =Sheet1!I7 -> 1100 | F3: =Sheet1!K7 -> 2 | G3: =Sheet1!L7 -> 191900
B4: =Sheet1!B8 -> 3 | C4: =Sheet1!F8 -> 魔兽 | D4: =Sheet1!G8 -> 30 | E4: =Sheet1!I8 -> 1200 | F4: =Sheet1!K8 -> 3 | G4: =Sheet1!L8 -> 230100
B5: =Sheet1!B9 -> 4 | C5: =Sheet1!F9 -> 魔兽 | D5: =Sheet1!G9 -> 35 | E5: =Sheet1!I9 -> 1300 | F5: =Sheet1!K9 -> 4 | G5: =Sheet1!L9 -> 275900
B6: =Sheet1!B10 -> 5 | C6: =Sheet1!F10 -> 魔兽 | D6: =Sheet1!G10 -> 40 | E6: =Sheet1!I10 -> 1400 | F6: =Sheet1!K10 -> 5 | G6: =Sheet1!L10 -> 376200
B7: =Sheet1!B11 -> 6 | C7: =Sheet1!F11 -> 魔兽 | D7: =Sheet1!G11 -> 45 | E7: =Sheet1!I11 -> 1500 | F7: =Sheet1!K11 -> 6 | G7: =Sheet1!L11 -> 513000
B8: =Sheet1!B12 -> 7 | C8: =Sheet1!F12 -> 魔兽 | D8: =Sheet1!G12 -> 50 | E8: =Sheet1!I12 -> 1600 | F8: =Sheet1!K12 -> 7 | G8: =Sheet1!L12 -> 699500
B9: =Sheet1!B13 -> 8 | C9: =Sheet1!F13 -> 魔兽 | D9: =Sheet1!G13 -> 55 | E9: =Sheet1!I13 -> 1700 | F9: =Sheet1!K13 -> 8 | G9: =Sheet1!L13 -> 953800
B10: =Sheet1!B14 -> 9 | C10: =Sheet1!F14 -> 魔兽 | D10: =Sheet1!G14 -> 60 | E10: =Sheet1!I14 -> 1800 | F10: =Sheet1!K14 -> 9 | G10: =Sheet1!L14 -> 1127600
B11: =Sheet1!B15 -> 10 | C11: =Sheet1!F15 -> 魔兽 | D11: =Sheet1!G15 -> 65 | E11: =Sheet1!I15 -> 1900 | F11: =Sheet1!K15 -> 10 | G11: =Sheet1!L15 -> 1333100
B12: =Sheet1!B16 -> 11 | C12: =Sheet1!F16 -> 魔兽 | D12: =Sheet1!G16 -> 70 | E12: =Sheet1!I16 -> 2000 | F12: =Sheet1!K16 -> 11 | G12: =Sheet1!L16 -> 1576100
B13: =Sheet1!B17 -> 12 | C13: =Sheet1!F17 -> 魔兽 | D13: =Sheet1!G17 -> 75 | E13: =Sheet1!I17 -> 2100 | F13: =Sheet1!K17 -> 12 | G13: =Sheet1!L17 -> 1863400
... B121: =Sheet1!B125 -> 120 | C121: =Sheet1!F125 -> 魔兽 | D121: =Sheet1!G125 -> 615 | E121: =Sheet1!I125 -> 12900 | F121: =Sheet1!K125 -> 120 | G121: =Sheet1!L125 -> 147627900

Sheet Sheet3
A1: 工会等级 | B1: 所需经验 | C1: 总需经验 | D1: BOSS经验 | E1: 打BOSS需要次数 | F1: 需要时间 | G1: 达到等级 | H1: 参考伤害 | I1: BOSS血量
A2: 1 | B2: =INDEX(Sheet1!E$6:E$125,Sheet3!A2*4) -> 4000 | C2: =B2 -> 4000 | D2: =INDEX(Sheet1!I$6:I$125,Sheet3!A2) -> 1000 | E2: =B2/D2 -> 4 | F2: =E2 -> 4 | G2: 18 | H2: =VLOOKUP(G2,[1]地图强度!$M$2:$N$101,2,0) -> 919.6644 | I2: =ROUND(H2*300,-2) -> 275900
A3: 2 | B3: =INDEX(Sheet1!E$6:E$125,Sheet3!A3*4) -> 8000 | C3: =B3+C2 -> 12000 | D3: =INDEX(Sheet1!I$6:I$125,Sheet3!A3) -> 1100 | E3: =B3/D3 -> 7.2727273 | F3: =F2+E3 -> 11.272727 | G3: 32 | H3: =VLOOKUP(G3,[1]地图强度!$M$2:$N$101,2,0) -> 3179.2444 | I3: =ROUND(H3*300,-2) -> 953800
A4: 3 | B4: =INDEX(Sheet1!E$6:E$125,Sheet3!A4*4) -> 12000 | C4: =B4+C3 -> 24000 | D4: =INDEX(Sheet1!I$6:I$125,Sheet3!A4) -> 1200 | E4: =B4/D4 -> 10 | F4: =F3+E4 -> 21.272727 | G4: 41 | H4: =VLOOKUP(G4,[1]地图强度!$M$2:$N$101,2,0) -> 6211.3743 | I4: =ROUND(H4*300,-2) -> 1863400
A5: 4 | B5: =INDEX(Sheet1!E$6:E$125,Sheet3!A5*4) -> 18000 | C5: =B5+C4 -> 42000 | D5: =INDEX(Sheet1!I$6:I$125,Sheet3!A5) -> 1300 | E5: =B5/D5 -> 13.846154 | F5: =F4+E5 -> 35.118881 | G5: 49 | H5: =VLOOKUP(G5,[1]地图强度!$M$2:$N$101,2,0) -> 9879.2078 | I5: =ROUND(H5*300,-2) -> 2963800
A6: 5 | B6: =INDEX(Sheet1!E$6:E$125,Sheet3!A6*4) -> 24000 | C6: =B6+C5 -> 66000 | D6: =INDEX(Sheet1!I$6:I$125,Sheet3!A6) -> 1400 | E6: =B6/D6 -> 17.142857 | F6: =F5+E6 -> 52.261738 | G6: 57 | H6: =VLOOKUP(G6,[1]地图强度!$M$2:$N$101,2,0) -> 15760.601 | I6: =ROUND(H6*300,-2) -> 4728200
A7: 6 | B7: =INDEX(Sheet1!E$6:E$125,Sheet3!A7*4) -> 29760 | C7: =B7+C6 -> 95760 | D7: =INDEX(Sheet1!I$6:I$125,Sheet3!A7) -> 1500 | E7: =B7/D7 -> 19.84 | F7: =F6+E7 -> 72.101738 | G7: 64 | H7: =VLOOKUP(G7,[1]地图强度!$M$2:$N$101,2,0) -> 27211.298 | I7: =ROUND(H7*300,-2) -> 8163400
A8: 7 | B8: =INDEX(Sheet1!E$6:E$125,Sheet3!A8*4) -> 36480 | C8: =B8+C7 -> 132240 | D8: =INDEX(Sheet1!I$6:I$125,Sheet3!A8) -> 1600 | E8: =B8/D8 -> 22.8 | F8: =F7+E8 -> 94.901738 | G8: 71 | H8: =VLOOKUP(G8,[1]地图强度!$M$2:$N$101,2,0) -> 41553.4 | I8: =ROUND(H8*300,-2) -> 12466000
A9: 8 | B9: =INDEX(Sheet1!E$6:E$125,Sheet3!A9*4) -> 44160 | C9: =B9+C8 -> 176400 | D9: =INDEX(Sheet1!I$6:I$125,Sheet3!A9) -> 1700 | E9: =B9/D9 -> 25.976471 | F9: =F8+E9 -> 120.87821 | G9: 76 | H9: =VLOOKUP(G9,[1]地图强度!$M$2:$N$101,2,0) -> 53374.844 | I9: =ROUND(H9*300,-2) -> 16012500
A10: 9 | B10: =INDEX(Sheet1!E$6:E$125,Sheet3!A10*4) -> 52800 | C10: =B10+C9 -> 229200 | D10: =INDEX(Sheet1!I$6:I$125,Sheet3!A10) -> 1800 | E10: =B10/D10 -> 29.333333 | F10: =F9+E10 -> 150.21154 | G10: 80 | H10: =VLOOKUP(G10,[1]地图强度!$M$2:$N$101,2,0) -> 64283.875 | I10: =ROUND(H10*300,-2) -> 19285200
A11: 10 | B11: =INDEX(Sheet1!E$6:E$125,Sheet3!A11*4) -> 62400 | C11: =B11+C10 -> 291600 | D11: =INDEX(Sheet1!I$6:I$125,Sheet3!A11) -> 1900 | E11: =B11/D11 -> 32.842105 | F11: =F10+E11 -> 183.05365 | G11: 84 | H11: =VLOOKUP(G11,[1]地图强度!$M$2:$N$101,2,0) -> 76719.779 | I11: =ROUND(H11*300,-2) -> 23015900
A12: 11 | B12: =INDEX(Sheet1!E$6:E$125,Sheet3!A12*4) -> 72960 | C12: =B12+C11 -> 364560 | D12: =INDEX(Sheet1!I$6:I$125,Sheet3!A12) -> 2000 | E12: =B12/D12 -> 36.48 | F12: =F11+E12 -> 219.53365 | G12: 87 | H12: =VLOOKUP(G12,[1]地图强度!$M$2:$N$101,2,0) -> 87485.548 | I12: =ROUND(H12*300,-2) -> 26245700
A13: 12 | B13: =INDEX(Sheet1!E$6:E$125,Sheet3!A13*4) -> 84480 | C13: =B13+C12 -> 449040 | D13: =INDEX(Sheet1!I$6:I$125,Sheet3!A13) -> 2100 | E13: =B13/D13 -> 40.228571 | F13: =F12+E13 -> 259.76222 | G13: 91 | H13: =VLOOKUP(G13,[1]地图强度!$M$2:$N$101,2,0) -> 103940.68 | I13: =ROUND(H13*300,-2) -> 31182200
A14: 13 | B14: =INDEX(Sheet1!E$6:E$125,Sheet3!A14*4) -> 96960 | C14: =B14+C13 -> 546000 | D14: =INDEX(Sheet1!I$6:I$125,Sheet3!A14) -> 2200 | E14: =B14/D14 -> 44.072727 | F14: =F13+E14 -> 303.83495 | G14: 94 | H14: =VLOOKUP(G14,[1]地图强度!$M$2:$N$101,2,0) -> 117790.13 | I14: =ROUND(H14*300,-2) -> 35337000
... A16: 15 | B16: =INDEX(Sheet1!E$6:E$125,Sheet3!A16*4) -> 124800 | C16: =B16+C15 -> 781200 | D16: =INDEX(Sheet1!I$6:I$125,Sheet3!A16) -> 2400 | E16: =B16/D16 -> 52 | F16: =F15+E16 -> 403.83495 | G16: 100 | H16: =VLOOKUP(G16,[1]地图强度!$M$2:$N$101,2,0) -> 149980.42 | I16: =ROUND(H16*300,-2) -> 44994100
A17: 16 | B17: =INDEX(Sheet1!E$6:E$125,Sheet3!A17*4) -> 140160 | C17: =B17+C16 -> 921360 | D17: =INDEX(Sheet1!I$6:I$125,Sheet3!A17) -> 2500 | E17: =B17/D17 -> 56.064 | F17: =F16+E17 -> 459.89895
A18: 17 | B18: =INDEX(Sheet1!E$6:E$125,Sheet3!A18*4) -> 156480 | C18: =B18+C17 -> 1077840 | D18: =INDEX(Sheet1!I$6:I$125,Sheet3!A18) -> 2600 | E18: =B18/D18 -> 60.184615 | F18: =F17+E18 -> 520.08356
A19: 18 | B19: =INDEX(Sheet1!E$6:E$125,Sheet3!A19*4) -> 173760 | C19: =B19+C18 -> 1251600 | D19: =INDEX(Sheet1!I$6:I$125,Sheet3!A19) -> 2700 | E19: =B19/D19 -> 64.355556 | F19: =F18+E19 -> 584.43912
A20: 19 | B20: =INDEX(Sheet1!E$6:E$125,Sheet3!A20*4) -> 192000 | C20: =B20+C19 -> 1443600 | D20: =INDEX(Sheet1!I$6:I$125,Sheet3!A20) -> 2800 | E20: =B20/D20 -> 68.571429 | F20: =F19+E20 -> 653.01055
A21: 20 | B21: =INDEX(Sheet1!E$6:E$125,Sheet3!A21*4) -> 211200 | C21: =B21+C20 -> 1654800 | D21: =INDEX(Sheet1!I$6:I$125,Sheet3!A21) -> 2900 | E21: =B21/D21 -> 72.827586 | F21: =F20+E21 -> 725.83813
A22: 21 | B22: =INDEX(Sheet1!E$6:E$125,Sheet3!A22*4) -> 231360 | C22: =B22+C21 -> 1886160 | D22: =INDEX(Sheet1!I$6:I$125,Sheet3!A22) -> 3000 | E22: =B22/D22 -> 77.12 | F22: =F21+E22 -> 802.95813
A23: 22 | B23: =INDEX(Sheet1!E$6:E$125,Sheet3!A23*4) -> 252480 | C23: =B23+C22 -> 2138640 | D23: =INDEX(Sheet1!I$6:I$125,Sheet3!A23) -> 3100 | E23: =B23/D23 -> 81.445161 | F23: =F22+E23 -> 884.40329
A24: 23 | B24: =INDEX(Sheet1!E$6:E$125,Sheet3!A24*4) -> 274560 | C24: =B24+C23 -> 2413200 | D24: =INDEX(Sheet1!I$6:I$125,Sheet3!A24) -> 3200 | E24: =B24/D24 -> 85.8 | F24: =F23+E24 -> 970.20329
A25: 24 | B25: =INDEX(Sheet1!E$6:E$125,Sheet3!A25*4) -> 297600 | C25: =B25+C24 -> 2710800 | D25: =INDEX(Sheet1!I$6:I$125,Sheet3!A25) -> 3300 | E25: =B25/D25 -> 90.181818 | F25: =F24+E25 -> 1060.3851
A26: 25 | B26: =INDEX(Sheet1!E$6:E$125,Sheet3!A26*4) -> 321600 | C26: =B26+C25 -> 3032400 | D26: =INDEX(Sheet1!I$6:I$125,Sheet3!A26) -> 3400 | E26: =B26/D26 -> 94.588235 | F26: =F25+E26 -> 1154.9733
A27: 26 | B27: =INDEX(Sheet1!E$6:E$125,Sheet3!A27*4) -> 346560 | C27: =B27+C26 -> 3378960 | D27: =INDEX(Sheet1!I$6:I$125,Sheet3!A27) -> 3500 | E27: =B27/D27 -> 99.017143 | F27: =F26+E27 -> 1253.9905
A28: 27 | B28: =INDEX(Sheet1!E$6:E$125,Sheet3!A28*4) -> 372480 | C28: =B28+C27 -> 3751440 | D28: =INDEX(Sheet1!I$6:I$125,Sheet3!A28) -> 3600 | E28: =B28/D28 -> 103.46667 | F28: =F27+E28 -> 1357.4572
... A31: 30 | B31: =INDEX(Sheet1!E$6:E$125,Sheet3!A31*4) -> 456000 | C31: =B31+C30 -> 5034000 | D31: =INDEX(Sheet1!I$6:I$125,Sheet3!A31) -> 3900 | E31: =B31/D31 -> 116.92308 | F31: =F30+E31 -> 1694.7364
